File: data/ExpDat_SK_Clear_resin_entalp5kpm_20-150.txt
#EXPORTTYPE:                 	DATA SINGLE
#FILE:                       	SK_Clear_resin_entalp5kpm_20-150.ngb-sdg
#FORMAT:                     	NETZSCH5
#FTYPE:                      	ASCII
#IDENTITY:                   	SK_clear_resin
#DECIMAL:                    	POINT
#SEPARATOR:                  	TAB
#MTYPE:                      	DSC
#INSTRUMENT:                 	NETZSCH DSC 214
#PROJECT:                    	?ø?†??-Ø
#DATE/TIME:                  	13.09.2019 19:00:27 (UTC+3)
#CORR. FILE:
#TEMPCAL:                    	applied
#SENSITIVITY:                	applied
#LABORATORY:                 	CISIS
#OPERATOR:                   	Nasonov
#REMARK:
#SAMPLE:                     	1070-G290S -0-Ù.1-3-17X3
#SAMPLE MASS /mg:            	8.3
#MATERIAL:
#REFERENCE:
#REFERENCE MASS /mg:         	7.76
#TYPE OF CRUCIBLE:           	Concavus Pan Al, pierced lid
#SAMPLE CRUCIBLE MASS /mg:   	0
#REFERENCE CRUCIBLE MASS /mg:	0
#M.RANGE /ßV:                	5000
#TAU-R:                      	---
#CORR. CODE:                 	009
#EXO:                        	+1
#RANGE:                      	20ËC/5.0(K/min)/130ËC
#SEGMENT:                    	S1/1
#SEG. 1:                     	20ËC/5.0(K/min)/130ËC

##Temp./ËC	Time/min	DSC/(mW/mg)	Sensit./(uV/mW)
 20.01700	 0.00000	 2.279258e-002	3.36733
 20.01857	 0.02000	 2.282005e-002	3.36733
 20.03631	 0.04000	 2.282406e-002	3.36735
 20.08221	 0.06000	 2.543072e-002	3.36740
 20.15536	 0.08000	 2.654706e-002	3.36748
 20.25194	 0.10000	 2.314328e-002	3.36758
 20.36659	 0.12000	 1.491726e-002	3.36770
 20.49347	 0.14000	 2.906497e-003	3.36783
 20.62718	 0.16000	-1.351822e-002	3.36796
 20.76322	 0.18000	-3.217492e-002	3.36810
 20.89810	 0.20000	-5.347383e-002	3.36824
 21.01084	 0.22000	-7.485254e-002	3.36836
 21.12895	 0.24000	-9.644200e-002	3.36847
 21.25151	 0.26000	      -0.11737	3.36860
 21.37708	 0.28000	      -0.13598	3.36873
 21.50451	 0.30000	      -0.15285	3.36885
 21.63248	 0.32000	      -0.16679	3.36898
 21.75992	 0.34000	      -0.17829	3.36911
 21.88572	 0.36000	      -0.18661	3.36923
 22.00920	 0.38000	      -0.19211	3.36936
 22.12967	 0.40000	      -0.19514	3.36947
 22.24679	 0.42000	      -0.19575	3.36959
 22.36021	 0.44000	      -0.19437	3.36970
 22.46989	 0.46000	      -0.19100	3.36981
 22.57592	 0.48000	      -0.18644	3.36991
 22.67854	 0.50000	      -0.18059	3.37001
 22.77793	 0.52000	      -0.17423	3.37011
 22.87456	 0.54000	      -0.16774	3.37020
 22.96877	 0.56000	      -0.16075	3.37029
 23.06108	 0.58000	      -0.15416	3.37038
 23.15190	 0.60000	      -0.14825	3.37047
 23.24167	 0.62000	      -0.14303	3.37055
 23.33085	 0.64000	      -0.13805	3.37064
 23.41979	 0.66000	      -0.13399	3.37072
 23.50884	 0.68000	      -0.13119	3.37081
 23.59818	 0.70000	      -0.12848	3.37089
 23.68810	 0.72000	      -0.12671	3.37098
 23.77875	 0.74000	      -0.12547	3.37106
 23.87030	 0.76000	      -0.12547	3.37115
 23.96282	 0.78000	      -0.12551	3.37123
 24.05620	 0.80000	      -0.12597	3.37132
 24.15052	 0.82000	      -0.12721	3.37141
 24.24584	 0.84000	      -0.12873	3.37150
 24.34200	 0.86000	      -0.13020	3.37159
 24.43892	 0.88000	      -0.13185	3.37168
 24.53654	 0.90000	      -0.13359	3.37177
 24.63484	 0.92000	      -0.13529	3.37186
 24.73359	 0.94000	      -0.13695	3.37195
 24.83285	 0.96000	      -0.13857	3.37204
 24.93246	 0.98000	      -0.14025	3.37213
 25.03225	 1.00000	      -0.14134	3.37222
 25.13231	 1.02000	      -0.14261	3.37231
 25.23234	 1.04000	      -0.14320	3.37240
 25.33248	 1.06000	      -0.14425	3.37249
 25.43259	 1.08000	      -0.14476	3.37258
 25.53266	 1.10000	      -0.14521	3.37267
 25.63270	 1.12000	      -0.14586	3.37276
 25.73261	 1.14000	      -0.14607	3.37285
 25.83230	 1.16000	      -0.14617	3.37293
 25.93187	 1.18000	      -0.14621	3.37302
 26.03146	 1.20000	      -0.14649	3.37311
 26.13111	 1.22000	      -0.14653	3.37320
 26.23057	 1.24000	      -0.14645	3.37328
 26.32993	 1.26000	      -0.14633	3.37337
 26.42946	 1.28000	      -0.14641	3.37346
 26.52893	 1.30000	      -0.14629	3.37354
 26.62834	 1.32000	      -0.14615	3.37363
 26.72784	 1.34000	      -0.14609	3.37371
 26.82730	 1.36000	      -0.14617	3.37380
 26.92674	 1.38000	      -0.14619	3.37388
 27.02620	 1.40000	      -0.14618	3.37397
 27.12577	 1.42000	      -0.14640	3.37405
 27.22533	 1.44000	      -0.14640	3.37414
 27.32493	 1.46000	      -0.14643	3.37422
 27.42448	 1.48000	      -0.14690	3.37431
 27.52403	 1.50000	      -0.14690	3.37439
 27.62379	 1.52000	      -0.14696	3.37447
 27.72349	 1.54000	      -0.14750	3.37456
 27.82328	 1.56000	      -0.14745	3.37464
 27.92311	 1.58000	      -0.14751	3.37472
 28.02297	 1.60000	      -0.14777	3.37480
 28.12275	 1.62000	      -0.14804	3.37489
 28.22264	 1.64000	      -0.14809	3.37497
 28.32256	 1.66000	      -0.14836	3.37505
 28.42249	 1.68000	      -0.14868	3.37513
 28.52230	 1.70000	      -0.14890	3.37521
 28.62218	 1.72000	      -0.14903	3.37529
 28.72210	 1.74000	      -0.14911	3.37537
 28.82203	 1.76000	      -0.14919	3.37545
 28.92197	 1.78000	      -0.14946	3.37553
 29.02192	 1.80000	      -0.14945	3.37561
 29.12177	 1.82000	      -0.14967	3.37569
 29.22172	 1.84000	      -0.14973	3.37577
 29.32166	 1.86000	      -0.14976	3.37585
 29.42167	 1.88000	      -0.14996	3.37593
 29.52179	 1.90000	      -0.15018	3.37601
 29.62185	 1.92000	      -0.15027	3.37609
 29.72192	 1.94000	      -0.15032	3.37616
 29.82207	 1.96000	      -0.15046	3.37624
 29.92213	 1.98000	      -0.15060	3.37632
 30.02218	 2.00000	      -0.15091	3.37640
 30.12223	 2.02000	      -0.15107	3.37647
 30.22225	 2.04000	      -0.15136	3.37655
 30.32231	 2.06000	      -0.15127	3.37663
 30.42234	 2.08000	      -0.15138	3.37670
 30.52238	 2.10000	      -0.15153	3.37678
 30.62254	 2.12000	      -0.15161	3.37685
 30.72256	 2.14000	      -0.15193	3.37693
 30.82262	 2.16000	      -0.15214	3.37700
 30.92266	 2.18000	      -0.15208	3.37708
 31.02274	 2.20000	      -0.15213	3.37715
 31.12289	 2.22000	      -0.15228	3.37723
 31.22302	 2.24000	      -0.15225	3.37730
 31.32311	 2.26000	      -0.15240	3.37738
 31.42323	 2.28000	      -0.15277	3.37745
 31.52325	 2.30000	      -0.15274	3.37752
 31.62334	 2.32000	      -0.15278	3.37759
 31.72348	 2.34000	      -0.15318	3.37767
 31.82362	 2.36000	      -0.15311	3.37774
 31.92366	 2.38000	      -0.15311	3.37781
 32.02369	 2.40000	      -0.15331	3.37788
 32.12380	 2.42000	      -0.15336	3.37795
 32.22395	 2.44000	      -0.15376	3.37803
 32.32402	 2.46000	      -0.15388	3.37810
 32.42416	 2.48000	      -0.15404	3.37817
 32.52421	 2.50000	      -0.15427	3.37824
 32.62426	 2.52000	      -0.15426	3.37831
 32.72434	 2.54000	      -0.15439	3.37838
 32.82444	 2.56000	      -0.15433	3.37845
 32.92462	 2.58000	      -0.15448	3.37852
 33.02464	 2.60000	      -0.15441	3.37859
 33.12462	 2.62000	      -0.15439	3.37865
 33.22452	 2.64000	      -0.15433	3.37872
 33.32448	 2.66000	      -0.15441	3.37879
 33.42444	 2.68000	      -0.15455	3.37886
 33.52448	 2.70000	      -0.15465	3.37893
 33.62446	 2.72000	      -0.15476	3.37899
 33.72441	 2.74000	      -0.15476	3.37906
 33.82439	 2.76000	      -0.15498	3.37913
 33.92439	 2.78000	      -0.15516	3.37919
 34.02456	 2.80000	      -0.15513	3.37926
 34.12461	 2.82000	      -0.15515	3.37933
 34.22456	 2.84000	      -0.15523	3.37939
 34.32456	 2.86000	      -0.15539	3.37946
 34.42454	 2.88000	      -0.15538	3.37952
 34.52456	 2.90000	      -0.15563	3.37959
 34.62462	 2.92000	      -0.15573	3.37965
 34.72466	 2.94000	      -0.15564	3.37972
 34.82466	 2.96000	      -0.15559	3.37978
 34.92466	 2.98000	      -0.15574	3.37985
 35.02466	 3.00000	      -0.15592	3.37991
 35.12475	 3.02000	      -0.15614	3.37997
 35.22492	 3.04000	      -0.15609	3.38004
 35.32508	 3.06000	      -0.15607	3.38010
 35.42521	 3.08000	      -0.15627	3.38016
 35.52531	 3.10000	      -0.15638	3.38022
 35.62538	 3.12000	      -0.15671	3.38029
 35.72544	 3.14000	      -0.15666	3.38035
 35.82546	 3.16000	      -0.15661	3.38041
 35.92554	 3.18000	      -0.15694	3.38047
 36.02562	 3.20000	      -0.15706	3.38053
 36.12569	 3.22000	      -0.15725	3.38059
 36.22584	 3.24000	      -0.15726	3.38065
 36.32592	 3.26000	      -0.15742	3.38071
 36.42595	 3.28000	      -0.15756	3.38077
 36.52602	 3.30000	      -0.15773	3.38083
 36.62610	 3.32000	      -0.15781	3.38089
 36.72623	 3.34000	      -0.15789	3.38095
 36.82634	 3.36000	      -0.15798	3.38101
 36.92644	 3.38000	      -0.15820	3.38107
 37.02654	 3.40000	      -0.15837	3.38113
 37.12662	 3.42000	      -0.15846	3.38118
 37.22670	 3.44000	      -0.15841	3.38124
 37.32677	 3.46000	      -0.15859	3.38130
 37.42677	 3.48000	      -0.15873	3.38136
 37.52680	 3.50000	      -0.15902	3.38141
 37.62693	 3.52000	      -0.15903	3.38147
 37.72700	 3.54000	      -0.15920	3.38153
 37.82713	 3.56000	      -0.15935	3.38158
 37.92726	 3.58000	      -0.15955	3.38164
 38.02731	 3.60000	      -0.15970	3.38169
 38.12731	 3.62000	      -0.15995	3.38175
 38.22736	 3.64000	      -0.16023	3.38181
 38.32739	 3.66000	      -0.16024	3.38186
 38.42739	 3.68000	      -0.16044	3.38191
 38.52744	 3.70000	      -0.16055	3.38197
 38.62744	 3.72000	      -0.16064	3.38202
 38.72741	 3.74000	      -0.16070	3.38208
 38.82734	 3.76000	      -0.16082	3.38213
 38.92734	 3.78000	      -0.16091	3.38218
 39.02731	 3.80000	      -0.16094	3.38224
 39.12726	 3.82000	      -0.16097	3.38229
 39.22718	 3.84000	      -0.16100	3.38234
 39.32721	 3.86000	      -0.16109	3.38239
 39.42720	 3.88000	      -0.16114	3.38244
 39.52725	 3.90000	      -0.16109	3.38250
 39.62723	 3.92000	      -0.16117	3.38255
 39.72721	 3.94000	      -0.16134	3.38260
 39.82725	 3.96000	      -0.16131	3.38265
 39.92716	 3.98000	      -0.16139	3.38270
 40.02713	 4.00000	      -0.16153	3.38275
 40.12711	 4.02000	      -0.16169	3.38280
 40.22707	 4.04000	      -0.16145	3.38285
 40.32710	 4.06000	      -0.16158	3.38290
 40.42718	 4.08000	      -0.16171	3.38295
 40.52725	 4.10000	      -0.16196	3.38300
 40.62731	 4.12000	      -0.16209	3.38305
 40.72743	 4.14000	      -0.16214	3.38309
 40.82752	 4.16000	      -0.16208	3.38314
 40.92762	 4.18000	      -0.16203	3.38319
 41.02764	 4.20000	      -0.16210	3.38324
 41.12767	 4.22000	      -0.16215	3.38329
 41.22774	 4.24000	      -0.16220	3.38333
 41.32774	 4.26000	      -0.16223	3.38338
 41.42777	 4.28000	      -0.16233	3.38343
 41.52775	 4.30000	      -0.16252	3.38347
 41.62777	 4.32000	      -0.16274	3.38352
 41.72780	 4.34000	      -0.16279	3.38356
 41.82784	 4.36000	      -0.16287	3.38361
 41.92784	 4.38000	      -0.16295	3.38365
 42.02785	 4.40000	      -0.16330	3.38370
 42.12784	 4.42000	      -0.16329	3.38374
 42.22792	 4.44000	      -0.16334	3.38379
 42.32802	 4.46000	      -0.16344	3.38383
 42.42808	 4.48000	      -0.16351	3.38388
 42.52818	 4.50000	      -0.16352	3.38392
 42.62826	 4.52000	      -0.16362	3.38396
 42.72829	 4.54000	      -0.16370	3.38401
 42.82831	 4.56000	      -0.16377	3.38405
 42.92836	 4.58000	      -0.16378	3.38409
 43.02841	 4.60000	      -0.16403	3.38413
 43.12851	 4.62000	      -0.16402	3.38418
 43.22856	 4.64000	      -0.16407	3.38422
 43.32859	 4.66000	      -0.16417	3.38426
 43.42864	 4.68000	      -0.16479	3.38430
 43.52872	 4.70000	      -0.16473	3.38434
 43.62874	 4.72000	      -0.16477	3.38438
 43.72872	 4.74000	      -0.16485	3.38442
 43.82874	 4.76000	      -0.16489	3.38446
 43.92867	 4.78000	      -0.16489	3.38450
 44.02870	 4.80000	      -0.16492	3.38454
 44.12877	 4.82000	      -0.16517	3.38458
 44.22882	 4.84000	      -0.16509	3.38462
 44.32884	 4.86000	      -0.16514	3.38466
 44.42885	 4.88000	      -0.16523	3.38470
 44.52884	 4.90000	      -0.16509	3.38474
 44.62875	 4.92000	      -0.16531	3.38478
 44.72877	 4.94000	      -0.16545	3.38481
 44.82875	 4.96000	      -0.16548	3.38485
 44.92872	 4.98000	      -0.16562	3.38489
 45.02871	 5.00000	      -0.16573	3.38493
 45.12877	 5.02000	      -0.16564	3.38496
 45.22877	 5.04000	      -0.16583	3.38500
 45.32885	 5.06000	      -0.16585	3.38504
 45.42887	 5.08000	      -0.16593	3.38507
 45.52892	 5.10000	      -0.16584	3.38511
 45.62903	 5.12000	      -0.16589	3.38514
 45.72918	 5.14000	      -0.16586	3.38518
 45.82920	 5.16000	      -0.16585	3.38521
 45.92923	 5.18000	      -0.16604	3.38525
 46.02923	 5.20000	      -0.16622	3.38528
 46.12926	 5.22000	      -0.16624	3.38532
 46.22933	 5.24000	      -0.16623	3.38535
 46.32933	 5.26000	      -0.16632	3.38538
 46.42933	 5.28000	      -0.16626	3.38542
 46.52930	 5.30000	      -0.16646	3.38545
 46.62936	 5.32000	      -0.16651	3.38548
 46.72934	 5.34000	      -0.16655	3.38552
 46.82943	 5.36000	      -0.16667	3.38555
 46.92944	 5.38000	      -0.16650	3.38558
 47.02939	 5.40000	      -0.16647	3.38561
 47.12941	 5.42000	      -0.16659	3.38564
 47.22951	 5.44000	      -0.16649	3.38567
 47.32954	 5.46000	      -0.16661	3.38571
 47.42956	 5.48000	      -0.16692	3.38574
 47.52959	 5.50000	      -0.16682	3.38577
 47.62959	 5.52000	      -0.16694	3.38580
 47.72948	 5.54000	      -0.16700	3.38583
 47.82949	 5.56000	      -0.16718	3.38586
 47.92949	 5.58000	      -0.16719	3.38589
 48.02952	 5.60000	      -0.16725	3.38592
 48.12951	 5.62000	      -0.16738	3.38594
 48.22946	 5.64000	      -0.16740	3.38597
 48.32948	 5.66000	      -0.16751	3.38600
 48.42954	 5.68000	      -0.16755	3.38603
 48.52956	 5.70000	      -0.16755	3.38606
 48.62956	 5.72000	      -0.16763	3.38608
 48.72956	 5.74000	      -0.16768	3.38611
 48.82954	 5.76000	      -0.16762	3.38614
 48.92951	 5.78000	      -0.16745	3.38617
 49.02954	 5.80000	      -0.16759	3.38619
 49.12957	 5.82000	      -0.16778	3.38622
 49.22952	 5.84000	      -0.16777	3.38624
 49.32957	 5.86000	      -0.16785	3.38627
 49.42962	 5.88000	      -0.16798	3.38630
 49.52964	 5.90000	      -0.16798	3.38632
 49.62956	 5.92000	      -0.16822	3.38635
 49.72957	 5.94000	      -0.16813	3.38637
 49.82956	 5.96000	      -0.16807	3.38640
 49.92952	 5.98000	      -0.16823	3.38642
 50.02956	 6.00000	      -0.16846	3.38644
 50.12962	 6.02000	      -0.16832	3.38647
 50.22967	 6.04000	      -0.16840	3.38649
 50.32966	 6.06000	      -0.16850	3.38651
 50.42962	 6.08000	      -0.16863	3.38654
 50.52961	 6.10000	      -0.16871	3.38656
 50.62974	 6.12000	      -0.16873	3.38658
 50.72982	 6.14000	      -0.16876	3.38660
 50.82992	 6.16000	      -0.16867	3.38663
 50.93003	 6.18000	      -0.16872	3.38665
 51.03007	 6.20000	      -0.16892	3.38667
 51.13013	 6.22000	      -0.16887	3.38669
 51.23018	 6.24000	      -0.16885	3.38671
 51.33011	 6.26000	      -0.16899	3.38673
 51.43007	 6.28000	      -0.16916	3.38675
 51.53000	 6.30000	      -0.16922	3.38677
 51.63005	 6.32000	      -0.16942	3.38679
 51.73007	 6.34000	      -0.16948	3.38681
 51.83007	 6.36000	      -0.16951	3.38683
 51.93013	 6.38000	      -0.16968	3.38685
 52.03021	 6.40000	      -0.16976	3.38687
 52.13016	 6.42000	      -0.16955	3.38689
 52.23020	 6.44000	      -0.16974	3.38691
 52.33023	 6.46000	      -0.16975	3.38692
 52.43034	 6.48000	      -0.16964	3.38694
 52.53036	 6.50000	      -0.16973	3.38696
 52.63034	 6.52000	      -0.16979	3.38698
 52.73031	 6.54000	      -0.16980	3.38699
 52.83021	 6.56000	      -0.16999	3.38701
 52.93011	 6.58000	      -0.16992	3.38703
 53.03005	 6.60000	      -0.16973	3.38704
 53.13000	 6.62000	      -0.17008	3.38706
 53.22993	 6.64000	      -0.17005	3.38707
 53.32993	 6.66000	      -0.16980	3.38709
 53.42984	 6.68000	      -0.17009	3.38710
 53.52987	 6.70000	      -0.17006	3.38712
 53.62989	 6.72000	      -0.16997	3.38713
 53.72995	 6.74000	      -0.16997	3.38715
 53.82997	 6.76000	      -0.17013	3.38716
 53.92998	 6.78000	      -0.17004	3.38718
 54.03002	 6.80000	      -0.16985	3.38719
 54.13005	 6.82000	      -0.16988	3.38720
 54.23010	 6.84000	      -0.17018	3.38722
 54.33011	 6.86000	      -0.17004	3.38723
 54.43011	 6.88000	      -0.16999	3.38724
 54.53007	 6.90000	      -0.16991	3.38725
 54.63008	 6.92000	      -0.17002	3.38727
 54.73018	 6.94000	      -0.16999	3.38728
 54.83028	 6.96000	      -0.17013	3.38729
 54.93034	 6.98000	      -0.17016	3.38730
 55.03039	 7.00000	      -0.17016	3.38731
 55.13041	 7.02000	      -0.17014	3.38732
 55.23043	 7.04000	      -0.16999	3.38733
 55.33048	 7.06000	      -0.17003	3.38734
 55.43059	 7.08000	      -0.17001	3.38735
 55.53056	 7.10000	      -0.17005	3.38736
 55.63052	 7.12000	      -0.17012	3.38737
 55.73051	 7.14000	      -0.17007	3.38738
 55.83054	 7.16000	      -0.17006	3.38739
 55.93054	 7.18000	      -0.17007	3.38740
 56.03049	 7.20000	      -0.16996	3.38741
 56.13049	 7.22000	      -0.17010	3.38742
 56.23048	 7.24000	      -0.17002	3.38742
 56.33044	 7.26000	      -0.17021	3.38743
 56.43043	 7.28000	      -0.17021	3.38744
 56.53039	 7.30000	      -0.17026	3.38745
 56.63051	 7.32000	      -0.17043	3.38745
 56.73054	 7.34000	      -0.17051	3.38746
 56.83059	 7.36000	      -0.17029	3.38747
 56.93064	 7.38000	      -0.17035	3.38747
 57.03066	 7.40000	      -0.17050	3.38748
 57.13077	 7.42000	      -0.17057	3.38749
 57.23089	 7.44000	      -0.17048	3.38749
 57.33095	 7.46000	      -0.17044	3.38750
 57.43103	 7.48000	      -0.17062	3.38750
 57.53107	 7.50000	      -0.17059	3.38750
 57.63108	 7.52000	      -0.17069	3.38751
 57.73107	 7.54000	      -0.17059	3.38751
 57.83100	 7.56000	      -0.17058	3.38752
 57.93105	 7.58000	      -0.17055	3.38752
 58.03111	 7.60000	      -0.17054	3.38752
 58.13125	 7.62000	      -0.17052	3.38753
 58.23133	 7.64000	      -0.17048	3.38753
 58.33139	 7.66000	      -0.17046	3.38753
 58.43144	 7.68000	      -0.17026	3.38754
 58.53141	 7.70000	      -0.17027	3.38754
 58.63139	 7.72000	      -0.17033	3.38754
 58.73126	 7.74000	      -0.17010	3.38754
 58.83115	 7.76000	      -0.16998	3.38754
 58.93102	 7.78000	      -0.16993	3.38754
 59.03097	 7.80000	      -0.16999	3.38754
 59.13090	 7.82000	      -0.17017	3.38755
 59.23080	 7.84000	      -0.16998	3.38755
 59.33080	 7.86000	      -0.17006	3.38755
 59.43074	 7.88000	      -0.17027	3.38755
 59.53069	 7.90000	      -0.17022	3.38754
 59.63079	 7.92000	      -0.17000	3.38754
 59.73090	 7.94000	      -0.17005	3.38754
 59.83102	 7.96000	      -0.17015	3.38754
 59.93115	 7.98000	      -0.17021	3.38754
 60.03120	 8.00000	      -0.17009	3.38754
 60.13125	 8.02000	      -0.17015	3.38754
 60.23126	 8.04000	      -0.16994	3.38754
 60.33130	 8.06000	      -0.17003	3.38753
 60.43133	 8.08000	      -0.17015	3.38753
 60.53136	 8.10000	      -0.17005	3.38753
 60.63136	 8.12000	      -0.17011	3.38752
 60.73139	 8.14000	      -0.17004	3.38752
 60.83141	 8.16000	      -0.17010	3.38752
 60.93148	 8.18000	      -0.17008	3.38751
 61.03152	 8.20000	      -0.17001	3.38751
 61.13162	 8.22000	      -0.17004	3.38750
 61.23159	 8.24000	      -0.16994	3.38750
 61.33156	 8.26000	      -0.16995	3.38749
 61.43162	 8.28000	      -0.16972	3.38749
 61.53169	 8.30000	      -0.16976	3.38748
 61.63171	 8.32000	      -0.16974	3.38748
 61.73167	 8.34000	      -0.16958	3.38747
 61.83154	 8.36000	      -0.16968	3.38747
 61.93138	 8.38000	      -0.16966	3.38746
 62.03123	 8.40000	      -0.16964	3.38745
 62.13107	 8.42000	      -0.16976	3.38745
 62.23079	 8.44000	      -0.16984	3.38744
 62.33057	 8.46000	      -0.16977	3.38743
 62.43039	 8.48000	      -0.16978	3.38742
 62.53034	 8.50000	      -0.16981	3.38741
 62.63023	 8.52000	      -0.16979	3.38741
 62.73016	 8.54000	      -0.16985	3.38740
 62.83011	 8.56000	      -0.16992	3.38739
 62.93008	 8.58000	      -0.16992	3.38738
 63.03010	 8.60000	      -0.16982	3.38737
 63.13000	 8.62000	      -0.16995	3.38736
 63.23003	 8.64000	      -0.17004	3.38735
 63.33007	 8.66000	      -0.16998	3.38734
 63.43008	 8.68000	      -0.17010	3.38733
 63.53005	 8.70000	      -0.17019	3.38732
 63.63002	 8.72000	      -0.17053	3.38731
 63.73003	 8.74000	      -0.17052	3.38730
 63.83013	 8.76000	      -0.17054	3.38729
 63.93025	 8.78000	      -0.17098	3.38728
 64.03028	 8.80000	      -0.17086	3.38726
 64.13025	 8.82000	      -0.17088	3.38725
 64.23041	 8.84000	      -0.17106	3.38724
 64.33059	 8.86000	      -0.17099	3.38723
 64.43079	 8.88000	      -0.17101	3.38722
 64.53080	 8.90000	      -0.17111	3.38720
 64.63085	 8.92000	      -0.17126	3.38719
 64.73093	 8.94000	      -0.17117	3.38718
 64.83097	 8.96000	      -0.17116	3.38716
 64.93103	 8.98000	      -0.17112	3.38715
 65.03107	 9.00000	      -0.17122	3.38713
 65.13107	 9.02000	      -0.17118	3.38712
 65.23107	 9.04000	      -0.17121	3.38710
 65.33111	 9.06000	      -0.17111	3.38709
 65.43108	 9.08000	      -0.17103	3.38707
 65.53102	 9.10000	      -0.17107	3.38706
 65.63098	 9.12000	      -0.17115	3.38704
 65.73093	 9.14000	      -0.17154	3.38703
 65.83092	 9.16000	      -0.17138	3.38701
 65.93092	 9.18000	      -0.17128	3.38699
 66.03097	 9.20000	      -0.17128	3.38698
 66.13102	 9.22000	      -0.17131	3.38696
 66.23110	 9.24000	      -0.17131	3.38694
 66.33107	 9.26000	      -0.17129	3.38693
 66.43105	 9.28000	      -0.17121	3.38691
 66.53100	 9.30000	      -0.17107	3.38689
 66.63103	 9.32000	      -0.17094	3.38687
 66.73110	 9.34000	      -0.17086	3.38685
 66.83113	 9.36000	      -0.17070	3.38683
 66.93111	 9.38000	      -0.17057	3.38682
 67.03108	 9.40000	      -0.17058	3.38680
 67.13107	 9.42000	      -0.17057	3.38678
 67.23105	 9.44000	      -0.17038	3.38676
 67.33100	 9.46000	      -0.17015	3.38674
 67.43102	 9.48000	      -0.16971	3.38672
 67.53110	 9.50000	      -0.16957	3.38670
 67.63111	 9.52000	      -0.16960	3.38668
 67.73113	 9.54000	      -0.16946	3.38665
 67.83107	 9.56000	      -0.16942	3.38663
 67.93102	 9.58000	      -0.16917	3.38661
 68.03103	 9.60000	      -0.16891	3.38659
 68.13100	 9.62000	      -0.16852	3.38657
 68.23097	 9.64000	      -0.16843	3.38655
 68.33105	 9.66000	      -0.16821	3.38652
 68.43111	 9.68000	      -0.16820	3.38650
 68.53121	 9.70000	      -0.16784	3.38648
 68.63125	 9.72000	      -0.16762	3.38645
 68.73128	 9.74000	      -0.16731	3.38643
 68.83131	 9.76000	      -0.16714	3.38641
 68.93143	 9.78000	      -0.16689	3.38638
 69.03148	 9.80000	      -0.16668	3.38636
 69.13151	 9.82000	      -0.16641	3.38634
 69.23146	 9.84000	      -0.16608	3.38631
 69.33146	 9.86000	      -0.16562	3.38629
 69.43144	 9.88000	      -0.16551	3.38626
 69.53144	 9.90000	      -0.16505	3.38623
 69.63146	 9.92000	      -0.16478	3.38621
 69.73144	 9.94000	      -0.16445	3.38618
 69.83143	 9.96000	      -0.16391	3.38616
 69.93149	 9.98000	      -0.16355	3.38613
 70.03141	10.00000	      -0.16315	3.38610
 70.13134	10.02000	      -0.16263	3.38608
 70.23131	10.04000	      -0.16204	3.38605
 70.33129	10.06000	      -0.16180	3.38602
 70.43126	10.08000	      -0.16105	3.38600
 70.53126	10.10000	      -0.16067	3.38597
 70.63125	10.12000	      -0.16027	3.38594
 70.73128	10.14000	      -0.15995	3.38591
 70.83125	10.16000	      -0.15952	3.38588
 70.93125	10.18000	      -0.15914	3.38585
 71.03129	10.20000	      -0.15855	3.38582
 71.13134	10.22000	      -0.15806	3.38580
 71.23138	10.24000	      -0.15759	3.38577
 71.33143	10.26000	      -0.15715	3.38574
 71.43146	10.28000	      -0.15671	3.38571
 71.53146	10.30000	      -0.15611	3.38568
 71.63151	10.32000	      -0.15553	3.38565
 71.73157	10.34000	      -0.15499	3.38561
 71.83161	10.36000	      -0.15430	3.38558
 71.93164	10.38000	      -0.15378	3.38555
 72.03166	10.40000	      -0.15329	3.38552
 72.13177	10.42000	      -0.15244	3.38549
 72.23184	10.44000	      -0.15176	3.38546
 72.33179	10.46000	      -0.15110	3.38542
 72.43180	10.48000	      -0.15031	3.38539
 72.53174	10.50000	      -0.14974	3.38536
 72.63164	10.52000	      -0.14917	3.38533
 72.73152	10.54000	      -0.14854	3.38529
 72.83151	10.56000	      -0.14770	3.38526
 72.93148	10.58000	      -0.14699	3.38523
 73.03141	10.60000	      -0.14619	3.38519
 73.13138	10.62000	      -0.14551	3.38516
 73.23146	10.64000	      -0.14463	3.38512
 73.33149	10.66000	      -0.14361	3.38509
 73.43146	10.68000	      -0.14276	3.38505
 73.53143	10.70000	      -0.14178	3.38502
 73.63139	10.72000	      -0.14093	3.38498
 73.73134	10.74000	      -0.14024	3.38495
 73.83131	10.76000	      -0.13928	3.38491
 73.93134	10.78000	      -0.13864	3.38488
 74.03128	10.80000	      -0.13764	3.38484
 74.13125	10.82000	      -0.13668	3.38480
 74.23128	10.84000	      -0.13580	3.38477
 74.33138	10.86000	      -0.13463	3.38473
 74.43138	10.88000	      -0.13367	3.38469
 74.53139	10.90000	      -0.13254	3.38465
 74.63149	10.92000	      -0.13167	3.38462
 74.73154	10.94000	      -0.13063	3.38458
 74.83159	10.96000	      -0.12959	3.38454
 74.93156	10.98000	      -0.12819	3.38450
 75.03162	11.00000	      -0.12714	3.38446
 75.13162	11.02000	      -0.12575	3.38442
 75.23161	11.04000	      -0.12455	3.38438
 75.33166	11.06000	      -0.12329	3.38434
 75.43174	11.08000	      -0.12179	3.38430
 75.53182	11.10000	      -0.12056	3.38426
 75.63184	11.12000	      -0.11913	3.38422
 75.73185	11.14000	      -0.11777	3.38418
 75.83187	11.16000	      -0.11651	3.38414
 75.93182	11.18000	      -0.11512	3.38410
 76.03182	11.20000	      -0.11363	3.38406
 76.13189	11.22000	      -0.11210	3.38402
 76.23185	11.24000	      -0.11049	3.38398
 76.33182	11.26000	      -0.10891	3.38394
 76.43177	11.28000	      -0.10716	3.38389
 76.53177	11.30000	      -0.10527	3.38385
 76.63172	11.32000	      -0.10361	3.38381
 76.73177	11.34000	      -0.10173	3.38377
 76.83179	11.36000	-9.984186e-002	3.38372
 76.93180	11.38000	-9.801263e-002	3.38368
 77.03185	11.40000	-9.621876e-002	3.38364
 77.13182	11.42000	-9.411614e-002	3.38359
 77.23175	11.44000	-9.201419e-002	3.38355
 77.33166	11.46000	-9.015635e-002	3.38350
 77.43166	11.48000	-8.802642e-002	3.38346
 77.53166	11.50000	-8.589716e-002	3.38341
 77.63175	11.52000	-8.379500e-002	3.38337
 77.73185	11.54000	-8.147403e-002	3.38332
 77.83195	11.56000	-7.926275e-002	3.38328
 77.93205	11.58000	-7.705177e-002	3.38323
 78.03205	11.60000	-7.441119e-002	3.38319
 78.13208	11.62000	-7.213729e-002	3.38314
 78.23210	11.64000	-6.964560e-002	3.38309
 78.33207	11.66000	-6.709880e-002	3.38305
 78.43202	11.68000	-6.436100e-002	3.38300
 78.53192	11.70000	-6.170572e-002	3.38295
 78.63185	11.72000	-5.902321e-002	3.38290
 78.73182	11.74000	-5.625910e-002	3.38286
 78.83180	11.76000	-5.319674e-002	3.38281
 78.93175	11.78000	-5.032343e-002	3.38276
 79.03169	11.80000	-4.716616e-002	3.38271
 79.13167	11.82000	-4.381771e-002	3.38266
 79.23172	11.84000	-4.060502e-002	3.38262
 79.33175	11.86000	-3.709403e-002	3.38257
 79.43172	11.88000	-3.355543e-002	3.38252
 79.53172	11.90000	-2.982577e-002	3.38247
 79.63161	11.92000	-2.628627e-002	3.38242
 79.73151	11.94000	-2.250243e-002	3.38237
 79.83136	11.96000	-1.866379e-002	3.38232
 79.93131	11.98000	-1.477101e-002	3.38227
 80.03136	12.00000	-1.078098e-002	3.38222
 80.13143	12.02000	-6.544463e-003	3.38217
 80.23149	12.04000	-2.199110e-003	3.38211
 80.33169	12.06000	 2.227894e-003	3.38206
 80.43187	12.08000	 6.736219e-003	3.38201
 80.53213	12.10000	 1.135411e-002	3.38196
 80.63231	12.12000	 1.654257e-002	3.38191
 80.73241	12.14000	 2.151376e-002	3.38185
 80.83244	12.16000	 2.683811e-002	3.38180
 80.93246	12.18000	 3.235397e-002	3.38175
 81.03248	12.20000	 3.814029e-002	3.38169
 81.13244	12.22000	 4.386928e-002	3.38164
 81.23243	12.24000	 4.968071e-002	3.38159
 81.33248	12.26000	 5.595408e-002	3.38153
 81.43252	12.28000	 6.274450e-002	3.38148
 81.53244	12.30000	 6.934415e-002	3.38143
 81.63248	12.32000	 7.637896e-002	3.38137
 81.73243	12.34000	 8.344155e-002	3.38132
 81.83246	12.36000	 9.091179e-002	3.38126
 81.93252	12.38000	 9.843736e-002	3.38121
 82.03254	12.40000	       0.10673	3.38115
 82.13244	12.42000	       0.11489	3.38109
 82.23243	12.44000	       0.12344	3.38104
 82.33234	12.46000	       0.13207	3.38098
 82.43230	12.48000	       0.14116	3.38093
 82.53218	12.50000	       0.15057	3.38087
 82.63215	12.52000	       0.16029	3.38081
 82.73210	12.54000	       0.17019	3.38076
 82.83205	12.56000	       0.18056	3.38070
 82.93205	12.58000	       0.19145	3.38064
 83.03203	12.60000	       0.20240	3.38058
 83.13203	12.62000	       0.21395	3.38052
 83.23205	12.64000	       0.22596	3.38047
 83.33208	12.66000	       0.23822	3.38041
 83.43207	12.68000	       0.25111	3.38035
 83.53211	12.70000	       0.26416	3.38029
 83.63211	12.72000	       0.27778	3.38023
 83.73215	12.74000	       0.29214	3.38017
 83.83220	12.76000	       0.30644	3.38011
 83.93223	12.78000	       0.32161	3.38005
 84.03225	12.80000	       0.33705	3.37999
 84.13226	12.82000	       0.35296	3.37993
 84.23230	12.84000	       0.36942	3.37987
 84.33230	12.86000	       0.38659	3.37981
 84.43231	12.88000	       0.40400	3.37975
 84.53233	12.90000	       0.42185	3.37969
 84.63231	12.92000	       0.44054	3.37963
 84.73243	12.94000	       0.45962	3.37956
 84.83256	12.96000	       0.47924	3.37950
 84.93259	12.98000	       0.49935	3.37944
 85.03262	13.00000	       0.52014	3.37938
 85.13266	13.02000	       0.54114	3.37931
 85.23277	13.04000	       0.56285	3.37925
 85.33282	13.06000	       0.58522	3.37919
 85.43289	13.08000	       0.60758	3.37912
 85.53300	13.10000	       0.63103	3.37906
 85.63315	13.12000	       0.65465	3.37900
 85.73323	13.14000	       0.67873	3.37893
 85.83321	13.16000	       0.70339	3.37887
 85.93316	13.18000	       0.72812	3.37880
 86.03305	13.20000	       0.75321	3.37874
 86.13302	13.22000	       0.77887	3.37867
 86.23300	13.24000	       0.80499	3.37861
 86.33298	13.26000	       0.83081	3.37854
 86.43297	13.28000	       0.85672	3.37848
 86.53297	13.30000	       0.88290	3.37841
 86.63302	13.32000	       0.90935	3.37834
 86.73292	13.34000	       0.93550	3.37828
 86.83280	13.36000	       0.96174	3.37821
 86.93274	13.38000	       0.98787	3.37814
 87.03269	13.40000	       1.01364	3.37808
 87.13272	13.42000	       1.03889	3.37801
 87.23269	13.44000	       1.06408	3.37794
 87.33269	13.46000	       1.08881	3.37787
 87.43261	13.48000	       1.11275	3.37781
 87.53252	13.50000	       1.13615	3.37774
 87.63241	13.52000	       1.15860	3.37767
 87.73230	13.54000	       1.18086	3.37760
 87.83231	13.56000	       1.20181	3.37753
 87.93236	13.58000	       1.22203	3.37746
 88.03234	13.60000	       1.24108	3.37739
 88.13236	13.62000	       1.25912	3.37732
 88.23233	13.64000	       1.27585	3.37725
 88.33225	13.66000	       1.29158	3.37718
 88.43223	13.68000	       1.30551	3.37711
 88.53218	13.70000	       1.31859	3.37704
 88.63216	13.72000	       1.33037	3.37697
 88.73213	13.74000	       1.34041	3.37690
 88.83211	13.76000	       1.34911	3.37683
 88.93216	13.78000	       1.35635	3.37676
 89.03220	13.80000	       1.36200	3.37669
 89.13221	13.82000	       1.36592	3.37661
 89.23208	13.84000	       1.36899	3.37654
 89.33192	13.86000	       1.36967	3.37647
 89.43179	13.88000	       1.36957	3.37640
 89.53162	13.90000	       1.36763	3.37632
 89.63144	13.92000	       1.36404	3.37625
 89.73136	13.94000	       1.35911	3.37618
 89.83128	13.96000	       1.35320	3.37610
 89.93123	13.98000	       1.34520	3.37603
 90.03134	14.00000	       1.33637	3.37596
 90.13143	14.02000	       1.32594	3.37588
 90.23139	14.04000	       1.31420	3.37581
 90.33133	14.06000	       1.30156	3.37573
 90.43120	14.08000	       1.28748	3.37566
 90.53107	14.10000	       1.27249	3.37558
 90.63095	14.12000	       1.25582	3.37551
 90.73087	14.14000	       1.23863	3.37543
 90.83087	14.16000	       1.22044	3.37536
 90.93077	14.18000	       1.20161	3.37528
 91.03061	14.20000	       1.18168	3.37520
 91.13054	14.22000	       1.16113	3.37513
 91.23051	14.24000	       1.14006	3.37505
 91.33052	14.26000	       1.11885	3.37497
 91.43054	14.28000	       1.09642	3.37490
 91.53062	14.30000	       1.07424	3.37482
 91.63072	14.32000	       1.05169	3.37474
 91.73075	14.34000	       1.02844	3.37466
 91.83077	14.36000	       1.00522	3.37458
 91.93071	14.38000	       0.98175	3.37451
 92.03057	14.40000	       0.95825	3.37443
 92.13046	14.42000	       0.93490	3.37435
 92.23041	14.44000	       0.91160	3.37427
 92.33043	14.46000	       0.88835	3.37419
 92.43054	14.48000	       0.86532	3.37411
 92.53066	14.50000	       0.84253	3.37403
 92.63069	14.52000	       0.81974	3.37395
 92.73072	14.54000	       0.79764	3.37387
 92.83070	14.56000	       0.77545	3.37379
 92.93072	14.58000	       0.75393	3.37371
 93.03079	14.60000	       0.73244	3.37363
 93.13085	14.62000	       0.71159	3.37355
 93.23089	14.64000	       0.69123	3.37347
 93.33093	14.66000	       0.67119	3.37338
 93.43093	14.68000	       0.65165	3.37330
 93.53092	14.70000	       0.63253	3.37322
 93.63092	14.72000	       0.61378	3.37314
 93.73098	14.74000	       0.59556	3.37306
 93.83111	14.76000	       0.57792	3.37297
 93.93120	14.78000	       0.56068	3.37289
 94.03129	14.80000	       0.54378	3.37281
 94.13131	14.82000	       0.52755	3.37272
 94.23133	14.84000	       0.51151	3.37264
 94.33131	14.86000	       0.49602	3.37256
 94.43123	14.88000	       0.48099	3.37247
 94.53123	14.90000	       0.46667	3.37239
 94.63126	14.92000	       0.45257	3.37230
 94.73133	14.94000	       0.43876	3.37222
 94.83143	14.96000	       0.42534	3.37213
 94.93154	14.98000	       0.41249	3.37205
 95.03164	15.00000	       0.40018	3.37196
 95.13169	15.02000	       0.38778	3.37188
 95.23175	15.04000	       0.37595	3.37179
 95.33175	15.06000	       0.36472	3.37171
 95.43180	15.08000	       0.35379	3.37162
 95.53192	15.10000	       0.34303	3.37153
 95.63198	15.12000	       0.33289	3.37145
 95.73198	15.14000	       0.32283	3.37136
 95.83192	15.16000	       0.31318	3.37127
 95.93180	15.18000	       0.30345	3.37119
 96.03174	15.20000	       0.29435	3.37110
 96.13175	15.22000	       0.28564	3.37101
 96.23179	15.24000	       0.27724	3.37092
 96.33190	15.26000	       0.26894	3.37083
 96.43197	15.28000	       0.26086	3.37075
 96.53198	15.30000	       0.25327	3.37066
 96.63198	15.32000	       0.24571	3.37057
 96.73197	15.34000	       0.23877	3.37048
 96.83193	15.36000	       0.23192	3.37039
 96.93189	15.38000	       0.22506	3.37030
 97.03175	15.40000	       0.21829	3.37021
 97.13172	15.42000	       0.21178	3.37012
 97.23170	15.44000	       0.20572	3.37003
 97.33170	15.46000	       0.19970	3.36994
 97.43172	15.48000	       0.19385	3.36985
 97.53172	15.50000	       0.18817	3.36976
 97.63170	15.52000	       0.18286	3.36967
 97.73174	15.54000	       0.17737	3.36957
 97.83174	15.56000	       0.17214	3.36948
 97.93177	15.58000	       0.16711	3.36939
 98.03182	15.60000	       0.16218	3.36930
 98.13180	15.62000	       0.15750	3.36921
 98.23177	15.64000	       0.15306	3.36911
 98.33169	15.66000	       0.14862	3.36902
 98.43175	15.68000	       0.14428	3.36893
 98.53172	15.70000	       0.14003	3.36884
 98.63175	15.72000	       0.13594	3.36874
 98.73182	15.74000	       0.13205	3.36865
 98.83189	15.76000	       0.12820	3.36856
 98.93198	15.78000	       0.12469	3.36846
 99.03211	15.80000	       0.12109	3.36837
 99.13220	15.82000	       0.11726	3.36827
 99.23223	15.84000	       0.11400	3.36818
 99.33229	15.86000	       0.11063	3.36808
 99.43236	15.88000	       0.10744	3.36799
 99.53234	15.90000	       0.10424	3.36789
 99.63239	15.92000	       0.10108	3.36780
 99.73233	15.94000	 9.803869e-002	3.36770
 99.83236	15.96000	 9.513026e-002	3.36760
 99.93239	15.98000	 9.235780e-002	3.36751
100.03239	16.00000	 8.961490e-002	3.36741
100.13243	16.02000	 8.687615e-002	3.36732
100.23249	16.04000	 8.413726e-002	3.36722
100.33251	16.06000	 8.150777e-002	3.36712
100.43244	16.08000	 7.945071e-002	3.36702
100.53241	16.10000	 7.698367e-002	3.36693
100.63243	16.12000	 7.457217e-002	3.36683
100.73239	16.14000	 7.226867e-002	3.36673
100.83228	16.16000	 7.010298e-002	3.36663
100.93218	16.18000	 6.815524e-002	3.36653
101.03203	16.20000	 6.586837e-002	3.36644
101.13198	16.22000	 6.366693e-002	3.36634
101.23197	16.24000	 6.149336e-002	3.36624
101.33192	16.26000	 5.972859e-002	3.36614
101.43185	16.28000	 5.749947e-002	3.36604
101.53180	16.30000	 5.548905e-002	3.36594
101.63171	16.32000	 5.377930e-002	3.36584
101.73167	16.34000	 5.179560e-002	3.36574
101.83169	16.36000	 4.986677e-002	3.36564
101.93167	16.38000	 4.823826e-002	3.36554
102.03166	16.40000	 4.645781e-002	3.36544
102.13166	16.42000	 4.484018e-002	3.36534
102.23161	16.44000	 4.308586e-002	3.36524
102.33157	16.46000	 4.122147e-002	3.36514
102.43157	16.48000	 3.982207e-002	3.36503
102.53161	16.50000	 3.839384e-002	3.36493
102.63159	16.52000	 3.696695e-002	3.36483
102.73166	16.54000	 3.567622e-002	3.36473
102.83174	16.56000	 3.411223e-002	3.36462
102.93177	16.58000	 3.257581e-002	3.36452
103.03180	16.60000	 3.133886e-002	3.36442
103.13179	16.62000	 2.998976e-002	3.36432
103.23172	16.64000	 2.874987e-002	3.36421
103.33167	16.66000	 2.726435e-002	3.36411
103.43164	16.68000	 2.594268e-002	3.36400
103.53157	16.70000	 2.473060e-002	3.36390
103.63162	16.72000	 2.346344e-002	3.36380
103.73166	16.74000	 2.219655e-002	3.36369
103.83162	16.76000	 2.120216e-002	3.36359
103.93167	16.78000	 2.001640e-002	3.36348
104.03167	16.80000	 1.909957e-002	3.36338
104.13162	16.82000	 1.789968e-002	3.36327
104.23166	16.84000	 1.694463e-002	3.36317
104.33172	16.86000	 1.585429e-002	3.36306
104.43177	16.88000	 1.487214e-002	3.36296
104.53179	16.90000	 1.380828e-002	3.36285
104.63182	16.92000	 1.274436e-002	3.36274
104.73180	16.94000	 1.162571e-002	3.36264
104.83175	16.96000	 1.058899e-002	3.36253
104.93167	16.98000	 9.607249e-003	3.36242
105.03162	17.00000	 8.736436e-003	3.36232
105.13159	17.02000	 7.653026e-003	3.36221
105.23157	17.04000	 6.951233e-003	3.36210
105.33161	17.06000	 5.976344e-003	3.36199
105.43161	17.08000	 4.783016e-003	3.36188
105.53161	17.10000	 3.999036e-003	3.36178
105.63167	17.12000	 3.270411e-003	3.36167
105.73171	17.14000	 2.486691e-003	3.36156
105.83177	17.16000	 1.756896e-003	3.36145
105.93184	17.18000	 8.636935e-004	3.36134
106.03180	17.20000	-8.900033e-006	3.36123
106.13184	17.22000	-7.302899e-004	3.36112
106.23179	17.24000	-1.534121e-003	3.36101
106.33174	17.26000	-2.283301e-003	3.36090
106.43180	17.28000	-3.196303e-003	3.36079
106.53182	17.30000	-3.863904e-003	3.36068
106.63184	17.32000	-4.612533e-003	3.36057
106.73184	17.34000	-5.362283e-003	3.36046
106.83185	17.36000	-6.138725e-003	3.36035
106.93197	17.38000	-6.915594e-003	3.36024
107.03205	17.40000	-7.443411e-003	3.36013
107.13218	17.42000	-8.263462e-003	3.36001
107.23230	17.44000	-9.111998e-003	3.35990
107.33239	17.46000	-9.548773e-003	3.35979
107.43254	17.48000	-1.034126e-002	3.35968
107.53261	17.50000	-1.091634e-002	3.35956
107.63270	17.52000	-1.165492e-002	3.35945
107.73285	17.54000	-1.206484e-002	3.35934
107.83297	17.56000	-1.288559e-002	3.35922
107.93311	17.58000	-1.351486e-002	3.35911
108.03323	17.60000	-1.400558e-002	3.35900
108.13330	17.62000	-1.449424e-002	3.35888
108.23331	17.64000	-1.509205e-002	3.35877
108.33338	17.66000	-1.585374e-002	3.35865
108.43338	17.68000	-1.634216e-002	3.35854
108.53333	17.70000	-1.710430e-002	3.35843
108.63329	17.72000	-1.762017e-002	3.35831
108.73329	17.74000	-1.799849e-002	3.35820
108.83323	17.76000	-1.843266e-002	3.35808
108.93315	17.78000	-1.913988e-002	3.35797
109.03308	17.80000	-1.967946e-002	3.35785
109.13297	17.82000	-2.001618e-002	3.35773
109.23287	17.84000	-2.021675e-002	3.35762
109.33279	17.86000	-2.066374e-002	3.35750
109.43269	17.88000	-2.102791e-002	3.35738
109.53257	17.90000	-2.152972e-002	3.35727
109.63246	17.92000	-2.194942e-002	3.35715
109.73228	17.94000	-2.234107e-002	3.35703
109.83211	17.96000	-2.317158e-002	3.35692
109.93193	17.98000	-2.328982e-002	3.35680
110.03175	18.00000	-2.414818e-002	3.35668
110.13166	18.02000	-2.454227e-002	3.35656
110.23157	18.04000	-2.485459e-002	3.35645
110.33148	18.06000	-2.544117e-002	3.35633
110.43139	18.08000	-2.605446e-002	3.35621
110.53126	18.10000	-2.647680e-002	3.35609
110.63116	18.12000	-2.700836e-002	3.35597
110.73116	18.14000	-2.726568e-002	3.35585
110.83121	18.16000	-2.787984e-002	3.35573
110.93133	18.18000	-2.821903e-002	3.35561
111.03148	18.20000	-2.867455e-002	3.35549
111.13164	18.22000	-2.911504e-002	3.35537
111.23177	18.24000	-2.966480e-002	3.35525
111.33193	18.26000	-3.007797e-002	3.35513
111.43210	18.28000	-3.043602e-002	3.35501
111.53228	18.30000	-3.082114e-002	3.35489
111.63243	18.32000	-3.150876e-002	3.35477
111.73254	18.34000	-3.161885e-002	3.35465
111.83261	18.36000	-3.211366e-002	3.35453
111.93261	18.38000	-3.269106e-002	3.35440
112.03259	18.40000	-3.291274e-002	3.35428
112.13262	18.42000	-3.319026e-002	3.35416
112.23266	18.44000	-3.363223e-002	3.35404
112.33267	18.46000	-3.407352e-002	3.35391
112.43266	18.48000	-3.459813e-002	3.35379
112.53269	18.50000	-3.451980e-002	3.35367
112.63264	18.52000	-3.474261e-002	3.35355
112.73262	18.54000	-3.482838e-002	3.35342
112.83257	18.56000	-3.513381e-002	3.35330
112.93244	18.58000	-3.546704e-002	3.35317
113.03228	18.60000	-3.568632e-002	3.35305
113.13215	18.62000	-3.611708e-002	3.35293
113.23211	18.64000	-3.638374e-002	3.35280
113.33208	18.66000	-3.684235e-002	3.35268
113.43193	18.68000	-3.708236e-002	3.35255
113.53177	18.70000	-3.721200e-002	3.35243
113.63164	18.72000	-3.764363e-002	3.35230
113.73149	18.74000	-3.793746e-002	3.35218
113.83133	18.76000	-3.855967e-002	3.35205
113.93120	18.78000	-3.901920e-002	3.35193
114.03116	18.80000	-3.941954e-002	3.35180
114.13113	18.82000	-3.967662e-002	3.35167
114.23111	18.84000	-4.001385e-002	3.35155
114.33120	18.86000	-4.010640e-002	3.35142
114.43131	18.88000	-4.047253e-002	3.35129
114.53143	18.90000	-4.072896e-002	3.35117
114.63156	18.92000	-4.090349e-002	3.35104
114.73172	18.94000	-4.124262e-002	3.35091
114.83182	18.96000	-4.147169e-002	3.35078
114.93185	18.98000	-4.175565e-002	3.35066
115.03200	19.00000	-4.201828e-002	3.35053
115.13210	19.02000	-4.246110e-002	3.35040
115.23218	19.04000	-4.271119e-002	3.35027
115.33213	19.06000	-4.298871e-002	3.35014
115.43211	19.08000	-4.321211e-002	3.35001
115.53215	19.10000	-4.343480e-002	3.34988
115.63215	19.12000	-4.382289e-002	3.34975
115.73218	19.14000	-4.399040e-002	3.34962
115.83220	19.16000	-4.426912e-002	3.34949
115.93228	19.18000	-4.440958e-002	3.34937
116.03231	19.20000	-4.452149e-002	3.34923
116.13230	19.22000	-4.482356e-002	3.34910
116.23233	19.24000	-4.498841e-002	3.34897
116.33226	19.26000	-4.520853e-002	3.34884
116.43221	19.28000	-4.542868e-002	3.34871
116.53225	19.30000	-4.548378e-002	3.34858
116.63221	19.32000	-4.567614e-002	3.34845
116.73220	19.34000	-4.581435e-002	3.34832
116.83215	19.36000	-4.600674e-002	3.34819
116.93215	19.38000	-4.611644e-002	3.34805
117.03208	19.40000	-4.647722e-002	3.34792
117.13198	19.42000	-4.684569e-002	3.34779
117.23190	19.44000	-4.710399e-002	3.34766
117.33182	19.46000	-4.752779e-002	3.34752
117.43180	19.48000	-4.767597e-002	3.34739
117.53180	19.50000	-4.782487e-002	3.34726
117.63180	19.52000	-4.808401e-002	3.34713
117.73182	19.54000	-4.850759e-002	3.34699
117.83193	19.56000	-4.846433e-002	3.34686
117.93203	19.58000	-4.880522e-002	3.34672
118.03211	19.60000	-4.891794e-002	3.34659
118.13225	19.62000	-4.917567e-002	3.34645
118.23231	19.64000	-4.929607e-002	3.34632
118.33236	19.66000	-4.936156e-002	3.34619
118.43236	19.68000	-4.967430e-002	3.34605
118.53230	19.70000	-4.984970e-002	3.34592
118.63225	19.72000	-4.996982e-002	3.34578
118.73223	19.74000	-5.017345e-002	3.34564
118.83221	19.76000	-5.034855e-002	3.34551
118.93223	19.78000	-5.049654e-002	3.34537
119.03223	19.80000	-5.067296e-002	3.34524
119.13225	19.82000	-5.082464e-002	3.34510
119.23221	19.84000	-5.092209e-002	3.34496
119.33220	19.86000	-5.123941e-002	3.34483
119.43221	19.88000	-5.117164e-002	3.34469
119.53221	19.90000	-5.135158e-002	3.34455
119.63223	19.92000	-5.153118e-002	3.34442
119.73218	19.94000	-5.179326e-002	3.34428
119.83215	19.96000	-5.197254e-002	3.34414
119.93213	19.98000	-5.201475e-002	3.34400
120.03211	20.00000	-5.233340e-002	3.34386
120.13202	20.02000	-5.235143e-002	3.34373
120.23192	20.04000	-5.270008e-002	3.34359
120.33189	20.06000	-5.280061e-002	3.34345
120.43184	20.08000	-5.306648e-002	3.34331
120.53187	20.10000	-5.335987e-002	3.34317
120.63193	20.12000	-5.357115e-002	3.34303
120.73200	20.14000	-5.380923e-002	3.34289
120.83208	20.16000	-5.404806e-002	3.34275
120.93216	20.18000	-5.420332e-002	3.34261
121.03221	20.20000	-5.441840e-002	3.34247
121.13228	20.22000	-5.469483e-002	3.34233
121.23239	20.24000	-5.480590e-002	3.34219
121.33244	20.26000	-5.510988e-002	3.34205
121.43238	20.28000	-5.530386e-002	3.34191
121.53234	20.30000	-5.549713e-002	3.34177
121.63239	20.32000	-5.577403e-002	3.34163
121.73239	20.34000	-5.588519e-002	3.34148
121.83233	20.36000	-5.616214e-002	3.34134
121.93228	20.38000	-5.641123e-002	3.34120
122.03221	20.40000	-5.671803e-002	3.34106
122.13216	20.42000	-5.678392e-002	3.34092
122.23216	20.44000	-5.726255e-002	3.34077
122.33215	20.46000	-5.721878e-002	3.34063
122.43221	20.48000	-5.736801e-002	3.34049
122.53223	20.50000	-5.768127e-002	3.34035
122.63223	20.52000	-5.788483e-002	3.34020
122.73223	20.54000	-5.828143e-002	3.34006
122.83220	20.56000	-5.848541e-002	3.33991
122.93213	20.58000	-5.879876e-002	3.33977
123.03215	20.60000	-5.907636e-002	3.33963
123.13210	20.62000	-5.939116e-002	3.33948
123.23202	20.64000	-5.953975e-002	3.33934
123.33200	20.66000	-5.982670e-002	3.33919
123.43200	20.68000	-6.022380e-002	3.33905
123.53205	20.70000	-6.056551e-002	3.33890
123.63197	20.72000	-6.066020e-002	3.33876
123.73195	20.74000	-6.097481e-002	3.33861
123.83195	20.76000	-6.120648e-002	3.33847
123.93198	20.78000	-6.146643e-002	3.33832
124.03202	20.80000	-6.150860e-002	3.33818
124.13208	20.82000	-6.199894e-002	3.33803
124.23216	20.84000	-6.202080e-002	3.33788
124.33215	20.86000	-6.231806e-002	3.33774
124.43221	20.88000	-6.253238e-002	3.33759
124.53225	20.90000	-6.288551e-002	3.33744
124.63218	20.92000	-6.307232e-002	3.33730
124.73223	20.94000	-6.336971e-002	3.33715
124.83226	20.96000	-6.375048e-002	3.33700
124.93220	20.98000	-6.399247e-002	3.33685
125.03215	21.00000	-6.434794e-002	3.33670
125.13211	21.02000	-6.454579e-002	3.33656
125.23210	21.04000	-6.499053e-002	3.33641
125.33211	21.06000	-6.551906e-002	3.33626
125.43211	21.08000	-6.579930e-002	3.33611
125.53207	21.10000	-6.599690e-002	3.33596
125.63208	21.12000	-6.646972e-002	3.33581
125.73211	21.14000	-6.683200e-002	3.33566
125.83213	21.16000	-6.741623e-002	3.33551
125.93223	21.18000	-6.750410e-002	3.33536
126.03233	21.20000	-6.774547e-002	3.33521
126.13236	21.22000	-6.823691e-002	3.33506
126.23239	21.24000	-6.837008e-002	3.33491
126.33241	21.26000	-6.866937e-002	3.33476
126.43239	21.28000	-6.902383e-002	3.33461
126.53241	21.30000	-6.957057e-002	3.33446
126.63244	21.32000	-6.970456e-002	3.33431
126.73244	21.34000	-7.033409e-002	3.33416
126.83236	21.36000	-7.079865e-002	3.33401
126.93234	21.38000	-7.093237e-002	3.33386
127.03231	21.40000	-7.137837e-002	3.33371
127.13234	21.42000	-7.214940e-002	3.33355
127.23239	21.44000	-7.234035e-002	3.33340
127.33233	21.46000	-7.280781e-002	3.33325
127.43238	21.48000	-7.335696e-002	3.33310
127.53239	21.50000	-7.385246e-002	3.33294
127.63239	21.52000	-7.415422e-002	3.33279
127.73244	21.54000	-7.462114e-002	3.33264
127.83249	21.56000	-7.514363e-002	3.33248
127.93244	21.58000	-7.544623e-002	3.33233
128.03243	21.60000	-7.591157e-002	3.33218
128.13231	21.62000	-7.634429e-002	3.33202
128.23228	21.64000	-7.686056e-002	3.33187
128.33221	21.66000	-7.743242e-002	3.33172
128.43216	21.68000	-7.781083e-002	3.33156
128.53208	21.70000	-7.827206e-002	3.33141
128.63205	21.72000	-7.898168e-002	3.33125
128.73202	21.74000	-7.958064e-002	3.33110
128.83202	21.76000	-7.995960e-002	3.33094
128.93200	21.78000	-8.058662e-002	3.33079
129.03205	21.80000	-8.105055e-002	3.33063
129.13200	21.82000	-8.171172e-002	3.33047
129.23198	21.84000	-8.226257e-002	3.33032
129.33198	21.86000	-8.275827e-002	3.33016
129.43183	21.88000	-8.330886e-002	3.33001
129.53179	21.90000	-8.394268e-002	3.32985
129.63196	21.92000	-8.463144e-002	3.32969
129.73212	21.94000	-8.515535e-002	3.32954
129.83218	21.96000	-8.578901e-002	3.32938
129.93220	21.98000	-8.645143e-002	3.32922
129.98251	21.99000	-8.678836e-002	3.32914