File: data/ExpDat_SK_Clear_resin_entalp75kpm_20-150.txt
#EXPORTTYPE:                 	DATA SINGLE
#FILE:                       	SK_Clear_resin_entalp75kpm_20-150.ngb-sdg
#FORMAT:                     	NETZSCH5
#FTYPE:                      	ASCII
#IDENTITY:                   	SK_clear_resin
#DECIMAL:                    	POINT
#SEPARATOR:                  	TAB
#MTYPE:                      	DSC
#INSTRUMENT:                 	NETZSCH DSC 214
#PROJECT:                    	?ø?†??-Ø
#DATE/TIME:                  	13.09.2019 18:37:53 (UTC+3)
#CORR. FILE:
#TEMPCAL:                    	applied
#SENSITIVITY:                	applied
#LABORATORY:                 	CISIS
#OPERATOR:                   	Nasonov
#REMARK:
#SAMPLE:                     	1070-G290S -0-Ù.1-3-17X3
#SAMPLE MASS /mg:            	9.19
#MATERIAL:
#REFERENCE:
#REFERENCE MASS /mg:         	7.76
#TYPE OF CRUCIBLE:           	Concavus Pan Al, pierced lid
#SAMPLE CRUCIBLE MASS /mg:   	0
#REFERENCE CRUCIBLE MASS /mg:	0
#M.RANGE /ßV:                	5000
#TAU-R:                      	---
#CORR. CODE:                 	009
#EXO:                        	+1
#RANGE:                      	20ËC/7.5(K/min)/150ËC
#SEGMENT:                    	S1/1
#SEG. 1:                     	20ËC/7.5(K/min)/150ËC

##Temp./ËC	Time/min	DSC/(mW/mg)	Sensit./(uV/mW)
 20.05400	 0.00000	 2.252373e-002	3.36737
 20.05122	 0.02000	 2.286732e-002	3.36737
 20.07247	 0.04000	 2.393073e-002	3.36739
 20.13616	 0.06000	 3.294484e-002	3.36746
 20.24139	 0.08000	 4.638733e-002	3.36757
 20.38249	 0.10000	 5.609496e-002	3.36771
 20.55100	 0.12000	 5.952858e-002	3.36789
 20.72618	 0.14000	 5.587360e-002	3.36807
 20.88084	 0.16000	 4.571805e-002	3.36822
 21.05215	 0.18000	 2.928867e-002	3.36840
 21.23807	 0.20000	 7.450274e-003	3.36859
 21.43527	 0.22000	-1.822617e-002	3.36878
 21.64056	 0.24000	-4.663039e-002	3.36899
 21.85067	 0.26000	-7.653377e-002	3.36920
 22.06287	 0.28000	      -0.10621	3.36941
 22.27435	 0.30000	      -0.13513	3.36962
 22.48278	 0.32000	      -0.16176	3.36982
 22.68645	 0.34000	      -0.18539	3.37002
 22.88393	 0.36000	      -0.20638	3.37021
 23.07415	 0.38000	      -0.22307	3.37039
 23.25664	 0.40000	      -0.23626	3.37057
 23.43138	 0.42000	      -0.24568	3.37073
 23.59825	 0.44000	      -0.25180	3.37089
 23.75758	 0.46000	      -0.25468	3.37104
 23.91013	 0.48000	      -0.25463	3.37118
 24.05662	 0.50000	      -0.25212	3.37132
 24.19787	 0.52000	      -0.24794	3.37145
 24.33476	 0.54000	      -0.24170	3.37158
 24.46822	 0.56000	      -0.23453	3.37170
 24.59933	 0.58000	      -0.22682	3.37182
 24.72895	 0.60000	      -0.21879	3.37194
 24.85776	 0.62000	      -0.21076	3.37206
 24.98655	 0.64000	      -0.20310	3.37218
 25.11585	 0.66000	      -0.19587	3.37229
 25.24611	 0.68000	      -0.18967	3.37241
 25.37775	 0.70000	      -0.18433	3.37253
 25.51109	 0.72000	      -0.17961	3.37265
 25.64624	 0.74000	      -0.17589	3.37277
 25.78325	 0.76000	      -0.17356	3.37289
 25.92222	 0.78000	      -0.17152	3.37301
 26.06324	 0.80000	      -0.17070	3.37314
 26.20591	 0.82000	      -0.17041	3.37326
 26.35024	 0.84000	      -0.17049	3.37339
 26.49604	 0.86000	      -0.17109	3.37351
 26.64316	 0.88000	      -0.17269	3.37364
 26.79136	 0.90000	      -0.17444	3.37377
 26.94027	 0.92000	      -0.17673	3.37390
 27.08991	 0.94000	      -0.17831	3.37402
 27.24018	 0.96000	      -0.18059	3.37415
 27.39073	 0.98000	      -0.18247	3.37428
 27.54142	 1.00000	      -0.18442	3.37440
 27.69213	 1.02000	      -0.18628	3.37453
 27.84273	 1.04000	      -0.18802	3.37465
 27.99318	 1.06000	      -0.18960	3.37478
 28.14358	 1.08000	      -0.19093	3.37490
 28.29396	 1.10000	      -0.19170	3.37503
 28.44398	 1.12000	      -0.19292	3.37515
 28.59380	 1.14000	      -0.19398	3.37527
 28.74336	 1.16000	      -0.19485	3.37539
 28.89267	 1.18000	      -0.19486	3.37551
 29.04191	 1.20000	      -0.19534	3.37563
 29.19093	 1.22000	      -0.19543	3.37575
 29.33978	 1.24000	      -0.19545	3.37587
 29.48858	 1.26000	      -0.19581	3.37598
 29.63735	 1.28000	      -0.19587	3.37610
 29.78613	 1.30000	      -0.19596	3.37621
 29.93515	 1.32000	      -0.19603	3.37633
 30.08411	 1.34000	      -0.19594	3.37644
 30.23315	 1.36000	      -0.19573	3.37656
 30.38207	 1.38000	      -0.19584	3.37667
 30.53115	 1.40000	      -0.19588	3.37679
 30.68018	 1.42000	      -0.19607	3.37690
 30.82936	 1.44000	      -0.19633	3.37701
 30.97876	 1.46000	      -0.19630	3.37712
 31.12820	 1.48000	      -0.19641	3.37723
 31.27776	 1.50000	      -0.19696	3.37734
 31.42736	 1.52000	      -0.19706	3.37745
 31.57698	 1.54000	      -0.19732	3.37756
 31.72678	 1.56000	      -0.19740	3.37767
 31.87656	 1.58000	      -0.19778	3.37778
 32.02627	 1.60000	      -0.19799	3.37788
 32.17613	 1.62000	      -0.19832	3.37799
 32.32585	 1.64000	      -0.19872	3.37810
 32.47576	 1.66000	      -0.19898	3.37820
 32.62562	 1.68000	      -0.19928	3.37831
 32.77562	 1.70000	      -0.19952	3.37841
 32.92565	 1.72000	      -0.19972	3.37852
 33.07555	 1.74000	      -0.19979	3.37862
 33.22545	 1.76000	      -0.20002	3.37872
 33.37533	 1.78000	      -0.20043	3.37883
 33.52535	 1.80000	      -0.20068	3.37893
 33.67524	 1.82000	      -0.20103	3.37903
 33.82536	 1.84000	      -0.20097	3.37913
 33.97547	 1.86000	      -0.20110	3.37923
 34.12553	 1.88000	      -0.20130	3.37933
 34.27556	 1.90000	      -0.20139	3.37943
 34.42553	 1.92000	      -0.20150	3.37952
 34.57555	 1.94000	      -0.20179	3.37962
 34.72551	 1.96000	      -0.20198	3.37972
 34.87545	 1.98000	      -0.20214	3.37981
 35.02545	 2.00000	      -0.20235	3.37991
 35.17562	 2.02000	      -0.20257	3.38001
 35.32576	 2.04000	      -0.20285	3.38010
 35.47596	 2.06000	      -0.20305	3.38019
 35.62613	 2.08000	      -0.20333	3.38029
 35.77629	 2.10000	      -0.20350	3.38038
 35.92635	 2.12000	      -0.20373	3.38047
 36.07636	 2.14000	      -0.20404	3.38056
 36.22645	 2.16000	      -0.20423	3.38065
 36.37656	 2.18000	      -0.20439	3.38074
 36.52660	 2.20000	      -0.20467	3.38083
 36.67660	 2.22000	      -0.20508	3.38092
 36.82655	 2.24000	      -0.20532	3.38101
 36.97644	 2.26000	      -0.20570	3.38110
 37.12631	 2.28000	      -0.20584	3.38118
 37.27622	 2.30000	      -0.20592	3.38127
 37.42616	 2.32000	      -0.20631	3.38136
 37.57620	 2.34000	      -0.20641	3.38144
 37.72624	 2.36000	      -0.20666	3.38153
 37.87615	 2.38000	      -0.20700	3.38161
 38.02616	 2.40000	      -0.20711	3.38169
 38.17620	 2.42000	      -0.20734	3.38178
 38.32624	 2.44000	      -0.20766	3.38186
 38.47635	 2.46000	      -0.20789	3.38194
 38.62651	 2.48000	      -0.20837	3.38202
 38.77665	 2.50000	      -0.20872	3.38210
 38.92696	 2.52000	      -0.20939	3.38218
 39.07722	 2.54000	      -0.20941	3.38226
 39.22742	 2.56000	      -0.20954	3.38234
 39.37745	 2.58000	      -0.20975	3.38242
 39.52747	 2.60000	      -0.20987	3.38250
 39.67736	 2.62000	      -0.21005	3.38257
 39.82735	 2.64000	      -0.21019	3.38265
 39.97736	 2.66000	      -0.21040	3.38273
 40.12735	 2.68000	      -0.21053	3.38280
 40.27731	 2.70000	      -0.21071	3.38287
 40.42736	 2.72000	      -0.21086	3.38295
 40.57738	 2.74000	      -0.21099	3.38302
 40.72733	 2.76000	      -0.21115	3.38309
 40.87731	 2.78000	      -0.21138	3.38317
 41.02731	 2.80000	      -0.21167	3.38324
 41.17736	 2.82000	      -0.21170	3.38331
 41.32747	 2.84000	      -0.21191	3.38338
 41.47756	 2.86000	      -0.21216	3.38345
 41.62765	 2.88000	      -0.21234	3.38352
 41.77782	 2.90000	      -0.21262	3.38359
 41.92802	 2.92000	      -0.21300	3.38365
 42.07809	 2.94000	      -0.21307	3.38372
 42.22820	 2.96000	      -0.21325	3.38379
 42.37829	 2.98000	      -0.21341	3.38386
 42.52829	 3.00000	      -0.21373	3.38392
 42.67827	 3.02000	      -0.21393	3.38399
 42.82836	 3.04000	      -0.21417	3.38405
 42.97851	 3.06000	      -0.21446	3.38411
 43.12849	 3.08000	      -0.21481	3.38418
 43.27847	 3.10000	      -0.21515	3.38424
 43.42849	 3.12000	      -0.21526	3.38430
 43.57853	 3.14000	      -0.21530	3.38436
 43.72860	 3.16000	      -0.21555	3.38442
 43.87840	 3.18000	      -0.21584	3.38448
 44.02818	 3.20000	      -0.21618	3.38454
 44.17791	 3.22000	      -0.21623	3.38460
 44.32775	 3.24000	      -0.21631	3.38466
 44.47753	 3.26000	      -0.21648	3.38472
 44.62749	 3.28000	      -0.21661	3.38478
 44.77744	 3.30000	      -0.21688	3.38483
 44.92733	 3.32000	      -0.21725	3.38489
 45.07725	 3.34000	      -0.21717	3.38494
 45.22729	 3.36000	      -0.21714	3.38500
 45.37735	 3.38000	      -0.21726	3.38505
 45.52744	 3.40000	      -0.21754	3.38511
 45.67760	 3.42000	      -0.21763	3.38516
 45.82784	 3.44000	      -0.21802	3.38521
 45.97822	 3.46000	      -0.21828	3.38526
 46.12858	 3.48000	      -0.21839	3.38532
 46.27902	 3.50000	      -0.21874	3.38537
 46.42940	 3.52000	      -0.21897	3.38542
 46.57976	 3.54000	      -0.21920	3.38547
 46.73004	 3.56000	      -0.21923	3.38552
 46.88029	 3.58000	      -0.21948	3.38556
 47.03053	 3.60000	      -0.21971	3.38561
 47.18069	 3.62000	      -0.21983	3.38566
 47.33089	 3.64000	      -0.22004	3.38571
 47.48095	 3.66000	      -0.22010	3.38575
 47.63085	 3.68000	      -0.22001	3.38580
 47.78078	 3.70000	      -0.22017	3.38584
 47.93062	 3.72000	      -0.22029	3.38589
 48.08051	 3.74000	      -0.22029	3.38593
 48.23047	 3.76000	      -0.22018	3.38597
 48.38042	 3.78000	      -0.22040	3.38602
 48.53036	 3.80000	      -0.22049	3.38606
 48.68029	 3.82000	      -0.22041	3.38610
 48.83018	 3.84000	      -0.22045	3.38614
 48.98009	 3.86000	      -0.22047	3.38618
 49.13005	 3.88000	      -0.22052	3.38622
 49.27995	 3.90000	      -0.22097	3.38626
 49.42995	 3.92000	      -0.22102	3.38630
 49.57998	 3.94000	      -0.22115	3.38633
 49.73011	 3.96000	      -0.22127	3.38637
 49.88011	 3.98000	      -0.22130	3.38641
 50.03009	 4.00000	      -0.22160	3.38644
 50.17995	 4.02000	      -0.22183	3.38648
 50.32980	 4.04000	      -0.22202	3.38651
 50.47962	 4.06000	      -0.22192	3.38655
 50.62951	 4.08000	      -0.22172	3.38658
 50.77947	 4.10000	      -0.22188	3.38661
 50.92958	 4.12000	      -0.22198	3.38665
 51.07965	 4.14000	      -0.22212	3.38668
 51.22960	 4.16000	      -0.22219	3.38671
 51.37965	 4.18000	      -0.22213	3.38674
 51.52965	 4.20000	      -0.22223	3.38677
 51.67971	 4.22000	      -0.22249	3.38680
 51.82971	 4.24000	      -0.22258	3.38683
 51.97982	 4.26000	      -0.22263	3.38686
 52.13007	 4.28000	      -0.22281	3.38689
 52.28033	 4.30000	      -0.22277	3.38691
 52.43065	 4.32000	      -0.22275	3.38694
 52.58087	 4.34000	      -0.22301	3.38697
 52.73095	 4.36000	      -0.22309	3.38699
 52.88107	 4.38000	      -0.22295	3.38702
 53.03127	 4.40000	      -0.22344	3.38704
 53.18138	 4.42000	      -0.22321	3.38707
 53.33151	 4.44000	      -0.22311	3.38709
 53.48156	 4.46000	      -0.22318	3.38711
 53.63164	 4.48000	      -0.22319	3.38713
 53.78162	 4.50000	      -0.22323	3.38716
 53.93164	 4.52000	      -0.22318	3.38718
 54.08156	 4.54000	      -0.22288	3.38720
 54.23153	 4.56000	      -0.22284	3.38722
 54.38160	 4.58000	      -0.22296	3.38724
 54.53149	 4.60000	      -0.22311	3.38725
 54.68151	 4.62000	      -0.22301	3.38727
 54.83156	 4.64000	      -0.22294	3.38729
 54.98145	 4.66000	      -0.22294	3.38731
 55.13136	 4.68000	      -0.22285	3.38732
 55.28124	 4.70000	      -0.22285	3.38734
 55.43118	 4.72000	      -0.22288	3.38735
 55.58102	 4.74000	      -0.22291	3.38737
 55.73098	 4.76000	      -0.22299	3.38738
 55.88102	 4.78000	      -0.22294	3.38740
 56.03111	 4.80000	      -0.22278	3.38741
 56.18109	 4.82000	      -0.22287	3.38742
 56.33091	 4.84000	      -0.22296	3.38743
 56.48087	 4.86000	      -0.22297	3.38744
 56.63084	 4.88000	      -0.22286	3.38745
 56.78089	 4.90000	      -0.22283	3.38746
 56.93087	 4.92000	      -0.22301	3.38747
 57.08095	 4.94000	      -0.22295	3.38748
 57.23105	 4.96000	      -0.22294	3.38749
 57.38116	 4.98000	      -0.22295	3.38750
 57.53125	 5.00000	      -0.22318	3.38750
 57.68144	 5.02000	      -0.22343	3.38751
 57.83175	 5.04000	      -0.22342	3.38752
 57.98180	 5.06000	      -0.22331	3.38752
 58.13189	 5.08000	      -0.22334	3.38753
 58.28204	 5.10000	      -0.22327	3.38753
 58.43231	 5.12000	      -0.22320	3.38754
 58.58249	 5.14000	      -0.22320	3.38754
 58.73255	 5.16000	      -0.22310	3.38754
 58.88260	 5.18000	      -0.22294	3.38754
 59.03247	 5.20000	      -0.22302	3.38754
 59.18235	 5.22000	      -0.22313	3.38755
 59.33224	 5.24000	      -0.22302	3.38755
 59.48222	 5.26000	      -0.22295	3.38755
 59.63224	 5.28000	      -0.22294	3.38754
 59.78216	 5.30000	      -0.22304	3.38754
 59.93195	 5.32000	      -0.22290	3.38754
 60.08184	 5.34000	      -0.22275	3.38754
 60.23169	 5.36000	      -0.22247	3.38754
 60.38151	 5.38000	      -0.22246	3.38753
 60.53136	 5.40000	      -0.22247	3.38753
 60.68120	 5.42000	      -0.22238	3.38752
 60.83113	 5.44000	      -0.22232	3.38752
 60.98122	 5.46000	      -0.22238	3.38751
 61.13140	 5.48000	      -0.22232	3.38750
 61.28160	 5.50000	      -0.22223	3.38750
 61.43180	 5.52000	      -0.22220	3.38749
 61.58193	 5.54000	      -0.22214	3.38748
 61.73198	 5.56000	      -0.22213	3.38747
 61.88207	 5.58000	      -0.22211	3.38746
 62.03215	 5.60000	      -0.22208	3.38745
 62.18220	 5.62000	      -0.22199	3.38744
 62.33224	 5.64000	      -0.22197	3.38743
 62.48227	 5.66000	      -0.22196	3.38742
 62.63227	 5.68000	      -0.22197	3.38741
 62.78235	 5.70000	      -0.22193	3.38739
 62.93236	 5.72000	      -0.22179	3.38738
 63.08229	 5.74000	      -0.22171	3.38737
 63.23224	 5.76000	      -0.22151	3.38735
 63.38215	 5.78000	      -0.22134	3.38734
 63.53193	 5.80000	      -0.22126	3.38732
 63.68176	 5.82000	      -0.22118	3.38730
 63.83171	 5.84000	      -0.22108	3.38729
 63.98158	 5.86000	      -0.22097	3.38727
 64.13147	 5.88000	      -0.22097	3.38725
 64.28144	 5.90000	      -0.22099	3.38723
 64.43144	 5.92000	      -0.22099	3.38722
 64.58142	 5.94000	      -0.22097	3.38720
 64.73145	 5.96000	      -0.22074	3.38718
 64.88144	 5.98000	      -0.22050	3.38715
 65.03142	 6.00000	      -0.22050	3.38713
 65.18138	 6.02000	      -0.22040	3.38711
 65.33135	 6.04000	      -0.22035	3.38709
 65.48129	 6.06000	      -0.22047	3.38707
 65.63129	 6.08000	      -0.22041	3.38704
 65.78122	 6.10000	      -0.22039	3.38702
 65.93115	 6.12000	      -0.22041	3.38699
 66.08116	 6.14000	      -0.22038	3.38697
 66.23133	 6.16000	      -0.22043	3.38694
 66.38135	 6.18000	      -0.22044	3.38692
 66.53136	 6.20000	      -0.22039	3.38689
 66.68135	 6.22000	      -0.22042	3.38686
 66.83133	 6.24000	      -0.22040	3.38683
 66.98140	 6.26000	      -0.22036	3.38681
 67.13144	 6.28000	      -0.22041	3.38678
 67.28147	 6.30000	      -0.22046	3.38675
 67.43151	 6.32000	      -0.22062	3.38672
 67.58165	 6.34000	      -0.22087	3.38669
 67.73189	 6.36000	      -0.22087	3.38665
 67.88216	 6.38000	      -0.22068	3.38662
 68.03236	 6.40000	      -0.22072	3.38659
 68.18256	 6.42000	      -0.22088	3.38656
 68.33269	 6.44000	      -0.22090	3.38652
 68.48293	 6.46000	      -0.22094	3.38649
 68.63311	 6.48000	      -0.22093	3.38645
 68.78333	 6.50000	      -0.22095	3.38642
 68.93351	 6.52000	      -0.22097	3.38638
 69.08362	 6.54000	      -0.22104	3.38635
 69.23365	 6.56000	      -0.22107	3.38631
 69.38369	 6.58000	      -0.22100	3.38627
 69.53369	 6.60000	      -0.22085	3.38623
 69.68369	 6.62000	      -0.22080	3.38620
 69.83355	 6.64000	      -0.22063	3.38616
 69.98338	 6.66000	      -0.22050	3.38612
 70.13318	 6.68000	      -0.22022	3.38608
 70.28295	 6.70000	      -0.21993	3.38604
 70.43276	 6.72000	      -0.21964	3.38600
 70.58262	 6.74000	      -0.21918	3.38595
 70.73251	 6.76000	      -0.21877	3.38591
 70.88233	 6.78000	      -0.21851	3.38587
 71.03220	 6.80000	      -0.21813	3.38582
 71.18216	 6.82000	      -0.21794	3.38578
 71.33220	 6.84000	      -0.21736	3.38574
 71.48222	 6.86000	      -0.21690	3.38569
 71.63222	 6.88000	      -0.21663	3.38564
 71.78235	 6.90000	      -0.21652	3.38560
 71.93236	 6.92000	      -0.21608	3.38555
 72.08247	 6.94000	      -0.21547	3.38550
 72.23265	 6.96000	      -0.21507	3.38546
 72.38285	 6.98000	      -0.21441	3.38541
 72.53296	 7.00000	      -0.21396	3.38536
 72.68304	 7.02000	      -0.21348	3.38531
 72.83307	 7.04000	      -0.21268	3.38526
 72.98318	 7.06000	      -0.21224	3.38521
 73.13322	 7.08000	      -0.21144	3.38516
 73.28325	 7.10000	      -0.21068	3.38511
 73.43329	 7.12000	      -0.20984	3.38505
 73.58327	 7.14000	      -0.20901	3.38500
 73.73331	 7.16000	      -0.20828	3.38495
 73.88311	 7.18000	      -0.20747	3.38489
 74.03293	 7.20000	      -0.20637	3.38484
 74.18285	 7.22000	      -0.20538	3.38478
 74.33284	 7.24000	      -0.20437	3.38473
 74.48269	 7.26000	      -0.20362	3.38467
 74.63253	 7.28000	      -0.20231	3.38462
 74.78233	 7.30000	      -0.20105	3.38456
 74.93215	 7.32000	      -0.20011	3.38450
 75.08209	 7.34000	      -0.19905	3.38444
 75.23202	 7.36000	      -0.19765	3.38438
 75.38196	 7.38000	      -0.19638	3.38432
 75.53202	 7.40000	      -0.19530	3.38426
 75.68207	 7.42000	      -0.19432	3.38420
 75.83224	 7.44000	      -0.19271	3.38414
 75.98251	 7.46000	      -0.19126	3.38408
 76.13271	 7.48000	      -0.18973	3.38402
 76.28287	 7.50000	      -0.18830	3.38396
 76.43302	 7.52000	      -0.18652	3.38389
 76.58322	 7.54000	      -0.18504	3.38383
 76.73340	 7.56000	      -0.18343	3.38376
 76.88364	 7.58000	      -0.18176	3.38370
 77.03378	 7.60000	      -0.17991	3.38363
 77.18389	 7.62000	      -0.17797	3.38357
 77.33393	 7.64000	      -0.17616	3.38350
 77.48396	 7.66000	      -0.17424	3.38344
 77.63398	 7.68000	      -0.17260	3.38337
 77.78398	 7.70000	      -0.17047	3.38330
 77.93376	 7.72000	      -0.16823	3.38323
 78.08371	 7.74000	      -0.16574	3.38316
 78.23358	 7.76000	      -0.16344	3.38309
 78.38340	 7.78000	      -0.16125	3.38302
 78.53347	 7.80000	      -0.15880	3.38295
 78.68362	 7.82000	      -0.15632	3.38288
 78.83378	 7.84000	      -0.15365	3.38281
 78.98382	 7.86000	      -0.15104	3.38274
 79.13395	 7.88000	      -0.14820	3.38266
 79.28413	 7.90000	      -0.14520	3.38259
 79.43436	 7.92000	      -0.14239	3.38252
 79.58444	 7.94000	      -0.13925	3.38244
 79.73447	 7.96000	      -0.13622	3.38237
 79.88444	 7.98000	      -0.13307	3.38229
 80.03458	 8.00000	      -0.12994	3.38221
 80.18464	 8.02000	      -0.12647	3.38214
 80.33465	 8.04000	      -0.12288	3.38206
 80.48467	 8.06000	      -0.11914	3.38198
 80.63445	 8.08000	      -0.11548	3.38190
 80.78420	 8.10000	      -0.11145	3.38183
 80.93402	 8.12000	      -0.10742	3.38175
 81.08389	 8.14000	      -0.10305	3.38167
 81.23362	 8.16000	-9.872488e-002	3.38159
 81.38333	 8.18000	-9.437820e-002	3.38151
 81.53313	 8.20000	-8.978647e-002	3.38143
 81.68304	 8.22000	-8.509602e-002	3.38134
 81.83302	 8.24000	-7.986521e-002	3.38126
 81.98307	 8.26000	-7.453627e-002	3.38118
 82.13305	 8.28000	-6.928864e-002	3.38109
 82.28316	 8.30000	-6.384257e-002	3.38101
 82.43320	 8.32000	-5.829704e-002	3.38093
 82.58333	 8.34000	-5.213769e-002	3.38084
 82.73345	 8.36000	-4.602746e-002	3.38075
 82.88356	 8.38000	-3.979414e-002	3.38067
 83.03371	 8.40000	-3.313908e-002	3.38058
 83.18384	 8.42000	-2.615072e-002	3.38049
 83.33400	 8.44000	-1.899010e-002	3.38041
 83.48405	 8.46000	-1.148528e-002	3.38032
 83.63411	 8.48000	-3.660794e-003	3.38023
 83.78425	 8.50000	 4.704449e-003	3.38014
 83.93425	 8.52000	 1.302132e-002	3.38005
 84.08429	 8.54000	 2.205951e-002	3.37996
 84.23431	 8.56000	 3.128215e-002	3.37987
 84.38425	 8.58000	 4.092320e-002	3.37978
 84.53424	 8.60000	 5.110485e-002	3.37969
 84.68420	 8.62000	 6.177933e-002	3.37959
 84.83431	 8.64000	 7.304332e-002	3.37950
 84.98436	 8.66000	 8.455329e-002	3.37941
 85.13429	 8.68000	 9.665458e-002	3.37931
 85.28436	 8.70000	       0.10945	3.37922
 85.43444	 8.72000	       0.12293	3.37912
 85.58451	 8.74000	       0.13720	3.37903
 85.73453	 8.76000	       0.15183	3.37893
 85.88442	 8.78000	       0.16743	3.37883
 86.03447	 8.80000	       0.18364	3.37874
 86.18440	 8.82000	       0.20004	3.37864
 86.33444	 8.84000	       0.21834	3.37854
 86.48455	 8.86000	       0.23693	3.37844
 86.63451	 8.88000	       0.25619	3.37834
 86.78444	 8.90000	       0.27697	3.37824
 86.93431	 8.92000	       0.29812	3.37814
 87.08425	 8.94000	       0.32103	3.37804
 87.23435	 8.96000	       0.34470	3.37794
 87.38436	 8.98000	       0.36922	3.37784
 87.53444	 9.00000	       0.39478	3.37774
 87.68449	 9.02000	       0.42209	3.37763
 87.83460	 9.04000	       0.45063	3.37753
 87.98475	 9.06000	       0.48023	3.37743
 88.13487	 9.08000	       0.51118	3.37732
 88.28509	 9.10000	       0.54366	3.37722
 88.43529	 9.12000	       0.57690	3.37711
 88.58549	 9.14000	       0.61187	3.37700
 88.73573	 9.16000	       0.64809	3.37690
 88.88593	 9.18000	       0.68567	3.37679
 89.03611	 9.20000	       0.72602	3.37668
 89.18622	 9.22000	       0.76662	3.37657
 89.33618	 9.24000	       0.80842	3.37647
 89.48622	 9.26000	       0.85161	3.37636
 89.63618	 9.28000	       0.89697	3.37625
 89.78615	 9.30000	       0.94306	3.37614
 89.93616	 9.32000	       0.99012	3.37603
 90.08611	 9.34000	       1.03804	3.37592
 90.23607	 9.36000	       1.08701	3.37580
 90.38600	 9.38000	       1.13678	3.37569
 90.53593	 9.40000	       1.18731	3.37558
 90.68584	 9.42000	       1.23797	3.37547
 90.83587	 9.44000	       1.28902	3.37535
 90.98585	 9.46000	       1.33969	3.37524
 91.13595	 9.48000	       1.39002	3.37512
 91.28615	 9.50000	       1.43966	3.37501
 91.43640	 9.52000	       1.48869	3.37489
 91.58645	 9.54000	       1.53630	3.37477
 91.73662	 9.56000	       1.58253	3.37466
 91.88667	 9.58000	       1.62671	3.37454
 92.03662	 9.60000	       1.66877	3.37442
 92.18655	 9.62000	       1.70826	3.37430
 92.33649	 9.64000	       1.74495	3.37419
 92.48638	 9.66000	       1.77857	3.37407
 92.63631	 9.68000	       1.80908	3.37395
 92.78611	 9.70000	       1.83547	3.37383
 92.93591	 9.72000	       1.85849	3.37371
 93.08567	 9.74000	       1.87724	3.37358
 93.23531	 9.76000	       1.89152	3.37346
 93.38495	 9.78000	       1.90187	3.37334
 93.53442	 9.80000	       1.90766	3.37322
 93.68393	 9.82000	       1.90912	3.37310
 93.83345	 9.84000	       1.90620	3.37297
 93.98313	 9.86000	       1.89893	3.37285
 94.13285	 9.88000	       1.88762	3.37272
 94.28253	 9.90000	       1.87185	3.37260
 94.43213	 9.92000	       1.85242	3.37247
 94.58176	 9.94000	       1.82912	3.37235
 94.73142	 9.96000	       1.80247	3.37222
 94.88127	 9.98000	       1.77235	3.37209
 95.03100	10.00000	       1.73959	3.37196
 95.18080	10.02000	       1.70371	3.37184
 95.33060	10.04000	       1.66569	3.37171
 95.48058	10.06000	       1.62528	3.37158
 95.63069	10.08000	       1.58375	3.37145
 95.78073	10.10000	       1.54043	3.37132
 95.93065	10.12000	       1.49590	3.37119
 96.08064	10.14000	       1.45071	3.37106
 96.23075	10.16000	       1.40484	3.37092
 96.38085	10.18000	       1.35889	3.37079
 96.53096	10.20000	       1.31280	3.37066
 96.68111	10.22000	       1.26684	3.37052
 96.83120	10.24000	       1.22143	3.37039
 96.98124	10.26000	       1.17677	3.37026
 97.13133	10.28000	       1.13270	3.37012
 97.28133	10.30000	       1.08951	3.36998
 97.43136	10.32000	       1.04738	3.36985
 97.58124	10.34000	       1.00603	3.36971
 97.73113	10.36000	       0.96621	3.36958
 97.88124	10.38000	       0.92750	3.36944
 98.03138	10.40000	       0.88966	3.36930
 98.18147	10.42000	       0.85337	3.36916
 98.33151	10.44000	       0.81837	3.36902
 98.48162	10.46000	       0.78454	3.36888
 98.63180	10.48000	       0.75198	3.36874
 98.78187	10.50000	       0.72068	3.36860
 98.93204	10.52000	       0.69056	3.36846
 99.08215	10.54000	       0.66165	3.36832
 99.23227	10.56000	       0.63395	3.36818
 99.38255	10.58000	       0.60735	3.36803
 99.53276	10.60000	       0.58219	3.36789
 99.68302	10.62000	       0.55786	3.36775
 99.83329	10.64000	       0.53461	3.36760
 99.98347	10.66000	       0.51220	3.36746
100.13360	10.68000	       0.49093	3.36731
100.28373	10.70000	       0.47072	3.36717
100.43393	10.72000	       0.45161	3.36702
100.58409	10.74000	       0.43307	3.36688
100.73416	10.76000	       0.41520	3.36673
100.88422	10.78000	       0.39826	3.36658
101.03422	10.80000	       0.38230	3.36643
101.18436	10.82000	       0.36681	3.36629
101.33447	10.84000	       0.35229	3.36614
101.48451	10.86000	       0.33806	3.36599
101.63453	10.88000	       0.32445	3.36584
101.78447	10.90000	       0.31153	3.36569
101.93444	10.92000	       0.29897	3.36554
102.08444	10.94000	       0.28760	3.36539
102.23433	10.96000	       0.27621	3.36523
102.38422	10.98000	       0.26533	3.36508
102.53400	11.00000	       0.25509	3.36493
102.68382	11.02000	       0.24542	3.36478
102.83371	11.04000	       0.23580	3.36462
102.98369	11.06000	       0.22662	3.36447
103.13358	11.08000	       0.21771	3.36431
103.28342	11.10000	       0.20949	3.36416
103.43329	11.12000	       0.20139	3.36400
103.58304	11.14000	       0.19376	3.36385
103.73289	11.16000	       0.18637	3.36369
103.88289	11.18000	       0.17911	3.36353
104.03284	11.20000	       0.17233	3.36338
104.18273	11.22000	       0.16559	3.36322
104.33265	11.24000	       0.15893	3.36306
104.48271	11.26000	       0.15310	3.36290
104.63278	11.28000	       0.14712	3.36274
104.78300	11.30000	       0.14117	3.36258
104.93316	11.32000	       0.13586	3.36242
105.08324	11.34000	       0.13062	3.36226
105.23344	11.36000	       0.12522	3.36210
105.38355	11.38000	       0.12026	3.36194
105.53376	11.40000	       0.11550	3.36177
105.68404	11.42000	       0.11114	3.36161
105.83425	11.44000	       0.10655	3.36145
105.98436	11.46000	       0.10209	3.36128
106.13451	11.48000	 9.774470e-002	3.36112
106.28475	11.50000	 9.374546e-002	3.36095
106.43498	11.52000	 8.989469e-002	3.36079
106.58502	11.54000	 8.611738e-002	3.36062
106.73511	11.56000	 8.256204e-002	3.36046
106.88504	11.58000	 7.922874e-002	3.36029
107.03500	11.60000	 7.579984e-002	3.36012
107.18516	11.62000	 7.248177e-002	3.35995
107.33520	11.64000	 6.931067e-002	3.35979
107.48525	11.66000	 6.608952e-002	3.35962
107.63527	11.68000	 6.319028e-002	3.35945
107.78535	11.70000	 6.031482e-002	3.35928
107.93540	11.72000	 5.753827e-002	3.35911
108.08540	11.74000	 5.461736e-002	3.35894
108.23529	11.76000	 5.199393e-002	3.35877
108.38522	11.78000	 4.937056e-002	3.35860
108.53516	11.80000	 4.694436e-002	3.35842
108.68498	11.82000	 4.456768e-002	3.35825
108.83462	11.84000	 4.199365e-002	3.35808
108.98442	11.86000	 3.971505e-002	3.35791
109.13418	11.88000	 3.730573e-002	3.35773
109.28380	11.90000	 3.534362e-002	3.35756
109.43355	11.92000	 3.330713e-002	3.35738
109.58333	11.94000	 3.122034e-002	3.35721
109.73315	11.96000	 2.908355e-002	3.35703
109.88300	11.98000	 2.692279e-002	3.35686
110.03280	12.00000	 2.520695e-002	3.35668
110.18276	12.02000	 2.343837e-002	3.35650
110.33278	12.04000	 2.152087e-002	3.35633
110.48276	12.06000	 1.943067e-002	3.35615
110.63284	12.08000	 1.763711e-002	3.35597
110.78298	12.10000	 1.571967e-002	3.35579
110.93322	12.12000	 1.409827e-002	3.35561
111.08344	12.14000	 1.229062e-002	3.35543
111.23360	12.16000	 1.047194e-002	3.35525
111.38387	12.18000	 8.751705e-003	3.35507
111.53400	12.20000	 7.427231e-003	3.35489
111.68413	12.22000	 5.879244e-003	3.35471
111.83431	12.24000	 4.356806e-003	3.35452
111.98438	12.26000	 2.833888e-003	3.35434
112.13451	12.28000	 1.358818e-003	3.35416
112.28447	12.30000	 1.553425e-004	3.35397
112.43440	12.32000	-1.073338e-003	3.35379
112.58449	12.34000	-2.673169e-003	3.35360
112.73458	12.36000	-4.000532e-003	3.35342
112.88476	12.38000	-5.105558e-003	3.35323
113.03484	12.40000	-6.306242e-003	3.35305
113.18475	12.42000	-7.471066e-003	3.35286
113.33478	12.44000	-8.487450e-003	3.35267
113.48478	12.46000	-9.602026e-003	3.35249
113.63480	12.48000	-1.084055e-002	3.35230
113.78475	12.50000	-1.212973e-002	3.35211
113.93458	12.52000	-1.314693e-002	3.35192
114.08447	12.54000	-1.425496e-002	3.35173
114.23436	12.56000	-1.523207e-002	3.35154
114.38433	12.58000	-1.613562e-002	3.35135
114.53427	12.60000	-1.686586e-002	3.35116
114.68422	12.62000	-1.814155e-002	3.35097
114.83427	12.64000	-1.894664e-002	3.35078
114.98424	12.66000	-1.997418e-002	3.35059
115.13418	12.68000	-2.112737e-002	3.35040
115.28420	12.70000	-2.178779e-002	3.35020
115.43405	12.72000	-2.291881e-002	3.35001
115.58391	12.74000	-2.377734e-002	3.34982
115.73387	12.76000	-2.475992e-002	3.34962
115.88391	12.78000	-2.574294e-002	3.34943
116.03396	12.80000	-2.652737e-002	3.34923
116.18404	12.82000	-2.753073e-002	3.34904
116.33409	12.84000	-2.823738e-002	3.34884
116.48416	12.86000	-2.901784e-002	3.34864
116.63433	12.88000	-2.987246e-002	3.34845
116.78431	12.90000	-3.052882e-002	3.34825
116.93429	12.92000	-3.121005e-002	3.34805
117.08438	12.94000	-3.197534e-002	3.34785
117.23442	12.96000	-3.274611e-002	3.34765
117.38440	12.98000	-3.369155e-002	3.34746
117.53462	13.00000	-3.436334e-002	3.34726
117.68493	13.02000	-3.498661e-002	3.34705
117.83509	13.04000	-3.565921e-002	3.34685
117.98516	13.06000	-3.645560e-002	3.34665
118.13529	13.08000	-3.697002e-002	3.34645
118.28533	13.10000	-3.770332e-002	3.34625
118.43553	13.12000	-3.828784e-002	3.34605
118.58551	13.14000	-3.884665e-002	3.34584
118.73549	13.16000	-3.953124e-002	3.34564
118.88547	13.18000	-4.004123e-002	3.34544
119.03542	13.20000	-4.057805e-002	3.34523
119.18542	13.22000	-4.109395e-002	3.34503
119.33549	13.24000	-4.153511e-002	3.34482
119.48549	13.26000	-4.202632e-002	3.34462
119.63529	13.28000	-4.261721e-002	3.34441
119.78511	13.30000	-4.293414e-002	3.34420
119.93493	13.32000	-4.364963e-002	3.34400
120.08480	13.34000	-4.384565e-002	3.34379
120.23460	13.36000	-4.456589e-002	3.34358
120.38442	13.38000	-4.513758e-002	3.34338
120.53425	13.40000	-4.563419e-002	3.34317
120.68429	13.42000	-4.608088e-002	3.34296
120.83420	13.44000	-4.647895e-002	3.34275
120.98422	13.46000	-4.702477e-002	3.34254
121.13407	13.48000	-4.738553e-002	3.34233
121.28396	13.50000	-4.809525e-002	3.34212
121.43396	13.52000	-4.860603e-002	3.34191
121.58400	13.54000	-4.894265e-002	3.34169
121.73391	13.56000	-4.952873e-002	3.34148
121.88398	13.58000	-5.031336e-002	3.34127
122.03400	13.60000	-5.085247e-002	3.34106
122.18409	13.62000	-5.102937e-002	3.34084
122.33409	13.64000	-5.162745e-002	3.34063
122.48415	13.66000	-5.210201e-002	3.34041
122.63416	13.68000	-5.260181e-002	3.34020
122.78407	13.70000	-5.315072e-002	3.33998
122.93396	13.72000	-5.337722e-002	3.33977
123.08395	13.74000	-5.395593e-002	3.33955
123.23405	13.76000	-5.446930e-002	3.33934
123.38407	13.78000	-5.490749e-002	3.33912
123.53400	13.80000	-5.537063e-002	3.33890
123.68398	13.82000	-5.558549e-002	3.33868
123.83404	13.84000	-5.614919e-002	3.33847
123.98405	13.86000	-5.668712e-002	3.33825
124.13409	13.88000	-5.713780e-002	3.33803
124.28413	13.90000	-5.761553e-002	3.33781
124.43425	13.92000	-5.794408e-002	3.33759
124.58427	13.94000	-5.829658e-002	3.33737
124.73424	13.96000	-5.894862e-002	3.33715
124.88431	13.98000	-5.940142e-002	3.33692
125.03447	14.00000	-5.978249e-002	3.33670
125.18444	14.02000	-6.012479e-002	3.33648
125.33444	14.04000	-6.064135e-002	3.33626
125.48455	14.06000	-6.115798e-002	3.33603
125.63456	14.08000	-6.179978e-002	3.33581
125.78464	14.10000	-6.184337e-002	3.33559
125.93469	14.12000	-6.245945e-002	3.33536
126.08469	14.14000	-6.279894e-002	3.33514
126.23460	14.16000	-6.326654e-002	3.33491
126.38455	14.18000	-6.373324e-002	3.33469
126.53453	14.20000	-6.407648e-002	3.33446
126.68453	14.22000	-6.469367e-002	3.33423
126.83447	14.24000	-6.501149e-002	3.33401
126.98444	14.26000	-6.562886e-002	3.33378
127.13429	14.28000	-6.630751e-002	3.33355
127.28429	14.30000	-6.679092e-002	3.33332
127.43425	14.32000	-6.712430e-002	3.33309
127.58424	14.34000	-6.770780e-002	3.33286
127.73433	14.36000	-6.834090e-002	3.33263
127.88436	14.38000	-6.904883e-002	3.33240
128.03435	14.40000	-6.967980e-002	3.33217
128.18436	14.42000	-7.037955e-002	3.33194
128.33446	14.44000	-7.097942e-002	3.33171
128.48451	14.46000	-7.152954e-002	3.33148
128.63445	14.48000	-7.220370e-002	3.33125
128.78440	14.50000	-7.302848e-002	3.33102
128.93449	14.52000	-7.400260e-002	3.33078
129.08449	14.54000	-7.470761e-002	3.33055
129.23449	14.56000	-7.544145e-002	3.33031
129.38440	14.58000	-7.610063e-002	3.33008
129.53431	14.60000	-7.703448e-002	3.32985
129.68424	14.62000	-7.779360e-002	3.32961
129.83407	14.64000	-7.855252e-002	3.32938
129.98391	14.66000	-7.951136e-002	3.32914
130.13384	14.68000	-8.056711e-002	3.32890
130.28382	14.70000	-8.117670e-002	3.32867
130.43375	14.72000	-8.213524e-002	3.32843
130.58367	14.74000	-8.309327e-002	3.32819
130.73367	14.76000	-8.405244e-002	3.32795
130.88375	14.78000	-8.496156e-002	3.32772
131.03378	14.80000	-8.603784e-002	3.32748
131.18382	14.82000	-8.700967e-002	3.32724
131.33387	14.84000	-8.808178e-002	3.32700
131.48389	14.86000	-8.902994e-002	3.32676
131.63398	14.88000	-9.032764e-002	3.32652
131.78404	14.90000	-9.139993e-002	3.32628
131.93411	14.92000	-9.259752e-002	3.32603
132.08415	14.94000	-9.362987e-002	3.32579
132.23416	14.96000	-9.461801e-002	3.32555
132.38413	14.98000	-9.565721e-002	3.32531
132.53425	15.00000	-9.674553e-002	3.32506
132.68442	15.02000	-9.788397e-002	3.32482
132.83444	15.04000	-9.909816e-002	3.32458
132.98435	15.06000	      -0.10019	3.32433
133.13435	15.08000	      -0.10166	3.32409
133.28447	15.10000	      -0.10270	3.32384
133.43462	15.12000	      -0.10372	3.32360
133.58460	15.14000	      -0.10498	3.32335
133.73462	15.16000	      -0.10640	3.32310
133.88473	15.18000	      -0.10722	3.32286
134.03505	15.20000	      -0.10884	3.32261
134.18531	15.22000	      -0.10967	3.32236
134.33553	15.24000	      -0.11120	3.32211
134.48565	15.26000	      -0.11247	3.32186
134.63574	15.28000	      -0.11373	3.32161
134.78576	15.30000	      -0.11489	3.32137
134.93587	15.32000	      -0.11602	3.32112
135.08602	15.34000	      -0.11734	3.32087
135.23600	15.36000	      -0.11868	3.32061
135.38582	15.38000	      -0.12019	3.32036
135.53578	15.40000	      -0.12111	3.32011
135.68576	15.42000	      -0.12235	3.31986
135.83556	15.44000	      -0.12389	3.31961
135.98531	15.46000	      -0.12493	3.31936
136.13495	15.48000	      -0.12591	3.31910
136.28462	15.50000	      -0.12700	3.31885
136.43427	15.52000	      -0.12778	3.31860
136.58409	15.54000	      -0.12940	3.31834
136.73384	15.56000	      -0.13024	3.31809
136.88367	15.58000	      -0.13149	3.31784
137.03356	15.60000	      -0.13216	3.31758
137.18347	15.62000	      -0.13348	3.31733
137.33342	15.64000	      -0.13458	3.31707
137.48344	15.66000	      -0.13560	3.31681
137.63349	15.68000	      -0.13644	3.31656
137.78362	15.70000	      -0.13749	3.31630
137.93376	15.72000	      -0.13841	3.31604
138.08393	15.74000	      -0.13904	3.31578
138.23415	15.76000	      -0.13996	3.31552
138.38440	15.78000	      -0.14091	3.31526
138.53460	15.80000	      -0.14136	3.31500
138.68474	15.82000	      -0.14193	3.31474
138.83491	15.84000	      -0.14273	3.31448
138.98498	15.86000	      -0.14333	3.31422
139.13500	15.88000	      -0.14369	3.31396
139.28504	15.90000	      -0.14420	3.31370
139.43524	15.92000	      -0.14460	3.31344
139.58531	15.94000	      -0.14489	3.31318
139.73529	15.96000	      -0.14529	3.31291
139.88535	15.98000	      -0.14550	3.31265
140.03533	16.00000	      -0.14561	3.31239
140.18533	16.02000	      -0.14557	3.31212
140.33522	16.04000	      -0.14563	3.31186
140.48511	16.06000	      -0.14589	3.31159
140.63495	16.08000	      -0.14577	3.31133
140.78482	16.10000	      -0.14601	3.31106
140.93464	16.12000	      -0.14592	3.31080
141.08455	16.14000	      -0.14578	3.31053
141.23446	16.16000	      -0.14572	3.31027
141.38431	16.18000	      -0.14561	3.31000
141.53407	16.20000	      -0.14540	3.30973
141.68400	16.22000	      -0.14521	3.30947
141.83386	16.24000	      -0.14502	3.30920
141.98362	16.26000	      -0.14474	3.30893
142.13346	16.28000	      -0.14458	3.30866
142.28324	16.30000	      -0.14422	3.30839
142.43324	16.32000	      -0.14409	3.30812
142.58326	16.34000	      -0.14391	3.30785
142.73336	16.36000	      -0.14365	3.30758
142.88340	16.38000	      -0.14342	3.30731
143.03349	16.40000	      -0.14331	3.30704
143.18358	16.42000	      -0.14278	3.30677
143.33358	16.44000	      -0.14228	3.30650
143.48371	16.46000	      -0.14216	3.30622
143.63393	16.48000	      -0.14173	3.30595
143.78413	16.50000	      -0.14155	3.30568
143.93438	16.52000	      -0.14125	3.30540
144.08475	16.54000	      -0.14101	3.30513
144.23495	16.56000	      -0.14059	3.30485
144.38518	16.58000	      -0.14037	3.30458
144.53529	16.60000	      -0.14010	3.30430
144.68536	16.62000	      -0.13960	3.30403
144.83536	16.64000	      -0.13913	3.30375
144.98549	16.66000	      -0.13868	3.30347
145.13556	16.68000	      -0.13836	3.30320
145.28545	16.70000	      -0.13801	3.30292
145.43533	16.72000	      -0.13756	3.30264
145.58507	16.74000	      -0.13701	3.30237
145.73478	16.76000	      -0.13668	3.30209
145.88447	16.78000	      -0.13646	3.30181
146.03425	16.80000	      -0.13588	3.30153
146.18405	16.82000	      -0.13544	3.30125
146.33393	16.84000	      -0.13517	3.30097
146.48389	16.86000	      -0.13480	3.30069
146.63387	16.88000	      -0.13437	3.30041
146.78391	16.90000	      -0.13400	3.30013
146.93391	16.92000	      -0.13353	3.29985
147.08380	16.94000	      -0.13347	3.29957
147.23384	16.96000	      -0.13328	3.29929
147.38404	16.98000	      -0.13309	3.29901
147.53425	17.00000	      -0.13270	3.29872
147.68449	17.02000	      -0.13249	3.29844
147.83465	17.04000	      -0.13212	3.29815
147.98485	17.06000	      -0.13178	3.29787
148.13491	17.08000	      -0.13149	3.29759
148.28507	17.10000	      -0.13116	3.29730
148.43511	17.12000	      -0.13069	3.29702
148.58502	17.14000	      -0.13047	3.29673
148.73484	17.16000	      -0.13015	3.29645
148.88465	17.18000	      -0.12965	3.29616
149.03467	17.20000	      -0.12907	3.29587
149.18458	17.22000	      -0.12889	3.29559
149.33434	17.24000	      -0.12840	3.29530
149.48422	17.26000	      -0.12818	3.29501
149.63374	17.28000	      -0.12757	3.29473
149.78327	17.30000	      -0.12733	3.29444
149.93300	17.32000	      -0.12696	3.29415