File: data/ExpDat_SK_Clear_resin_entalp300kpm_30-300.txt
#EXPORTTYPE:                 	DATA COMPARE
#FILE:                       	SK_Clear_resin_entalp300kpm_30-300.ngb-sdg
#FORMAT:                     	NETZSCH5
#FTYPE:                      	ASCII
#IDENTITY:                   	Sk_resin
#DECIMAL:                    	POINT
#SEPARATOR:                  	TAB
#MTYPE:                      	DSC
#INSTRUMENT:                 	NETZSCH DSC 214
#PROJECT:                    	?ø?†??-Ø
#DATE/TIME:                  	16.09.2019 19:53:45 (UTC+3)
#CORR. FILE:
#TEMPCAL:                    	applied
#SENSITIVITY:                	applied
#LABORATORY:                 	CISIS
#OPERATOR:                   	Nasonov
#REMARK:
#SAMPLE:                     	"R°§0 ISO 160_2
#SAMPLE MASS /mg:            	6.79
#MATERIAL:
#REFERENCE:
#REFERENCE MASS /mg:         	7.92
#TYPE OF CRUCIBLE:           	Concavus Pan Al, pierced lid
#SAMPLE CRUCIBLE MASS /mg:   	0
#REFERENCE CRUCIBLE MASS /mg:	0
#M.RANGE /ßV:                	5000
#TAU-R:                      	---
#CORR. CODE:                 	009
#EXO:                        	+1
#RANGE:                      	20ËC/300.0(K/min)/300ËC
#SEGMENT:                    	S1/1
#SEG. 1:                     	20ËC/300.0(K/min)/300ËC

##Temp./ËC	DSC/(mW/mg)
 19.98433	 3.615321e-002
 20.18433	 1.824070e-002
 20.38433	 1.025796e-002
 20.58433	 2.435324e-003
 20.78433	-6.887256e-003
 20.98433	-1.772899e-002
 21.18433	-3.021788e-002
 21.38433	-4.441906e-002
 21.58433	-5.997924e-002
 21.78433	-7.712623e-002
 21.98433	-9.541642e-002
 22.18433	      -0.11471
 22.38433	      -0.13518
 22.58433	      -0.15664
 22.78433	      -0.17891
 22.98433	      -0.20205
 23.18433	      -0.22620
 23.38433	      -0.25124
 23.58433	      -0.27695
 23.78433	      -0.30327
 23.98433	      -0.33022
 24.18433	      -0.35772
 24.38433	      -0.38576
 24.58433	      -0.41429
 24.78433	      -0.44326
 24.98433	      -0.47272
 25.18433	      -0.50266
 25.38433	      -0.53301
 25.58433	      -0.56368
 25.78433	      -0.59470
 25.98433	      -0.62610
 26.18433	      -0.65779
 26.38433	      -0.68975
 26.58433	      -0.72197
 26.78433	      -0.75444
 26.98433	      -0.78720
 27.18433	      -0.82029
 27.38433	      -0.85360
 27.58433	      -0.88703
 27.78433	      -0.92066
 27.98433	      -0.95457
 28.18433	      -0.98868
 28.38433	      -1.02297
 28.58433	      -1.05745
 28.78433	      -1.09212
 28.98433	      -1.12693
 29.18433	      -1.16185
 29.38433	      -1.19687
 29.58433	      -1.23198
 29.78433	      -1.26717
 29.98433	      -1.30247
 30.18433	      -1.33795
 30.38433	      -1.37361
 30.58433	      -1.40940
 30.78433	      -1.44527
 30.98433	      -1.48122
 31.18433	      -1.51724
 31.38433	      -1.55335
 31.58433	      -1.58958
 31.78433	      -1.62591
 31.98433	      -1.66235
 32.18433	      -1.69886
 32.38433	      -1.73540
 32.58433	      -1.77199
 32.78433	      -1.80865
 32.98433	      -1.84538
 33.18433	      -1.88217
 33.38433	      -1.91901
 33.58433	      -1.95592
 33.78433	      -1.99290
 33.98433	      -2.02994
 34.18433	      -2.06700
 34.38433	      -2.10407
 34.58433	      -2.14114
 34.78433	      -2.17823
 34.98433	      -2.21544
 35.18433	      -2.25280
 35.38433	      -2.29027
 35.58433	      -2.32782
 35.78433	      -2.36541
 35.98433	      -2.40304
 36.18433	      -2.44071
 36.38433	      -2.47840
 36.58433	      -2.51609
 36.78433	      -2.55380
 36.98433	      -2.59154
 37.18433	      -2.62932
 37.38433	      -2.66712
 37.58433	      -2.70494
 37.78433	      -2.74277
 37.98433	      -2.78062
 38.18433	      -2.81851
 38.38433	      -2.85644
 38.58433	      -2.89441
 38.78433	      -2.93241
 38.98433	      -2.97034
 39.18433	      -3.00814
 39.38433	      -3.04584
 39.58433	      -3.08352
 39.78433	      -3.12125
 39.98433	      -3.15901
 40.18433	      -3.19675
 40.38433	      -3.23448
 40.58433	      -3.27221
 40.78433	      -3.30999
 40.98433	      -3.34781
 41.18433	      -3.38570
 41.38433	      -3.42364
 41.58433	      -3.46161
 41.78433	      -3.49960
 41.98433	      -3.53757
 42.18433	      -3.57554
 42.38433	      -3.61353
 42.58433	      -3.65154
 42.78433	      -3.68957
 42.98433	      -3.72762
 43.18433	      -3.76569
 43.38433	      -3.80380
 43.58433	      -3.84196
 43.78433	      -3.88017
 43.98433	      -3.91840
 44.18433	      -3.95661
 44.38433	      -3.99479
 44.58433	      -4.03295
 44.78433	      -4.07109
 44.98433	      -4.10922
 45.18433	      -4.14735
 45.38433	      -4.18549
 45.58433	      -4.22364
 45.78433	      -4.26180
 45.98433	      -4.29995
 46.18433	      -4.33809
 46.38433	      -4.37625
 46.58433	      -4.41441
 46.78433	      -4.45259
 46.98433	      -4.49079
 47.18433	      -4.52901
 47.38433	      -4.56725
 47.58433	      -4.60546
 47.78433	      -4.64362
 47.98433	      -4.68173
 48.18433	      -4.71981
 48.38433	      -4.75788
 48.58433	      -4.79593
 48.78433	      -4.83398
 48.98433	      -4.87201
 49.18433	      -4.91004
 49.38433	      -4.94806
 49.58433	      -4.98607
 49.78433	      -5.02406
 49.98433	      -5.06200
 50.18433	      -5.09984
 50.38433	      -5.13759
 50.58433	      -5.17526
 50.78433	      -5.21288
 50.98433	      -5.25047
 51.18433	      -5.28804
 51.38433	      -5.32559
 51.58433	      -5.36311
 51.78433	      -5.40057
 51.98433	      -5.43790
 52.18433	      -5.47506
 52.38433	      -5.51194
 52.58433	      -5.54842
 52.78433	      -5.58439
 52.98433	      -5.61986
 53.18433	      -5.65489
 53.38433	      -5.68959
 53.58433	      -5.72402
 53.78433	      -5.75830
 53.98433	      -5.79252
 54.18433	      -5.82675
 54.38433	      -5.86103
 54.58433	      -5.89536
 54.78433	      -5.92975
 54.98433	      -5.96422
 55.18433	      -5.99876
 55.38433	      -6.03338
 55.58433	      -6.06807
 55.78433	      -6.10285
 55.98433	      -6.13771
 56.18433	      -6.17266
 56.38433	      -6.20770
 56.58433	      -6.24283
 56.78433	      -6.27803
 56.98433	      -6.31328
 57.18433	      -6.34858
 57.38433	      -6.38389
 57.58433	      -6.41922
 57.78433	      -6.45457
 57.98433	      -6.48993
 58.18433	      -6.52531
 58.38433	      -6.56072
 58.58433	      -6.59616
 58.78433	      -6.63165
 58.98433	      -6.66717
 59.18433	      -6.70272
 59.38433	      -6.73830
 59.58433	      -6.77390
 59.78433	      -6.80950
 59.98433	      -6.84507
 60.18433	      -6.88060
 60.38433	      -6.91610
 60.58433	      -6.95157
 60.78433	      -6.98702
 60.98433	      -7.02244
 61.18433	      -7.05783
 61.38433	      -7.09320
 61.58433	      -7.12854
 61.78433	      -7.16386
 61.98433	      -7.19916
 62.18433	      -7.23444
 62.38433	      -7.26969
 62.58433	      -7.30491
 62.78433	      -7.34009
 62.98433	      -7.37523
 63.18433	      -7.41033
 63.38433	      -7.44540
 63.58433	      -7.48045
 63.78433	      -7.51547
 63.98433	      -7.55045
 64.18433	      -7.58541
 64.38433	      -7.62034
 64.58433	      -7.65524
 64.78433	      -7.69013
 64.98433	      -7.72499
 65.18433	      -7.75982
 65.38433	      -7.79463
 65.58433	      -7.82941
 65.78433	      -7.86416
 65.98433	      -7.89885
 66.18433	      -7.93349
 66.38433	      -7.96807
 66.58433	      -8.00261
 66.78433	      -8.03711
 66.98433	      -8.07160
 67.18433	      -8.10607
 67.38433	      -8.14051
 67.58433	      -8.17488
 67.78433	      -8.20920
 67.98433	      -8.24346
 68.18433	      -8.27769
 68.38433	      -8.31192
 68.58433	      -8.34614
 68.78433	      -8.38030
 68.98433	      -8.41438
 69.18433	      -8.44835
 69.38433	      -8.48224
 69.58433	      -8.51606
 69.78433	      -8.54987
 69.98433	      -8.58366
 70.18433	      -8.61745
 70.38433	      -8.65122
 70.58433	      -8.68497
 70.78433	      -8.71871
 70.98433	      -8.75243
 71.18433	      -8.78615
 71.38433	      -8.81985
 71.58433	      -8.85354
 71.78433	      -8.88719
 71.98433	      -8.92080
 72.18433	      -8.95436
 72.38433	      -8.98788
 72.58433	      -9.02136
 72.78433	      -9.05479
 72.98433	      -9.08818
 73.18433	      -9.12150
 73.38433	      -9.15475
 73.58433	      -9.18793
 73.78433	      -9.22105
 73.98433	      -9.25415
 74.18433	      -9.28722
 74.38433	      -9.32026
 74.58433	      -9.35322
 74.78433	      -9.38609
 74.98433	      -9.41884
 75.18433	      -9.45151
 75.38433	      -9.48411
 75.58433	      -9.51665
 75.78433	      -9.54914
 75.98433	      -9.58156
 76.18433	      -9.61390
 76.38433	      -9.64615
 76.58433	      -9.67832
 76.78433	      -9.71044
 76.98433	      -9.74251
 77.18433	      -9.77456
 77.38433	      -9.80655
 77.58433	      -9.83847
 77.78433	      -9.87032
 77.98433	      -9.90210
 78.18433	      -9.93384
 78.38433	      -9.96554
 78.58433	      -9.99721
 78.78433	     -10.02882
 78.98433	     -10.06034
 79.18433	     -10.09176
 79.38433	     -10.12308
 79.58433	     -10.15432
 79.78433	     -10.18551
 79.98433	     -10.21667
 80.18433	     -10.24780
 80.38433	     -10.27889
 80.58433	     -10.30992
 80.78433	     -10.34090
 80.98433	     -10.37181
 81.18433	     -10.40265
 81.38433	     -10.43343
 81.58433	     -10.46413
 81.78433	     -10.49476
 81.98433	     -10.52531
 82.18433	     -10.55578
 82.38433	     -10.58618
 82.58433	     -10.61652
 82.78433	     -10.64681
 82.98433	     -10.67705
 83.18433	     -10.70724
 83.38433	     -10.73739
 83.58433	     -10.76747
 83.78433	     -10.79749
 83.98433	     -10.82747
 84.18433	     -10.85739
 84.38433	     -10.88727
 84.58433	     -10.91711
 84.78433	     -10.94689
 84.98433	     -10.97662
 85.18433	     -11.00629
 85.38433	     -11.03591
 85.58433	     -11.06547
 85.78433	     -11.09498
 85.98433	     -11.12443
 86.18433	     -11.15382
 86.38433	     -11.18314
 86.58433	     -11.21241
 86.78433	     -11.24161
 86.98433	     -11.27077
 87.18433	     -11.29990
 87.38433	     -11.32898
 87.58433	     -11.35801
 87.78433	     -11.38698
 87.98433	     -11.41586
 88.18433	     -11.44467
 88.38433	     -11.47339
 88.58433	     -11.50203
 88.78433	     -11.53060
 88.98433	     -11.55910
 89.18433	     -11.58755
 89.38433	     -11.61596
 89.58433	     -11.64434
 89.78433	     -11.67267
 89.98433	     -11.70094
 90.18433	     -11.72916
 90.38433	     -11.75732
 90.58433	     -11.78541
 90.78433	     -11.81344
 90.98433	     -11.84139
 91.18433	     -11.86928
 91.38433	     -11.89710
 91.58433	     -11.92486
 91.78433	     -11.95256
 91.98433	     -11.98019
 92.18433	     -12.00773
 92.38433	     -12.03518
 92.58433	     -12.06256
 92.78433	     -12.08988
 92.98433	     -12.11716
 93.18433	     -12.14440
 93.38433	     -12.17160
 93.58433	     -12.19874
 93.78433	     -12.22582
 93.98433	     -12.25283
 94.18433	     -12.27976
 94.38433	     -12.30661
 94.58433	     -12.33339
 94.78433	     -12.36009
 94.98433	     -12.38673
 95.18433	     -12.41332
 95.38433	     -12.43987
 95.58433	     -12.46635
 95.78433	     -12.49278
 95.98433	     -12.51913
 96.18433	     -12.54542
 96.38433	     -12.57163
 96.58433	     -12.59776
 96.78433	     -12.62381
 96.98433	     -12.64979
 97.18433	     -12.67570
 97.38433	     -12.70154
 97.58433	     -12.72733
 97.78433	     -12.75308
 97.98433	     -12.77881
 98.18433	     -12.80452
 98.38433	     -12.83022
 98.58433	     -12.85587
 98.78433	     -12.88146
 98.98433	     -12.90697
 99.18433	     -12.93242
 99.38433	     -12.95781
 99.58433	     -12.98317
 99.78433	     -13.00850
 99.98433	     -13.03378
100.18433	     -13.05901
100.38433	     -13.08418
100.58433	     -13.10930
100.78433	     -13.13438
100.98433	     -13.15943
101.18433	     -13.18447
101.38433	     -13.20946
101.58433	     -13.23439
101.78433	     -13.25924
101.98433	     -13.28400
102.18433	     -13.30868
102.38433	     -13.33327
102.58433	     -13.35777
102.78433	     -13.38219
102.98433	     -13.40653
103.18433	     -13.43079
103.38433	     -13.45497
103.58433	     -13.47908
103.78433	     -13.50312
103.98433	     -13.52710
104.18433	     -13.55100
104.38433	     -13.57485
104.58433	     -13.59863
104.78433	     -13.62234
104.98433	     -13.64598
105.18433	     -13.66953
105.38433	     -13.69298
105.58433	     -13.71635
105.78433	     -13.73965
105.98433	     -13.76289
106.18433	     -13.78608
106.38433	     -13.80922
106.58433	     -13.83227
106.78433	     -13.85523
106.98433	     -13.87808
107.18433	     -13.90083
107.38433	     -13.92347
107.58433	     -13.94602
107.78433	     -13.96846
107.98433	     -13.99081
108.18433	     -14.01307
108.38433	     -14.03523
108.58433	     -14.05729
108.78433	     -14.07924
108.98433	     -14.10106
109.18433	     -14.12277
109.38433	     -14.14438
109.58433	     -14.16590
109.78433	     -14.18733
109.98433	     -14.20867
110.18433	     -14.22991
110.38433	     -14.25104
110.58433	     -14.27207
110.78433	     -14.29299
110.98433	     -14.31380
111.18433	     -14.33451
111.38433	     -14.35512
111.58433	     -14.37565
111.78433	     -14.39609
111.98433	     -14.41645
112.18433	     -14.43672
112.38433	     -14.45692
112.58433	     -14.47705
112.78433	     -14.49708
112.98433	     -14.51701
113.18433	     -14.53683
113.38433	     -14.55654
113.58433	     -14.57611
113.78433	     -14.59555
113.98433	     -14.61485
114.18433	     -14.63403
114.38433	     -14.65309
114.58433	     -14.67206
114.78433	     -14.69092
114.98433	     -14.70969
115.18433	     -14.72835
115.38433	     -14.74691
115.58433	     -14.76535
115.78433	     -14.78364
115.98433	     -14.80179
116.18433	     -14.81978
116.38433	     -14.83762
116.58433	     -14.85532
116.78433	     -14.87288
116.98433	     -14.89031
117.18433	     -14.90761
117.38433	     -14.92479
117.58433	     -14.94182
117.78433	     -14.95871
117.98433	     -14.97543
118.18433	     -14.99199
118.38433	     -15.00839
118.58433	     -15.02465
118.78433	     -15.04078
118.98433	     -15.05676
119.18433	     -15.07260
119.38433	     -15.08829
119.58433	     -15.10382
119.78433	     -15.11918
119.98433	     -15.13434
120.18433	     -15.14931
120.38433	     -15.16409
120.58433	     -15.17870
120.78433	     -15.19315
120.98433	     -15.20744
121.18433	     -15.22156
121.38433	     -15.23552
121.58433	     -15.24930
121.78433	     -15.26292
121.98433	     -15.27638
122.18433	     -15.28967
122.38433	     -15.30279
122.58433	     -15.31572
122.78433	     -15.32845
122.98433	     -15.34097
123.18433	     -15.35329
123.38433	     -15.36540
123.58433	     -15.37729
123.78433	     -15.38897
123.98433	     -15.40045
124.18433	     -15.41171
124.38433	     -15.42276
124.58433	     -15.43360
124.78433	     -15.44421
124.98433	     -15.45462
125.18433	     -15.46482
125.38433	     -15.47483
125.58433	     -15.48464
125.78433	     -15.49421
125.98433	     -15.50350
126.18433	     -15.51247
126.38433	     -15.52115
126.58433	     -15.52956
126.78433	     -15.53772
126.98433	     -15.54566
127.18433	     -15.55336
127.38433	     -15.56084
127.58433	     -15.56808
127.78433	     -15.57506
127.98433	     -15.58176
128.18433	     -15.58817
128.38433	     -15.59428
128.58433	     -15.60010
128.78433	     -15.60564
128.98433	     -15.61089
129.18433	     -15.61586
129.38433	     -15.62057
129.58433	     -15.62501
129.78433	     -15.62919
129.98433	     -15.63311
130.18433	     -15.63679
130.38433	     -15.64018
130.58433	     -15.64327
130.78433	     -15.64605
130.98433	     -15.64851
131.18433	     -15.65064
131.38433	     -15.65245
131.58433	     -15.65394
131.78433	     -15.65512
131.98433	     -15.65600
132.18433	     -15.65657
132.38433	     -15.65684
132.58433	     -15.65677
132.78433	     -15.65638
132.98433	     -15.65565
133.18433	     -15.65457
133.38433	     -15.65314
133.58433	     -15.65136
133.78433	     -15.64923
133.98433	     -15.64673
134.18433	     -15.64389
134.38433	     -15.64069
134.58433	     -15.63716
134.78433	     -15.63331
134.98433	     -15.62916
135.18433	     -15.62474
135.38433	     -15.62003
135.58433	     -15.61499
135.78433	     -15.60959
135.98433	     -15.60379
136.18433	     -15.59760
136.38433	     -15.59099
136.58433	     -15.58398
136.78433	     -15.57654
136.98433	     -15.56868
137.18433	     -15.56038
137.38433	     -15.55165
137.58433	     -15.54246
137.78433	     -15.53282
137.98433	     -15.52274
138.18433	     -15.51222
138.38433	     -15.50127
138.58433	     -15.48985
138.78433	     -15.47793
138.98433	     -15.46550
139.18433	     -15.45253
139.38433	     -15.43906
139.58433	     -15.42508
139.78433	     -15.41057
139.98433	     -15.39553
140.18433	     -15.37993
140.38433	     -15.36378
140.58433	     -15.34709
140.78433	     -15.32987
140.98433	     -15.31213
141.18433	     -15.29385
141.38433	     -15.27503
141.58433	     -15.25565
141.78433	     -15.23568
141.98433	     -15.21511
142.18433	     -15.19391
142.38433	     -15.17211
142.58433	     -15.14971
142.78433	     -15.12670
142.98433	     -15.10303
143.18433	     -15.07869
143.38433	     -15.05365
143.58433	     -15.02793
143.78433	     -15.00157
143.98433	     -14.97455
144.18433	     -14.94686
144.38433	     -14.91848
144.58433	     -14.88939
144.78433	     -14.85959
144.98433	     -14.82907
145.18433	     -14.79783
145.38433	     -14.76583
145.58433	     -14.73307
145.78433	     -14.69952
145.98433	     -14.66519
146.18433	     -14.63006
146.38433	     -14.59412
146.58433	     -14.55732
146.78433	     -14.51965
146.98433	     -14.48106
147.18433	     -14.44152
147.38433	     -14.40099
147.58433	     -14.35944
147.78433	     -14.31690
147.98433	     -14.27335
148.18433	     -14.22877
148.38433	     -14.18313
148.58433	     -14.13638
148.78433	     -14.08850
148.98433	     -14.03943
149.18433	     -13.98914
149.38433	     -13.93761
149.58433	     -13.88483
149.78433	     -13.83078
149.98433	     -13.77542
150.18433	     -13.71871
150.38433	     -13.66059
150.58433	     -13.60104
150.78433	     -13.54004
150.98433	     -13.47756
151.18433	     -13.41353
151.38433	     -13.34790
151.58433	     -13.28060
151.78433	     -13.21160
151.98433	     -13.14090
152.18433	     -13.06847
152.38433	     -12.99427
152.58433	     -12.91828
152.78433	     -12.84042
152.98433	     -12.76061
153.18433	     -12.67874
153.38433	     -12.59476
153.58433	     -12.50864
153.78433	     -12.42034
153.98433	     -12.32983
154.18433	     -12.23706
154.38433	     -12.14198
154.58433	     -12.04451
154.78433	     -11.94460
154.98433	     -11.84216
155.18433	     -11.73711
155.38433	     -11.62937
155.58433	     -11.51888
155.78433	     -11.40559
155.98433	     -11.28944
156.18433	     -11.17037
156.38433	     -11.04832
156.58433	     -10.92321
156.78433	     -10.79502
156.98433	     -10.66372
157.18433	     -10.52929
157.38433	     -10.39164
157.58433	     -10.25071
157.78433	     -10.10641
157.98433	      -9.95869
158.18433	      -9.80748
158.38433	      -9.65275
158.58433	      -9.49448
158.78433	      -9.33266
158.98433	      -9.16726
159.18433	      -8.99824
159.38433	      -8.82555
159.58433	      -8.64919
159.78433	      -8.46917
159.98433	      -8.28550
160.18433	      -8.09822
160.38433	      -7.90735
160.58433	      -7.71292
160.78433	      -7.51494
160.98433	      -7.31345
161.18433	      -7.10851
161.38433	      -6.90023
161.58433	      -6.68869
161.78433	      -6.47401
161.98433	      -6.25628
162.18433	      -6.03564
162.38433	      -5.81225
162.58433	      -5.58632
162.78433	      -5.35801
162.98433	      -5.12744
163.18433	      -4.89478
163.38433	      -4.66024
163.58433	      -4.42411
163.78433	      -4.18662
163.98433	      -3.94802
164.18433	      -3.70857
164.38433	      -3.46851
164.58433	      -3.22807
164.78433	      -2.98752
164.98433	      -2.74712
165.18433	      -2.50715
165.38433	      -2.26786
165.58433	      -2.02952
165.78433	      -1.79239
165.98433	      -1.55669
166.18433	      -1.32263
166.38433	      -1.09038
166.58433	      -0.86009
166.78433	      -0.63188
166.98433	      -0.40588
167.18433	      -0.18220
167.38433	 3.904596e-002
167.58433	       0.25778
167.78433	       0.47397
167.98433	       0.68759
168.18433	       0.89865
168.38433	       1.10719
168.58433	       1.31322
168.78433	       1.51678
168.98433	       1.71794
169.18433	       1.91679
169.38433	       2.11347
169.58433	       2.30808
169.78433	       2.50067
169.98433	       2.69128
170.18433	       2.88004
170.38433	       3.06714
170.58433	       3.25272
170.78433	       3.43686
170.98433	       3.61961
171.18433	       3.80106
171.38433	       3.98132
171.58433	       4.16052
171.78433	       4.33865
171.98433	       4.51571
172.18433	       4.69172
172.38433	       4.86676
172.58433	       5.04087
172.78433	       5.21399
172.98433	       5.38601
173.18433	       5.55683
173.38433	       5.72641
173.58433	       5.89470
173.78433	       6.06161
173.98433	       6.22703
174.18433	       6.39084
174.38433	       6.55289
174.58433	       6.71304
174.78433	       6.87109
174.98433	       7.02682
175.18433	       7.18003
175.38433	       7.33050
175.58433	       7.47805
175.78433	       7.62254
175.98433	       7.76391
176.18433	       7.90202
176.38433	       8.03658
176.58433	       8.16736
176.78433	       8.29416
176.98433	       8.41685
177.18433	       8.53528
177.38433	       8.64926
177.58433	       8.75862
177.78433	       8.86324
177.98433	       8.96302
178.18433	       9.05786
178.38433	       9.14763
178.58433	       9.23219
178.78433	       9.31146
178.98433	       9.38537
179.18433	       9.45384
179.38433	       9.51682
179.58433	       9.57426
179.78433	       9.62613
179.98433	       9.67245
180.18433	       9.71322
180.38433	       9.74847
180.58433	       9.77824
180.78433	       9.80253
180.98433	       9.82138
181.18433	       9.83486
181.38433	       9.84303
181.58433	       9.84599
181.78433	       9.84385
181.98433	       9.83670
182.18433	       9.82466
182.38433	       9.80781
182.58433	       9.78626
182.78433	       9.76010
182.98433	       9.72943
183.18433	       9.69439
183.38433	       9.65513
183.58433	       9.61178
183.78433	       9.56449
183.98433	       9.51339
184.18433	       9.45863
184.38433	       9.40035
184.58433	       9.33860
184.78433	       9.27348
184.98433	       9.20509
185.18433	       9.13361
185.38433	       9.05918
185.58433	       8.98198
185.78433	       8.90214
185.98433	       8.81980
186.18433	       8.73506
186.38433	       8.64803
186.58433	       8.55878
186.78433	       8.46744
186.98433	       8.37417
187.18433	       8.27916
187.38433	       8.18245
187.58433	       8.08411
187.78433	       7.98416
187.98433	       7.88266
188.18433	       7.77966
188.38433	       7.67529
188.58433	       7.56971
188.78433	       7.46305
188.98433	       7.35544
189.18433	       7.24695
189.38433	       7.13761
189.58433	       7.02747
189.78433	       6.91664
189.98433	       6.80521
190.18433	       6.69322
190.38433	       6.58069
190.58433	       6.46768
190.78433	       6.35430
190.98433	       6.24060
191.18433	       6.12662
191.38433	       6.01236
191.58433	       5.89791
191.78433	       5.78331
191.98433	       5.66861
192.18433	       5.55382
192.38433	       5.43897
192.58433	       5.32412
192.78433	       5.20933
192.98433	       5.09465
193.18433	       4.98014
193.38433	       4.86583
193.58433	       4.75175
193.78433	       4.63794
193.98433	       4.52442
194.18433	       4.41125
194.38433	       4.29844
194.58433	       4.18603
194.78433	       4.07402
194.98433	       3.96239
195.18433	       3.85119
195.38433	       3.74052
195.58433	       3.63044
195.78433	       3.52092
195.98433	       3.41195
196.18433	       3.30352
196.38433	       3.19562
196.58433	       3.08833
196.78433	       2.98174
196.98433	       2.87587
197.18433	       2.77072
197.38433	       2.66627
197.58433	       2.56252
197.78433	       2.45947
197.98433	       2.35714
198.18433	       2.25554
198.38433	       2.15467
198.58433	       2.05451
198.78433	       1.95505
198.98433	       1.85626
199.18433	       1.75811
199.38433	       1.66059
199.58433	       1.56367
199.78433	       1.46734
199.98433	       1.37160
200.18433	       1.27647
200.38433	       1.18196
200.58433	       1.08808
200.78433	       0.99481
200.98433	       0.90212
201.18433	       0.80996
201.38433	       0.71833
201.58433	       0.62729
201.78433	       0.53689
201.98433	       0.44718
202.18433	       0.35814
202.38433	       0.26976
202.58433	       0.18199
202.78433	 9.481697e-002
202.98433	 8.252494e-003
203.18433	-7.768654e-002
203.38433	      -0.16299
203.58433	      -0.24765
203.78433	      -0.33164
203.98433	      -0.41492
204.18433	      -0.49750
204.38433	      -0.57936
204.58433	      -0.66051
204.78433	      -0.74094
204.98433	      -0.82066
205.18433	      -0.89965
205.38433	      -0.97793
205.58433	      -1.05552
205.78433	      -1.13249
205.98433	      -1.20880
206.18433	      -1.28438
206.38433	      -1.35921
206.58433	      -1.43335
206.78433	      -1.50687
206.98433	      -1.57973
207.18433	      -1.65188
207.38433	      -1.72335
207.58433	      -1.79419
207.78433	      -1.86439
207.98433	      -1.93392
208.18433	      -2.00277
208.38433	      -2.07096
208.58433	      -2.13852
208.78433	      -2.20546
208.98433	      -2.27176
209.18433	      -2.33742
209.38433	      -2.40242
209.58433	      -2.46678
209.78433	      -2.53051
209.98433	      -2.59363
210.18433	      -2.65616
210.38433	      -2.71810
210.58433	      -2.77945
210.78433	      -2.84017
210.98433	      -2.90027
211.18433	      -2.95976
211.38433	      -3.01866
211.58433	      -3.07702
211.78433	      -3.13487
211.98433	      -3.19221
212.18433	      -3.24905
212.38433	      -3.30535
212.58433	      -3.36105
212.78433	      -3.41618
212.98433	      -3.47078
213.18433	      -3.52484
213.38433	      -3.57833
213.58433	      -3.63125
213.78433	      -3.68361
213.98433	      -3.73542
214.18433	      -3.78668
214.38433	      -3.83739
214.58433	      -3.88756
214.78433	      -3.93721
214.98433	      -3.98634
215.18433	      -4.03495
215.38433	      -4.08305
215.58433	      -4.13063
215.78433	      -4.17772
215.98433	      -4.22430
216.18433	      -4.27038
216.38433	      -4.31596
216.58433	      -4.36104
216.78433	      -4.40564
216.98433	      -4.44974
217.18433	      -4.49336
217.38433	      -4.53652
217.58433	      -4.57925
217.78433	      -4.62156
217.98433	      -4.66347
218.18433	      -4.70498
218.38433	      -4.74606
218.58433	      -4.78671
218.78433	      -4.82695
218.98433	      -4.86677
219.18433	      -4.90619
219.38433	      -4.94522
219.58433	      -4.98386
219.78433	      -5.02215
219.98433	      -5.06009
220.18433	      -5.09769
220.38433	      -5.13495
220.58433	      -5.17185
220.78433	      -5.20836
220.98433	      -5.24453
221.18433	      -5.28041
221.38433	      -5.31599
221.58433	      -5.35123
221.78433	      -5.38611
221.98433	      -5.42065
222.18433	      -5.45483
222.38433	      -5.48867
222.58433	      -5.52218
222.78433	      -5.55535
222.98433	      -5.58821
223.18433	      -5.62075
223.38433	      -5.65298
223.58433	      -5.68489
223.78433	      -5.71653
223.98433	      -5.74790
224.18433	      -5.77902
224.38433	      -5.80988
224.58433	      -5.84051
224.78433	      -5.87095
224.98433	      -5.90123
225.18433	      -5.93130
225.38433	      -5.96117
225.58433	      -5.99083
225.78433	      -6.02032
225.98433	      -6.04966
226.18433	      -6.07890
226.38433	      -6.10803
226.58433	      -6.13700
226.78433	      -6.16575
226.98433	      -6.19430
227.18433	      -6.22264
227.38433	      -6.25080
227.58433	      -6.27880
227.78433	      -6.30667
227.98433	      -6.33439
228.18433	      -6.36199
228.38433	      -6.38948
228.58433	      -6.41689
228.78433	      -6.44420
228.98433	      -6.47137
229.18433	      -6.49839
229.38433	      -6.52529
229.58433	      -6.55210
229.78433	      -6.57880
229.98433	      -6.60542
230.18433	      -6.63195
230.38433	      -6.65842
230.58433	      -6.68483
230.78433	      -6.71117
230.98433	      -6.73744
231.18433	      -6.76369
231.38433	      -6.78995
231.58433	      -6.81622
231.78433	      -6.84245
231.98433	      -6.86863
232.18433	      -6.89478
232.38433	      -6.92095
232.58433	      -6.94716
232.78433	      -6.97344
232.98433	      -6.99983
233.18433	      -7.02634
233.38433	      -7.05294
233.58433	      -7.07960
233.78433	      -7.10627
233.98433	      -7.13293
234.18433	      -7.15960
234.38433	      -7.18630
234.58433	      -7.21305
234.78433	      -7.23987
234.98433	      -7.26672
235.18433	      -7.29356
235.38433	      -7.32042
235.58433	      -7.34733
235.78433	      -7.37428
235.98433	      -7.40127
236.18433	      -7.42826
236.38433	      -7.45529
236.58433	      -7.48236
236.78433	      -7.50946
236.98433	      -7.53657
237.18433	      -7.56370
237.38433	      -7.59086
237.58433	      -7.61807
237.78433	      -7.64531
237.98433	      -7.67257
238.18433	      -7.69985
238.38433	      -7.72719
238.58433	      -7.75458
238.78433	      -7.78202
238.98433	      -7.80950
239.18433	      -7.83701
239.38433	      -7.86458
239.58433	      -7.89219
239.78433	      -7.91984
239.98433	      -7.94754
240.18433	      -7.97531
240.38433	      -8.00314
240.58433	      -8.03101
240.78433	      -8.05889
240.98433	      -8.08676
241.18433	      -8.11466
241.38433	      -8.14261
241.58433	      -8.17056
241.78433	      -8.19851
241.98433	      -8.22645
242.18433	      -8.25441
242.38433	      -8.28239
242.58433	      -8.31040
242.78433	      -8.33840
242.98433	      -8.36637
243.18433	      -8.39428
243.38433	      -8.42213
243.58433	      -8.44998
243.78433	      -8.47785
243.98433	      -8.50570
244.18433	      -8.53347
244.38433	      -8.56117
244.58433	      -8.58884
244.78433	      -8.61648
244.98433	      -8.64410
245.18433	      -8.67169
245.38433	      -8.69923
245.58433	      -8.72671
245.78433	      -8.75414
245.98433	      -8.78153
246.18433	      -8.80889
246.38433	      -8.83621
246.58433	      -8.86347
246.78433	      -8.89069
246.98433	      -8.91787
247.18433	      -8.94500
247.38433	      -8.97207
247.58433	      -8.99905
247.78433	      -9.02595
247.98433	      -9.05279
248.18433	      -9.07958
248.38433	      -9.10630
248.58433	      -9.13295
248.78433	      -9.15947
248.98433	      -9.18581
249.18433	      -9.21197
249.38433	      -9.23798
249.58433	      -9.26383
249.78433	      -9.28954
249.98433	      -9.31509
250.18433	      -9.34048
250.38433	      -9.36573
250.58433	      -9.39084
250.78433	      -9.41584
250.98433	      -9.44073
251.18433	      -9.46554
251.38433	      -9.49025
251.58433	      -9.51486
251.78433	      -9.53934
251.98433	      -9.56368
252.18433	      -9.58788
252.38433	      -9.61197
252.58433	      -9.63594
252.78433	      -9.65978
252.98433	      -9.68347
253.18433	      -9.70701
253.38433	      -9.73038
253.58433	      -9.75357
253.78433	      -9.77654
253.98433	      -9.79930
254.18433	      -9.82182
254.38433	      -9.84411
254.58433	      -9.86622
254.78433	      -9.88818
254.98433	      -9.91001
255.18433	      -9.93166
255.38433	      -9.95313
255.58433	      -9.97443
255.78433	      -9.99557
255.98433	     -10.01660
256.18433	     -10.03754
256.38433	     -10.05839
256.58433	     -10.07916
256.78433	     -10.09983
256.98433	     -10.12044
257.18433	     -10.14104
257.38433	     -10.16163
257.58433	     -10.18211
257.78433	     -10.20239
257.98433	     -10.22247
258.18433	     -10.24240
258.38433	     -10.26221
258.58433	     -10.28192
258.78433	     -10.30155
258.98433	     -10.32109
259.18433	     -10.34049
259.38433	     -10.35977
259.58433	     -10.37894
259.78433	     -10.39804
259.98433	     -10.41703
260.18433	     -10.43585
260.38433	     -10.45451
260.58433	     -10.47307
260.78433	     -10.49156
260.98433	     -10.50996
261.18433	     -10.52825
261.38433	     -10.54642
261.58433	     -10.56450
261.78433	     -10.58251
261.98433	     -10.60044
262.18433	     -10.61833
262.38433	     -10.63614
262.58433	     -10.65387
262.78433	     -10.67152
262.98433	     -10.68908
263.18433	     -10.70655
263.38433	     -10.72393
263.58433	     -10.74119
263.78433	     -10.75833
263.98433	     -10.77535
264.18433	     -10.79226
264.38433	     -10.80908
264.58433	     -10.82580
264.78433	     -10.84243
264.98433	     -10.85896
265.18433	     -10.87538
265.38433	     -10.89172
265.58433	     -10.90801
265.78433	     -10.92425
265.98433	     -10.94043
266.18433	     -10.95650
266.38433	     -10.97249
266.58433	     -10.98839
266.78433	     -11.00422
266.98433	     -11.02003
267.18433	     -11.03582
267.38433	     -11.05158
267.58433	     -11.06722
267.78433	     -11.08272
267.98433	     -11.09810
268.18433	     -11.11340
268.38433	     -11.12863
268.58433	     -11.14379
268.78433	     -11.15888
268.98433	     -11.17384
269.18433	     -11.18862
269.38433	     -11.20324
269.58433	     -11.21775
269.78433	     -11.23220
269.98433	     -11.24661
270.18433	     -11.26101
270.38433	     -11.27537
270.58433	     -11.28964
270.78433	     -11.30378
270.98433	     -11.31785
271.18433	     -11.33188
271.38433	     -11.34586
271.58433	     -11.35980
271.78433	     -11.37368
271.98433	     -11.38755
272.18433	     -11.40141
272.38433	     -11.41524
272.58433	     -11.42900
272.78433	     -11.44264
272.98433	     -11.45615
273.18433	     -11.46953
273.38433	     -11.48279
273.58433	     -11.49597
273.78433	     -11.50909
273.98433	     -11.52208
274.18433	     -11.53491
274.38433	     -11.54760
274.58433	     -11.56024
274.78433	     -11.57286
274.98433	     -11.58541
275.18433	     -11.59787
275.38433	     -11.61024
275.58433	     -11.62253
275.78433	     -11.63477
275.98433	     -11.64697
276.18433	     -11.65916
276.38433	     -11.67133
276.58433	     -11.68345
276.78433	     -11.69554
276.98433	     -11.70761
277.18433	     -11.71969
277.38433	     -11.73178
277.58433	     -11.74386
277.78433	     -11.75589
277.98433	     -11.76785
278.18433	     -11.77972
278.38433	     -11.79151
278.58433	     -11.80325
278.78433	     -11.81494
278.98433	     -11.82648
279.18433	     -11.83778
279.38433	     -11.84887
279.58433	     -11.85987
279.78433	     -11.87086
279.98433	     -11.88185
280.18433	     -11.89286
280.38433	     -11.90387
280.58433	     -11.91485
280.78433	     -11.92578
280.98433	     -11.93670
281.18433	     -11.94763
281.38433	     -11.95857
281.58433	     -11.96946
281.78433	     -11.98029
281.98433	     -11.99106
282.18433	     -12.00179
282.38433	     -12.01249
282.58433	     -12.02315
282.78433	     -12.03376
282.98433	     -12.04433
283.18433	     -12.05487
283.38433	     -12.06539
283.58433	     -12.07589
283.78433	     -12.08634
283.98433	     -12.09676
284.18433	     -12.10713
284.38433	     -12.11746
284.58433	     -12.12772
284.78433	     -12.13791
284.98433	     -12.14804
285.18433	     -12.15814
285.38433	     -12.16822
285.58433	     -12.17829
285.78433	     -12.18834
285.98433	     -12.19836
286.18433	     -12.20829
286.38433	     -12.21811
286.58433	     -12.22785
286.78433	     -12.23754
286.98433	     -12.24720
287.18433	     -12.25687
287.38433	     -12.26653
287.58433	     -12.27618
287.78433	     -12.28576
287.98433	     -12.29528
288.18433	     -12.30473
288.38433	     -12.31412
288.58433	     -12.32342
288.78433	     -12.33263
288.98433	     -12.34174
289.18433	     -12.35078
289.38433	     -12.35976
289.58433	     -12.36872
289.78433	     -12.37766
289.98433	     -12.38660
290.18433	     -12.39549
290.38433	     -12.40434
290.58433	     -12.41313
290.78433	     -12.42186
290.98433	     -12.43055
291.18433	     -12.43919
291.38433	     -12.44781
291.58433	     -12.45639
291.78433	     -12.46491
291.98433	     -12.47338
292.18433	     -12.48177
292.38433	     -12.49008
292.58433	     -12.49833
292.78433	     -12.50655
292.98433	     -12.51475
293.18433	     -12.52290
293.38433	     -12.53097
293.58433	     -12.53898
293.78433	     -12.54694
293.98433	     -12.55487
294.18433	     -12.56276
294.38433	     -12.57060
294.58433	     -12.57838
294.78433	     -12.58610
294.98433	     -12.59376
295.18433	     -12.60139
295.38433	     -12.60902
295.58433	     -12.61665
295.78433	     -12.62428
295.98433	     -12.63190
296.18433	     -12.63951
296.38433	     -12.64711
296.58433	     -12.65468
296.78433	     -12.66220
296.98433	     -12.66963
297.18433	     -12.67701
297.38433	     -12.68436
297.58433	     -12.69169
297.78433	     -12.69901
297.98433	     -12.70632
298.18433	     -12.71360
298.38433	     -12.72085
298.58433	     -12.72806
298.78433	     -12.73523
298.98433	     -12.74237
299.18433	     -12.74948
299.38433	     -12.75656
299.58433	     -12.76361
299.78433	     -12.77064
299.98433	     -12.77764
300.18433	     -12.78463
300.28433	     -12.78812