File: data/ExpDat_SK_Mix_resin_entalp10kpm_20-150.txt
#EXPORTTYPE:                 	DATA SINGLE
#FILE:                       	SK_Mix_resin_entalp10kpm_20-150.ngb-sdg
#FORMAT:                     	NETZSCH5
#FTYPE:                      	ASCII
#IDENTITY:                   	1
#DECIMAL:                    	POINT
#SEPARATOR:                  	TAB
#MTYPE:                      	DSC
#INSTRUMENT:                 	NETZSCH DSC 214
#PROJECT:                    	?ø?†??-Ø
#DATE/TIME:                  	12.09.2019 20:12:26 (UTC+3)
#CORR. FILE:
#TEMPCAL:                    	applied
#SENSITIVITY:                	applied
#LABORATORY:                 	CISIS
#OPERATOR:                   	Nasonov
#REMARK:
#SAMPLE:                     	20190907_1083-G290S -0-
#SAMPLE MASS /mg:            	6.8
#MATERIAL:
#REFERENCE:
#REFERENCE MASS /mg:         	0
#TYPE OF CRUCIBLE:           	Concavus Pan Al, pierced lid
#SAMPLE CRUCIBLE MASS /mg:   	0
#REFERENCE CRUCIBLE MASS /mg:	0
#M.RANGE /ßV:                	5000
#TAU-R:                      	---
#CORR. CODE:                 	009
#EXO:                        	+1
#RANGE:                      	20ËC/10.0(K/min)/250ËC
#SEGMENT:                    	S1/1
#SEG. 1:                     	20ËC/10.0(K/min)/250ËC

##Temp./ËC	Time/min	DSC/(mW/mg)	Sensit./(uV/mW)
 20.04200	 0.00000	 3.906300e-002	3.36736
 20.04262	 0.02000	 3.962950e-002	3.36736
 20.07088	 0.04000	 3.883601e-002	3.36739
 20.15692	 0.06000	 2.713596e-002	3.36748
 20.29745	 0.08000	-9.256246e-004	3.36762
 20.48348	 0.10000	-4.248241e-002	3.36782
 20.64413	 0.12000	-9.145035e-002	3.36798
 20.83457	 0.14000	      -0.14396	3.36818
 21.05341	 0.16000	      -0.19744	3.36840
 21.29626	 0.18000	      -0.24862	3.36864
 21.55800	 0.20000	      -0.29535	3.36891
 21.83343	 0.22000	      -0.33727	3.36918
 22.11797	 0.24000	      -0.37330	3.36946
 22.40713	 0.26000	      -0.40216	3.36975
 22.69703	 0.28000	      -0.42458	3.37003
 22.98433	 0.30000	      -0.44005	3.37031
 23.26602	 0.32000	      -0.44916	3.37058
 23.54028	 0.34000	      -0.45232	3.37084
 23.80531	 0.36000	      -0.45043	3.37109
 24.06000	 0.38000	      -0.44372	3.37132
 24.30387	 0.40000	      -0.43386	3.37155
 24.53687	 0.42000	      -0.42145	3.37177
 24.75931	 0.44000	      -0.40695	3.37197
 24.97195	 0.46000	      -0.39153	3.37216
 25.17564	 0.48000	      -0.37631	3.37235
 25.37130	 0.50000	      -0.36065	3.37252
 25.56020	 0.52000	      -0.34595	3.37269
 25.74354	 0.54000	      -0.33266	3.37285
 25.92261	 0.56000	      -0.32043	3.37301
 26.09869	 0.58000	      -0.31034	3.37317
 26.27277	 0.60000	      -0.30150	3.37332
 26.44577	 0.62000	      -0.29459	3.37347
 26.61880	 0.64000	      -0.28955	3.37362
 26.79251	 0.66000	      -0.28646	3.37377
 26.96748	 0.68000	      -0.28471	3.37392
 27.14439	 0.70000	      -0.28366	3.37407
 27.32346	 0.72000	      -0.28395	3.37422
 27.50469	 0.74000	      -0.28616	3.37437
 27.68834	 0.76000	      -0.28847	3.37453
 27.87438	 0.78000	      -0.29154	3.37468
 28.06284	 0.80000	      -0.29508	3.37484
 28.25374	 0.82000	      -0.29890	3.37499
 28.44677	 0.84000	      -0.30278	3.37515
 28.64162	 0.86000	      -0.30672	3.37531
 28.83813	 0.88000	      -0.31077	3.37547
 29.03603	 0.90000	      -0.31446	3.37562
 29.23503	 0.92000	      -0.31729	3.37578
 29.43490	 0.94000	      -0.32035	3.37594
 29.63551	 0.96000	      -0.32271	3.37610
 29.83675	 0.98000	      -0.32454	3.37625
 30.03821	 1.00000	      -0.32638	3.37641
 30.23967	 1.02000	      -0.32789	3.37656
 30.44098	 1.04000	      -0.32879	3.37672
 30.64218	 1.06000	      -0.32970	3.37687
 30.84323	 1.08000	      -0.33041	3.37702
 31.04390	 1.10000	      -0.33065	3.37717
 31.24431	 1.12000	      -0.33062	3.37732
 31.44470	 1.14000	      -0.33063	3.37746
 31.64482	 1.16000	      -0.33070	3.37761
 31.84428	 1.18000	      -0.33080	3.37775
 32.04354	 1.20000	      -0.33041	3.37790
 32.24267	 1.22000	      -0.33031	3.37804
 32.44170	 1.24000	      -0.33019	3.37818
 32.64048	 1.26000	      -0.33003	3.37832
 32.83916	 1.28000	      -0.32987	3.37846
 33.03766	 1.30000	      -0.32986	3.37860
 33.23605	 1.32000	      -0.33002	3.37873
 33.43428	 1.34000	      -0.32975	3.37887
 33.63252	 1.36000	      -0.32984	3.37900
 33.83095	 1.38000	      -0.33017	3.37913
 34.02957	 1.40000	      -0.33008	3.37926
 34.22839	 1.42000	      -0.33030	3.37940
 34.42728	 1.44000	      -0.33062	3.37953
 34.62618	 1.46000	      -0.33104	3.37965
 34.82531	 1.48000	      -0.33142	3.37978
 35.02457	 1.50000	      -0.33199	3.37991
 35.22411	 1.52000	      -0.33253	3.38004
 35.42387	 1.54000	      -0.33300	3.38016
 35.62375	 1.56000	      -0.33314	3.38028
 35.82370	 1.58000	      -0.33354	3.38041
 36.02370	 1.60000	      -0.33412	3.38053
 36.22357	 1.62000	      -0.33469	3.38065
 36.42344	 1.64000	      -0.33529	3.38077
 36.62357	 1.66000	      -0.33588	3.38089
 36.82351	 1.68000	      -0.33612	3.38101
 37.02361	 1.70000	      -0.33655	3.38112
 37.22359	 1.72000	      -0.33717	3.38124
 37.42354	 1.74000	      -0.33742	3.38136
 37.62343	 1.76000	      -0.33768	3.38147
 37.82326	 1.78000	      -0.33820	3.38158
 38.02303	 1.80000	      -0.33859	3.38169
 38.22282	 1.82000	      -0.33917	3.38180
 38.42259	 1.84000	      -0.33954	3.38191
 38.62241	 1.86000	      -0.34025	3.38202
 38.82243	 1.88000	      -0.34063	3.38213
 39.02246	 1.90000	      -0.34108	3.38223
 39.22252	 1.92000	      -0.34135	3.38234
 39.42254	 1.94000	      -0.34185	3.38244
 39.62264	 1.96000	      -0.34208	3.38255
 39.82277	 1.98000	      -0.34267	3.38265
 40.02302	 2.00000	      -0.34317	3.38275
 40.22321	 2.02000	      -0.34343	3.38285
 40.42338	 2.04000	      -0.34358	3.38295
 40.62359	 2.06000	      -0.34374	3.38304
 40.82366	 2.08000	      -0.34413	3.38314
 41.02364	 2.10000	      -0.34430	3.38324
 41.22357	 2.12000	      -0.34472	3.38333
 41.42351	 2.14000	      -0.34518	3.38342
 41.62348	 2.16000	      -0.34560	3.38352
 41.82348	 2.18000	      -0.34593	3.38361
 42.02354	 2.20000	      -0.34625	3.38370
 42.22338	 2.22000	      -0.34679	3.38379
 42.42339	 2.24000	      -0.34722	3.38388
 42.62346	 2.26000	      -0.34773	3.38396
 42.82361	 2.28000	      -0.34810	3.38405
 43.02370	 2.30000	      -0.34864	3.38413
 43.22392	 2.32000	      -0.34912	3.38422
 43.42423	 2.34000	      -0.34953	3.38430
 43.62443	 2.36000	      -0.35024	3.38438
 43.82461	 2.38000	      -0.35075	3.38446
 44.02466	 2.40000	      -0.35127	3.38454
 44.22477	 2.42000	      -0.35161	3.38462
 44.42493	 2.44000	      -0.35191	3.38470
 44.62507	 2.46000	      -0.35197	3.38477
 44.82536	 2.48000	      -0.35261	3.38485
 45.02566	 2.50000	      -0.35304	3.38492
 45.22577	 2.52000	      -0.35322	3.38500
 45.42575	 2.54000	      -0.35341	3.38507
 45.62566	 2.56000	      -0.35392	3.38514
 45.82561	 2.58000	      -0.35444	3.38521
 46.02551	 2.60000	      -0.35462	3.38528
 46.22551	 2.62000	      -0.35485	3.38535
 46.42551	 2.64000	      -0.35515	3.38542
 46.62541	 2.66000	      -0.35575	3.38548
 46.82503	 2.68000	      -0.35595	3.38555
 47.02464	 2.70000	      -0.35630	3.38561
 47.22439	 2.72000	      -0.35678	3.38567
 47.42426	 2.74000	      -0.35733	3.38573
 47.62416	 2.76000	      -0.35792	3.38580
 47.82402	 2.78000	      -0.35818	3.38585
 48.02385	 2.80000	      -0.35849	3.38591
 48.22380	 2.82000	      -0.35884	3.38597
 48.42369	 2.84000	      -0.35929	3.38603
 48.62364	 2.86000	      -0.35955	3.38608
 48.82364	 2.88000	      -0.35964	3.38614
 49.02380	 2.90000	      -0.36072	3.38619
 49.22397	 2.92000	      -0.36078	3.38624
 49.42398	 2.94000	      -0.36142	3.38629
 49.62400	 2.96000	      -0.36217	3.38634
 49.82423	 2.98000	      -0.36269	3.38639
 50.02461	 3.00000	      -0.36313	3.38644
 50.22479	 3.02000	      -0.36388	3.38649
 50.42508	 3.04000	      -0.36417	3.38654
 50.62523	 3.06000	      -0.36445	3.38658
 50.82533	 3.08000	      -0.36474	3.38663
 51.02554	 3.10000	      -0.36517	3.38667
 51.22566	 3.12000	      -0.36541	3.38671
 51.42582	 3.14000	      -0.36595	3.38675
 51.62611	 3.16000	      -0.36656	3.38679
 51.82618	 3.18000	      -0.36707	3.38683
 52.02613	 3.20000	      -0.36721	3.38687
 52.22623	 3.22000	      -0.36742	3.38690
 52.42628	 3.24000	      -0.36786	3.38694
 52.62638	 3.26000	      -0.36844	3.38697
 52.82643	 3.28000	      -0.36892	3.38701
 53.02630	 3.30000	      -0.36902	3.38704
 53.22625	 3.32000	      -0.36964	3.38707
 53.42628	 3.34000	      -0.37009	3.38710
 53.62626	 3.36000	      -0.37018	3.38713
 53.82623	 3.38000	      -0.37056	3.38716
 54.02629	 3.40000	      -0.37105	3.38719
 54.22634	 3.42000	      -0.37158	3.38722
 54.42639	 3.44000	      -0.37175	3.38724
 54.62644	 3.46000	      -0.37235	3.38727
 54.82662	 3.48000	      -0.37285	3.38729
 55.02684	 3.50000	      -0.37317	3.38731
 55.22695	 3.52000	      -0.37337	3.38733
 55.42703	 3.54000	      -0.37376	3.38735
 55.62723	 3.56000	      -0.37379	3.38737
 55.82739	 3.58000	      -0.37431	3.38739
 56.02744	 3.60000	      -0.37462	3.38741
 56.22743	 3.62000	      -0.37522	3.38742
 56.42738	 3.64000	      -0.37561	3.38744
 56.62743	 3.66000	      -0.37591	3.38745
 56.82748	 3.68000	      -0.37628	3.38747
 57.02748	 3.70000	      -0.37647	3.38748
 57.22744	 3.72000	      -0.37701	3.38749
 57.42736	 3.74000	      -0.37748	3.38750
 57.62715	 3.76000	      -0.37805	3.38751
 57.82697	 3.78000	      -0.37829	3.38752
 58.02684	 3.80000	      -0.37840	3.38752
 58.22677	 3.82000	      -0.37866	3.38753
 58.42674	 3.84000	      -0.37865	3.38754
 58.62659	 3.86000	      -0.37938	3.38754
 58.82636	 3.88000	      -0.37974	3.38754
 59.02618	 3.90000	      -0.38017	3.38754
 59.22618	 3.92000	      -0.38063	3.38755
 59.42628	 3.94000	      -0.38076	3.38755
 59.62641	 3.96000	      -0.38125	3.38754
 59.82633	 3.98000	      -0.38160	3.38754
 60.02651	 4.00000	      -0.38216	3.38754
 60.22667	 4.02000	      -0.38264	3.38754
 60.42685	 4.04000	      -0.38296	3.38753
 60.62690	 4.06000	      -0.38314	3.38752
 60.82700	 4.08000	      -0.38323	3.38752
 61.02707	 4.10000	      -0.38385	3.38751
 61.22720	 4.12000	      -0.38417	3.38750
 61.42720	 4.14000	      -0.38455	3.38749
 61.62721	 4.16000	      -0.38494	3.38748
 61.82733	 4.18000	      -0.38527	3.38747
 62.02739	 4.20000	      -0.38572	3.38745
 62.22736	 4.22000	      -0.38607	3.38744
 62.42733	 4.24000	      -0.38638	3.38742
 62.62733	 4.26000	      -0.38647	3.38741
 62.82752	 4.28000	      -0.38692	3.38739
 63.02775	 4.30000	      -0.38721	3.38737
 63.22779	 4.32000	      -0.38744	3.38735
 63.42780	 4.34000	      -0.38804	3.38733
 63.62784	 4.36000	      -0.38834	3.38731
 63.82800	 4.38000	      -0.38858	3.38729
 64.02805	 4.40000	      -0.38858	3.38726
 64.22813	 4.42000	      -0.38889	3.38724
 64.42821	 4.44000	      -0.38929	3.38722
 64.62829	 4.46000	      -0.38927	3.38719
 64.82834	 4.48000	      -0.38964	3.38716
 65.02826	 4.50000	      -0.38985	3.38713
 65.22808	 4.52000	      -0.39017	3.38710
 65.42800	 4.54000	      -0.39032	3.38707
 65.62795	 4.56000	      -0.39040	3.38704
 65.82780	 4.58000	      -0.39042	3.38701
 66.02772	 4.60000	      -0.39079	3.38698
 66.22777	 4.62000	      -0.39070	3.38694
 66.42784	 4.64000	      -0.39117	3.38691
 66.62813	 4.66000	      -0.39151	3.38687
 66.82825	 4.68000	      -0.39179	3.38683
 67.02836	 4.70000	      -0.39200	3.38680
 67.22862	 4.72000	      -0.39202	3.38676
 67.42887	 4.74000	      -0.39214	3.38672
 67.62887	 4.76000	      -0.39223	3.38668
 67.82898	 4.78000	      -0.39219	3.38663
 68.02916	 4.80000	      -0.39225	3.38659
 68.22931	 4.82000	      -0.39227	3.38655
 68.42918	 4.84000	      -0.39233	3.38650
 68.62864	 4.86000	      -0.39238	3.38646
 68.82816	 4.88000	      -0.39260	3.38641
 69.02782	 4.90000	      -0.39267	3.38636
 69.22757	 4.92000	      -0.39257	3.38631
 69.42730	 4.94000	      -0.39241	3.38626
 69.62725	 4.96000	      -0.39231	3.38621
 69.82713	 4.98000	      -0.39224	3.38616
 70.02692	 5.00000	      -0.39231	3.38611
 70.22672	 5.02000	      -0.39236	3.38605
 70.42672	 5.04000	      -0.39244	3.38600
 70.62692	 5.06000	      -0.39232	3.38594
 70.82734	 5.08000	      -0.39207	3.38588
 71.02771	 5.10000	      -0.39202	3.38583
 71.22787	 5.12000	      -0.39185	3.38577
 71.42816	 5.14000	      -0.39167	3.38571
 71.62852	 5.16000	      -0.39140	3.38565
 71.82867	 5.18000	      -0.39119	3.38558
 72.02884	 5.20000	      -0.39115	3.38552
 72.22902	 5.22000	      -0.39081	3.38546
 72.42921	 5.24000	      -0.39028	3.38539
 72.62930	 5.26000	      -0.39011	3.38533
 72.82916	 5.28000	      -0.38924	3.38526
 73.02900	 5.30000	      -0.38894	3.38519
 73.22892	 5.32000	      -0.38859	3.38512
 73.42875	 5.34000	      -0.38801	3.38505
 73.62844	 5.36000	      -0.38769	3.38498
 73.82826	 5.38000	      -0.38714	3.38491
 74.02825	 5.40000	      -0.38690	3.38484
 74.22811	 5.42000	      -0.38675	3.38477
 74.42798	 5.44000	      -0.38637	3.38469
 74.62785	 5.46000	      -0.38609	3.38462
 74.82775	 5.48000	      -0.38581	3.38454
 75.02775	 5.50000	      -0.38559	3.38446
 75.22787	 5.52000	      -0.38571	3.38439
 75.42797	 5.54000	      -0.38539	3.38431
 75.62812	 5.56000	      -0.38501	3.38423
 75.82830	 5.58000	      -0.38477	3.38414
 76.02830	 5.60000	      -0.38467	3.38406
 76.22836	 5.62000	      -0.38443	3.38398
 76.42854	 5.64000	      -0.38395	3.38389
 76.62877	 5.66000	      -0.38370	3.38381
 76.82910	 5.68000	      -0.38322	3.38372
 77.02931	 5.70000	      -0.38271	3.38364
 77.22944	 5.72000	      -0.38207	3.38355
 77.42959	 5.74000	      -0.38138	3.38346
 77.62966	 5.76000	      -0.38120	3.38337
 77.82975	 5.78000	      -0.38052	3.38328
 78.02966	 5.80000	      -0.37988	3.38319
 78.22951	 5.82000	      -0.37917	3.38309
 78.42928	 5.84000	      -0.37807	3.38300
 78.62905	 5.86000	      -0.37717	3.38291
 78.82880	 5.88000	      -0.37584	3.38281
 79.02856	 5.90000	      -0.37452	3.38271
 79.22838	 5.92000	      -0.37366	3.38262
 79.42818	 5.94000	      -0.37246	3.38252
 79.62808	 5.96000	      -0.37102	3.38242
 79.82805	 5.98000	      -0.36913	3.38232
 80.02818	 6.00000	      -0.36738	3.38222
 80.22838	 6.02000	      -0.36570	3.38212
 80.42862	 6.04000	      -0.36373	3.38201
 80.62880	 6.06000	      -0.36199	3.38191
 80.82893	 6.08000	      -0.36009	3.38180
 81.02903	 6.10000	      -0.35792	3.38170
 81.22913	 6.12000	      -0.35532	3.38159
 81.42928	 6.14000	      -0.35273	3.38148
 81.62933	 6.16000	      -0.34994	3.38137
 81.82939	 6.18000	      -0.34695	3.38126
 82.02944	 6.20000	      -0.34425	3.38115
 82.22966	 6.22000	      -0.34102	3.38104
 82.42984	 6.24000	      -0.33770	3.38093
 82.62993	 6.26000	      -0.33441	3.38081
 82.83007	 6.28000	      -0.33079	3.38070
 83.03023	 6.30000	      -0.32712	3.38058
 83.23030	 6.32000	      -0.32340	3.38047
 83.43020	 6.34000	      -0.31892	3.38035
 83.63025	 6.36000	      -0.31457	3.38023
 83.83010	 6.38000	      -0.31015	3.38011
 84.02998	 6.40000	      -0.30570	3.37999
 84.22980	 6.42000	      -0.30080	3.37987
 84.42969	 6.44000	      -0.29603	3.37975
 84.62946	 6.46000	      -0.29053	3.37963
 84.82926	 6.48000	      -0.28563	3.37950
 85.02907	 6.50000	      -0.27976	3.37938
 85.22890	 6.52000	      -0.27421	3.37925
 85.42893	 6.54000	      -0.26833	3.37913
 85.62889	 6.56000	      -0.26215	3.37900
 85.82898	 6.58000	      -0.25583	3.37887
 86.02910	 6.60000	      -0.24926	3.37874
 86.22902	 6.62000	      -0.24202	3.37861
 86.42882	 6.64000	      -0.23485	3.37848
 86.62890	 6.66000	      -0.22739	3.37835
 86.82897	 6.68000	      -0.21965	3.37821
 87.02908	 6.70000	      -0.21166	3.37808
 87.22920	 6.72000	      -0.20336	3.37794
 87.42926	 6.74000	      -0.19437	3.37781
 87.62926	 6.76000	      -0.18547	3.37767
 87.82933	 6.78000	      -0.17631	3.37753
 88.02936	 6.80000	      -0.16598	3.37739
 88.22957	 6.82000	      -0.15577	3.37726
 88.42975	 6.84000	      -0.14563	3.37711
 88.62979	 6.86000	      -0.13426	3.37697
 88.82993	 6.88000	      -0.12288	3.37683
 89.03000	 6.90000	      -0.11088	3.37669
 89.23003	 6.92000	-9.813453e-002	3.37654
 89.43005	 6.94000	-8.488586e-002	3.37640
 89.63020	 6.96000	-7.107160e-002	3.37625
 89.83002	 6.98000	-5.655691e-002	3.37610
 90.02995	 7.00000	-4.111340e-002	3.37596
 90.23002	 7.02000	-2.567758e-002	3.37581
 90.43007	 7.04000	-8.910920e-003	3.37566
 90.63018	 7.06000	 8.355365e-003	3.37551
 90.83046	 7.08000	 2.645417e-002	3.37536
 91.03077	 7.10000	 4.615966e-002	3.37520
 91.23103	 7.12000	 6.650695e-002	3.37505
 91.43133	 7.14000	 8.805162e-002	3.37490
 91.63154	 7.16000	       0.11070	3.37474
 91.83195	 7.18000	       0.13471	3.37458
 92.03229	 7.20000	       0.16009	3.37443
 92.23234	 7.22000	       0.18692	3.37427
 92.43231	 7.24000	       0.21535	3.37411
 92.63228	 7.26000	       0.24527	3.37395
 92.83205	 7.28000	       0.27710	3.37379
 93.03179	 7.30000	       0.31012	3.37363
 93.23164	 7.32000	       0.34546	3.37347
 93.43154	 7.34000	       0.38273	3.37330
 93.63148	 7.36000	       0.42210	3.37314
 93.83136	 7.38000	       0.46337	3.37297
 94.03121	 7.40000	       0.50728	3.37281
 94.23126	 7.42000	       0.55326	3.37264
 94.43116	 7.44000	       0.60210	3.37247
 94.63108	 7.46000	       0.65294	3.37230
 94.83102	 7.48000	       0.70721	3.37213
 95.03098	 7.50000	       0.76365	3.37196
 95.23087	 7.52000	       0.82261	3.37179
 95.43080	 7.54000	       0.88460	3.37162
 95.63084	 7.56000	       0.94896	3.37145
 95.83085	 7.58000	       1.01535	3.37127
 96.03089	 7.60000	       1.08416	3.37110
 96.23095	 7.62000	       1.15537	3.37092
 96.43120	 7.64000	       1.22829	3.37075
 96.63144	 7.66000	       1.30219	3.37057
 96.83172	 7.68000	       1.37762	3.37039
 97.03205	 7.70000	       1.45266	3.37021
 97.23225	 7.72000	       1.52800	3.37003
 97.43231	 7.74000	       1.60235	3.36985
 97.63231	 7.76000	       1.67418	3.36967
 97.83243	 7.78000	       1.74366	3.36948
 98.03259	 7.80000	       1.80907	3.36930
 98.23256	 7.82000	       1.87018	3.36911
 98.43238	 7.84000	       1.92554	3.36893
 98.63221	 7.86000	       1.97461	3.36874
 98.83198	 7.88000	       2.01649	3.36856
 99.03166	 7.90000	       2.05035	3.36837
 99.23129	 7.92000	       2.07570	3.36818
 99.43090	 7.94000	       2.09170	3.36799
 99.63056	 7.96000	       2.09804	3.36780
 99.82995	 7.98000	       2.09438	3.36761
100.02944	 8.00000	       2.08130	3.36742
100.22895	 8.02000	       2.05857	3.36722
100.42854	 8.04000	       2.02647	3.36703
100.62821	 8.06000	       1.98567	3.36683
100.82792	 8.08000	       1.93623	3.36664
101.02764	 8.10000	       1.87991	3.36644
101.22739	 8.12000	       1.81665	3.36624
101.42726	 8.14000	       1.74822	3.36604
101.62697	 8.16000	       1.67531	3.36585
101.82690	 8.18000	       1.59935	3.36564
102.02675	 8.20000	       1.52084	3.36544
102.22652	 8.22000	       1.44093	3.36524
102.42646	 8.24000	       1.36131	3.36504
102.62626	 8.26000	       1.28165	3.36484
102.82620	 8.28000	       1.20341	3.36463
103.02608	 8.30000	       1.12720	3.36442
103.22605	 8.32000	       1.05370	3.36422
103.42607	 8.34000	       0.98227	3.36401
103.62615	 8.36000	       0.91442	3.36380
103.82626	 8.38000	       0.84978	3.36359
104.02641	 8.40000	       0.78842	3.36338
104.22662	 8.42000	       0.73069	3.36317
104.42671	 8.44000	       0.67636	3.36296
104.62698	 8.46000	       0.62503	3.36275
104.82718	 8.48000	       0.57712	3.36253
105.02754	 8.50000	       0.53235	3.36232
105.22784	 8.52000	       0.49053	3.36210
105.42815	 8.54000	       0.45170	3.36189
105.62851	 8.56000	       0.41551	3.36167
105.82877	 8.58000	       0.38161	3.36145
106.02903	 8.60000	       0.35008	3.36123
106.22933	 8.62000	       0.32093	3.36101
106.42964	 8.64000	       0.29362	3.36079
106.62987	 8.66000	       0.26814	3.36057
106.83005	 8.68000	       0.24406	3.36035
107.03018	 8.70000	       0.22194	3.36013
107.23031	 8.72000	       0.20159	3.35990
107.43038	 8.74000	       0.18227	3.35968
107.63043	 8.76000	       0.16395	3.35945
107.83054	 8.78000	       0.14719	3.35923
108.03056	 8.80000	       0.13141	3.35900
108.23061	 8.82000	       0.11666	3.35877
108.43070	 8.84000	       0.10242	3.35854
108.63080	 8.86000	 8.910773e-002	3.35831
108.83087	 8.88000	 7.669703e-002	3.35808
109.03085	 8.90000	 6.495758e-002	3.35785
109.23090	 8.92000	 5.394998e-002	3.35762
109.43093	 8.94000	 4.380886e-002	3.35739
109.63093	 8.96000	 3.349879e-002	3.35715
109.83093	 8.98000	 2.439139e-002	3.35692
110.03105	 9.00000	 1.541467e-002	3.35668
110.23108	 9.02000	 7.234153e-003	3.35645
110.43095	 9.04000	-1.347814e-003	3.35621
110.63079	 9.06000	-8.861618e-003	3.35597
110.83079	 9.08000	-1.604256e-002	3.35573
111.03074	 9.10000	-2.326340e-002	3.35549
111.23075	 9.12000	-3.025663e-002	3.35525
111.43087	 9.14000	-3.634665e-002	3.35501
111.63089	 9.16000	-4.267253e-002	3.35477
111.83080	 9.18000	-4.866398e-002	3.35453
112.03080	 9.20000	-5.448964e-002	3.35428
112.23072	 9.22000	-5.991824e-002	3.35404
112.43072	 9.24000	-6.461211e-002	3.35379
112.63061	 9.26000	-7.000925e-002	3.35355
112.83041	 9.28000	-7.510519e-002	3.35330
113.03038	 9.30000	-8.009786e-002	3.35305
113.23030	 9.32000	-8.439946e-002	3.35280
113.43016	 9.34000	-8.860090e-002	3.35256
113.62998	 9.36000	-9.307072e-002	3.35231
113.83005	 9.38000	-9.733998e-002	3.35205
114.03005	 9.40000	      -0.10131	3.35180
114.23018	 9.42000	      -0.10515	3.35155
114.43031	 9.44000	      -0.10876	3.35130
114.63049	 9.46000	      -0.11230	3.35104
114.83066	 9.48000	      -0.11601	3.35079
115.03075	 9.50000	      -0.11980	3.35053
115.23089	 9.52000	      -0.12303	3.35027
115.43095	 9.54000	      -0.12669	3.35001
115.63105	 9.56000	      -0.12992	3.34976
115.83115	 9.58000	      -0.13312	3.34950
116.03118	 9.60000	      -0.13632	3.34924
116.23116	 9.62000	      -0.13981	3.34898
116.43113	 9.64000	      -0.14296	3.34871
116.63105	 9.66000	      -0.14599	3.34845
116.83100	 9.68000	      -0.14918	3.34819
117.03085	 9.70000	      -0.15231	3.34792
117.23072	 9.72000	      -0.15543	3.34766
117.43064	 9.74000	      -0.15868	3.34739
117.63048	 9.76000	      -0.16183	3.34713
117.83038	 9.78000	      -0.16536	3.34686
118.03026	 9.80000	      -0.16900	3.34659
118.23003	 9.82000	      -0.17289	3.34632
118.42987	 9.84000	      -0.17645	3.34605
118.62974	 9.86000	      -0.18038	3.34578
118.82972	 9.88000	      -0.18470	3.34551
119.02967	 9.90000	      -0.18907	3.34524
119.22972	 9.92000	      -0.19388	3.34497
119.42972	 9.94000	      -0.19875	3.34469
119.62984	 9.96000	      -0.20424	3.34442
119.82989	 9.98000	      -0.20999	3.34414
120.02993	10.00000	      -0.21648	3.34387
120.23007	10.02000	      -0.22257	3.34359
120.43026	10.04000	      -0.22945	3.34331
120.63057	10.06000	      -0.23699	3.34303
120.83098	10.08000	      -0.24473	3.34275
121.03125	10.10000	      -0.25326	3.34247
121.23146	10.12000	      -0.26234	3.34219
121.43143	10.14000	      -0.27210	3.34191
121.63144	10.16000	      -0.28249	3.34163
121.83138	10.18000	      -0.29353	3.34134
122.03120	10.20000	      -0.30537	3.34106
122.23105	10.22000	      -0.31771	3.34078
122.43080	10.24000	      -0.33083	3.34049
122.63041	10.26000	      -0.34465	3.34020
122.82998	10.28000	      -0.35918	3.33992
123.02969	10.30000	      -0.37366	3.33963
123.22946	10.32000	      -0.38820	3.33934
123.42938	10.34000	      -0.40250	3.33905
123.62931	10.36000	      -0.41566	3.33876
123.82938	10.38000	      -0.42846	3.33847
124.02949	10.40000	      -0.44029	3.33818
124.22964	10.42000	      -0.45072	3.33789
124.42979	10.44000	      -0.46036	3.33759
124.62990	10.46000	      -0.46851	3.33730
124.83010	10.48000	      -0.47476	3.33700
125.03036	10.50000	      -0.47861	3.33671
125.23059	10.52000	      -0.48004	3.33641
125.43077	10.54000	      -0.47790	3.33611
125.63095	10.56000	      -0.47230	3.33582
125.83115	10.58000	      -0.46229	3.33552
126.03134	10.60000	      -0.44849	3.33522
126.23157	10.62000	      -0.43048	3.33492
126.43189	10.64000	      -0.40971	3.33461
126.63229	10.66000	      -0.38742	3.33431
126.83256	10.68000	      -0.36479	3.33401
127.03269	10.70000	      -0.34328	3.33371
127.23285	10.72000	      -0.32360	3.33340
127.43305	10.74000	      -0.30699	3.33310
127.63325	10.76000	      -0.29287	3.33279
127.83330	10.78000	      -0.28167	3.33248
128.03325	10.80000	      -0.27256	3.33218
128.23310	10.82000	      -0.26592	3.33187
128.43279	10.84000	      -0.26090	3.33156
128.63249	10.86000	      -0.25729	3.33125
128.83234	10.88000	      -0.25470	3.33094
129.03210	10.90000	      -0.25271	3.33063
129.23172	10.92000	      -0.25208	3.33032
129.43120	10.94000	      -0.25155	3.33001
129.63074	10.96000	      -0.25146	3.32970
129.83034	10.98000	      -0.25201	3.32938
130.02998	11.00000	      -0.25220	3.32907
130.22972	11.02000	      -0.25340	3.32875
130.42962	11.04000	      -0.25410	3.32844
130.62956	11.06000	      -0.25550	3.32812
130.82939	11.08000	      -0.25677	3.32780
131.02929	11.10000	      -0.25820	3.32748
131.22939	11.12000	      -0.25940	3.32716
131.42969	11.14000	      -0.26105	3.32684
131.62982	11.16000	      -0.26239	3.32652
131.82993	11.18000	      -0.26396	3.32620
132.03015	11.20000	      -0.26534	3.32588
132.23039	11.22000	      -0.26664	3.32556
132.43051	11.24000	      -0.26848	3.32523
132.63057	11.26000	      -0.26971	3.32491
132.83074	11.28000	      -0.27108	3.32458
133.03093	11.30000	      -0.27275	3.32426
133.23102	11.32000	      -0.27397	3.32393
133.43106	11.34000	      -0.27503	3.32360
133.63095	11.36000	      -0.27697	3.32327
133.83093	11.38000	      -0.27830	3.32295
134.03093	11.40000	      -0.27973	3.32262
134.23082	11.42000	      -0.28071	3.32229
134.43085	11.44000	      -0.28229	3.32195
134.63083	11.46000	      -0.28341	3.32162
134.83065	11.48000	      -0.28469	3.32129
135.03047	11.50000	      -0.28598	3.32096
135.23033	11.52000	      -0.28703	3.32062
135.43008	11.54000	      -0.28888	3.32029
135.63008	11.56000	      -0.28992	3.31995
135.83015	11.58000	      -0.29117	3.31962
136.03020	11.60000	      -0.29197	3.31928
136.23038	11.62000	      -0.29323	3.31894
136.43047	11.64000	      -0.29413	3.31861
136.63067	11.66000	      -0.29479	3.31827
136.83088	11.68000	      -0.29565	3.31793
137.03105	11.70000	      -0.29624	3.31759
137.23120	11.72000	      -0.29672	3.31724
137.43125	11.74000	      -0.29734	3.31690
137.63136	11.76000	      -0.29793	3.31656
137.83141	11.78000	      -0.29821	3.31622
138.03141	11.80000	      -0.29826	3.31587
138.23130	11.82000	      -0.29839	3.31553
138.43125	11.84000	      -0.29886	3.31518
138.63121	11.86000	      -0.29899	3.31484
138.83118	11.88000	      -0.29916	3.31449
139.03113	11.90000	      -0.29901	3.31414
139.23115	11.92000	      -0.29905	3.31379
139.43129	11.94000	      -0.29898	3.31344
139.63141	11.96000	      -0.29894	3.31309
139.83139	11.98000	      -0.29911	3.31274
140.03139	12.00000	      -0.29884	3.31239
140.23143	12.02000	      -0.29892	3.31204
140.43134	12.04000	      -0.29872	3.31169
140.63116	12.06000	      -0.29845	3.31134
140.83110	12.08000	      -0.29792	3.31098
141.03110	12.10000	      -0.29759	3.31063
141.23103	12.12000	      -0.29747	3.31027
141.43112	12.14000	      -0.29731	3.30992
141.63098	12.16000	      -0.29682	3.30956
141.83097	12.18000	      -0.29639	3.30920
142.03089	12.20000	      -0.29640	3.30884
142.23079	12.22000	      -0.29629	3.30849
142.43079	12.24000	      -0.29560	3.30813
142.63087	12.26000	      -0.29555	3.30777
142.83097	12.28000	      -0.29507	3.30741
143.03103	12.30000	      -0.29505	3.30704
143.23118	12.32000	      -0.29484	3.30668
143.43120	12.34000	      -0.29452	3.30632
143.63120	12.36000	      -0.29428	3.30595
143.83111	12.38000	      -0.29386	3.30559
144.03120	12.40000	      -0.29354	3.30523
144.23130	12.42000	      -0.29320	3.30486
144.43138	12.44000	      -0.29266	3.30449
144.63113	12.46000	      -0.29215	3.30413
144.83087	12.48000	      -0.29171	3.30376
145.03057	12.50000	      -0.29124	3.30339
145.23031	12.52000	      -0.29099	3.30302
145.43010	12.54000	      -0.29071	3.30265
145.62995	12.56000	      -0.29057	3.30228
145.82987	12.58000	      -0.29025	3.30191
146.02979	12.60000	      -0.29008	3.30154
146.22972	12.62000	      -0.28984	3.30117
146.42962	12.64000	      -0.28930	3.30080
146.62979	12.66000	      -0.28913	3.30042
146.82998	12.68000	      -0.28865	3.30005
147.03012	12.70000	      -0.28842	3.29967
147.23036	12.72000	      -0.28823	3.29929
147.43048	12.74000	      -0.28756	3.29892
147.63062	12.76000	      -0.28730	3.29854
147.83084	12.78000	      -0.28704	3.29816
148.03103	12.80000	      -0.28658	3.29778
148.23116	12.82000	      -0.28617	3.29740
148.43139	12.84000	      -0.28596	3.29702
148.63161	12.86000	      -0.28549	3.29664
148.83174	12.88000	      -0.28508	3.29626
149.03192	12.90000	      -0.28443	3.29588
149.23192	12.92000	      -0.28414	3.29550
149.43189	12.94000	      -0.28361	3.29511
149.63189	12.96000	      -0.28304	3.29473
149.83180	12.98000	      -0.28262	3.29435
150.03167	13.00000	      -0.28213	3.29396
150.23148	13.02000	      -0.28173	3.29358
150.43133	13.04000	      -0.28110	3.29319
150.63112	13.06000	      -0.28095	3.29280
150.83095	13.08000	      -0.28045	3.29241
151.03077	13.10000	      -0.27991	3.29203
151.23066	13.12000	      -0.27933	3.29164
151.43061	13.14000	      -0.27910	3.29125
151.63043	13.16000	      -0.27853	3.29086
151.83048	13.18000	      -0.27812	3.29047
152.03049	13.20000	      -0.27707	3.29008
152.23059	13.22000	      -0.27714	3.28968
152.43066	13.24000	      -0.27642	3.28929
152.63072	13.26000	      -0.27597	3.28890
152.83075	13.28000	      -0.27549	3.28850
153.03089	13.30000	      -0.27494	3.28811
153.23098	13.32000	      -0.27401	3.28771
153.43108	13.34000	      -0.27353	3.28731
153.63128	13.36000	      -0.27301	3.28692
153.83136	13.38000	      -0.27238	3.28652
154.03139	13.40000	      -0.27176	3.28612
154.23148	13.42000	      -0.27119	3.28572
154.43159	13.44000	      -0.27010	3.28532
154.63161	13.46000	      -0.26963	3.28492
154.83180	13.48000	      -0.26881	3.28452
155.03202	13.50000	      -0.26845	3.28412
155.23216	13.52000	      -0.26753	3.28372
155.43218	13.54000	      -0.26696	3.28332
155.63219	13.56000	      -0.26604	3.28291
155.83233	13.58000	      -0.26563	3.28251
156.03261	13.60000	      -0.26488	3.28210
156.23272	13.62000	      -0.26401	3.28170
156.43167	13.64000	      -0.26310	3.28129
156.53167	13.65000	      -0.26272	3.28109