File: data/ExpDat_SK_Clear_resin_entalp10kpm_20-150.txt
#EXPORTTYPE:                 	DATA SINGLE
#FILE:                       	SK_Clear_resin_entalp10kpm_20-150.ngb-sdg
#FORMAT:                     	NETZSCH5
#FTYPE:                      	ASCII
#IDENTITY:                   	SK_clear_resin
#DECIMAL:                    	POINT
#SEPARATOR:                  	TAB
#MTYPE:                      	DSC
#INSTRUMENT:                 	NETZSCH DSC 214
#PROJECT:                    	?ø?†??-Ø
#DATE/TIME:                  	13.09.2019 18:18:30 (UTC+3)
#CORR. FILE:
#TEMPCAL:                    	applied
#SENSITIVITY:                	applied
#LABORATORY:                 	CISIS
#OPERATOR:                   	Nasonov
#REMARK:
#SAMPLE:                     	1070-G290S -0-Ù.1-3-17X3
#SAMPLE MASS /mg:            	7.81
#MATERIAL:
#REFERENCE:
#REFERENCE MASS /mg:         	7.76
#TYPE OF CRUCIBLE:           	Concavus Pan Al, pierced lid
#SAMPLE CRUCIBLE MASS /mg:   	0
#REFERENCE CRUCIBLE MASS /mg:	0
#M.RANGE /ßV:                	5000
#TAU-R:                      	---
#CORR. CODE:                 	009
#EXO:                        	+1
#RANGE:                      	20ËC/10.0(K/min)/150ËC
#SEGMENT:                    	S1/1
#SEG. 1:                     	20ËC/10.0(K/min)/150ËC

##Temp./ËC	Time/min	DSC/(mW/mg)	Sensit./(uV/mW)
 20.04200	 0.00000	 2.977584e-002	3.36736
 20.04054	 0.02000	 2.948481e-002	3.36736
 20.06740	 0.04000	 2.954732e-002	3.36738
 20.15027	 0.06000	 3.920236e-002	3.36747
 20.28794	 0.08000	 5.445116e-002	3.36761
 20.47241	 0.10000	 6.351191e-002	3.36780
 20.63192	 0.12000	 6.292694e-002	3.36797
 20.82152	 0.14000	 5.220800e-002	3.36816
 21.04020	 0.16000	 3.202363e-002	3.36838
 21.28336	 0.18000	 3.686191e-003	3.36863
 21.54605	 0.20000	-3.142066e-002	3.36889
 21.82318	 0.22000	-7.098074e-002	3.36917
 22.10980	 0.24000	      -0.11301	3.36945
 22.40136	 0.26000	      -0.15592	3.36974
 22.69364	 0.28000	      -0.19706	3.37003
 22.98302	 0.30000	      -0.23564	3.37030
 23.26643	 0.32000	      -0.27045	3.37058
 23.54157	 0.34000	      -0.30089	3.37084
 23.80680	 0.36000	      -0.32634	3.37109
 24.06108	 0.38000	      -0.34644	3.37133
 24.30385	 0.40000	      -0.36109	3.37155
 24.53511	 0.42000	      -0.37045	3.37176
 24.75543	 0.44000	      -0.37550	3.37197
 24.96544	 0.46000	      -0.37613	3.37216
 25.16638	 0.48000	      -0.37339	3.37234
 25.35933	 0.50000	      -0.36757	3.37251
 25.54562	 0.52000	      -0.35950	3.37268
 25.72661	 0.54000	      -0.34960	3.37284
 25.90357	 0.56000	      -0.33869	3.37300
 26.07784	 0.58000	      -0.32751	3.37315
 26.25066	 0.60000	      -0.31611	3.37330
 26.42315	 0.62000	      -0.30488	3.37345
 26.59592	 0.64000	      -0.29510	3.37360
 26.76954	 0.66000	      -0.28569	3.37375
 26.94479	 0.68000	      -0.27747	3.37390
 27.12231	 0.70000	      -0.27056	3.37405
 27.30230	 0.72000	      -0.26546	3.37420
 27.48489	 0.74000	      -0.26136	3.37436
 27.67008	 0.76000	      -0.25874	3.37451
 27.85797	 0.78000	      -0.25736	3.37467
 28.04852	 0.80000	      -0.25594	3.37482
 28.24116	 0.82000	      -0.25643	3.37498
 28.43593	 0.84000	      -0.25801	3.37514
 28.63280	 0.86000	      -0.25971	3.37530
 28.83125	 0.88000	      -0.26207	3.37546
 29.03082	 0.90000	      -0.26459	3.37562
 29.23133	 0.92000	      -0.26749	3.37578
 29.43252	 0.94000	      -0.27030	3.37594
 29.63421	 0.96000	      -0.27314	3.37610
 29.83616	 0.98000	      -0.27600	3.37625
 30.03792	 1.00000	      -0.27870	3.37641
 30.23979	 1.02000	      -0.28059	3.37656
 30.44151	 1.04000	      -0.28323	3.37672
 30.64293	 1.06000	      -0.28507	3.37687
 30.84407	 1.08000	      -0.28667	3.37702
 31.04480	 1.10000	      -0.28751	3.37717
 31.24526	 1.12000	      -0.28888	3.37732
 31.44531	 1.14000	      -0.28981	3.37746
 31.64495	 1.16000	      -0.29016	3.37761
 31.84428	 1.18000	      -0.29083	3.37775
 32.04348	 1.20000	      -0.29106	3.37790
 32.24239	 1.22000	      -0.29107	3.37804
 32.44105	 1.24000	      -0.29127	3.37818
 32.63956	 1.26000	      -0.29119	3.37832
 32.83816	 1.28000	      -0.29117	3.37846
 33.03672	 1.30000	      -0.29117	3.37859
 33.23516	 1.32000	      -0.29096	3.37873
 33.43367	 1.34000	      -0.29101	3.37887
 33.63228	 1.36000	      -0.29097	3.37900
 33.83097	 1.38000	      -0.29079	3.37913
 34.02974	 1.40000	      -0.29098	3.37926
 34.22862	 1.42000	      -0.29140	3.37940
 34.42769	 1.44000	      -0.29136	3.37953
 34.62687	 1.46000	      -0.29135	3.37965
 34.82610	 1.48000	      -0.29122	3.37978
 35.02529	 1.50000	      -0.29154	3.37991
 35.22452	 1.52000	      -0.29178	3.38004
 35.42395	 1.54000	      -0.29225	3.38016
 35.62356	 1.56000	      -0.29266	3.38028
 35.82333	 1.58000	      -0.29298	3.38041
 36.02298	 1.60000	      -0.29360	3.38053
 36.22272	 1.62000	      -0.29378	3.38065
 36.42266	 1.64000	      -0.29433	3.38077
 36.62254	 1.66000	      -0.29490	3.38089
 36.82241	 1.68000	      -0.29528	3.38101
 37.02236	 1.70000	      -0.29563	3.38112
 37.22254	 1.72000	      -0.29625	3.38124
 37.42262	 1.74000	      -0.29691	3.38135
 37.62267	 1.76000	      -0.29733	3.38147
 37.82270	 1.78000	      -0.29796	3.38158
 38.02289	 1.80000	      -0.29873	3.38169
 38.22295	 1.82000	      -0.29941	3.38180
 38.42297	 1.84000	      -0.29976	3.38191
 38.62297	 1.86000	      -0.30029	3.38202
 38.82305	 1.88000	      -0.30094	3.38213
 39.02316	 1.90000	      -0.30168	3.38223
 39.22325	 1.92000	      -0.30194	3.38234
 39.42343	 1.94000	      -0.30229	3.38244
 39.62362	 1.96000	      -0.30263	3.38255
 39.82374	 1.98000	      -0.30289	3.38265
 40.02371	 2.00000	      -0.30321	3.38275
 40.22375	 2.02000	      -0.30340	3.38285
 40.42379	 2.04000	      -0.30374	3.38295
 40.62389	 2.06000	      -0.30417	3.38304
 40.82392	 2.08000	      -0.30456	3.38314
 41.02374	 2.10000	      -0.30480	3.38324
 41.22366	 2.12000	      -0.30499	3.38333
 41.42346	 2.14000	      -0.30556	3.38342
 41.62336	 2.16000	      -0.30614	3.38352
 41.82331	 2.18000	      -0.30636	3.38361
 42.02343	 2.20000	      -0.30699	3.38370
 42.22352	 2.22000	      -0.30722	3.38379
 42.42367	 2.24000	      -0.30760	3.38388
 42.62384	 2.26000	      -0.30821	3.38396
 42.82389	 2.28000	      -0.30865	3.38405
 43.02403	 2.30000	      -0.30910	3.38413
 43.22416	 2.32000	      -0.30971	3.38422
 43.42418	 2.34000	      -0.31016	3.38430
 43.62389	 2.36000	      -0.31043	3.38438
 43.82361	 2.38000	      -0.31093	3.38446
 44.02331	 2.40000	      -0.31171	3.38454
 44.22308	 2.42000	      -0.31162	3.38462
 44.42270	 2.44000	      -0.31214	3.38470
 44.62241	 2.46000	      -0.31252	3.38477
 44.82225	 2.48000	      -0.31284	3.38485
 45.02220	 2.50000	      -0.31336	3.38492
 45.22218	 2.52000	      -0.31384	3.38500
 45.42228	 2.54000	      -0.31423	3.38507
 45.62264	 2.56000	      -0.31453	3.38514
 45.82308	 2.58000	      -0.31489	3.38521
 46.02344	 2.60000	      -0.31537	3.38528
 46.22385	 2.62000	      -0.31592	3.38535
 46.42421	 2.64000	      -0.31630	3.38541
 46.62454	 2.66000	      -0.31659	3.38548
 46.82479	 2.68000	      -0.31676	3.38555
 47.02507	 2.70000	      -0.31732	3.38561
 47.22533	 2.72000	      -0.31771	3.38567
 47.42561	 2.74000	      -0.31799	3.38573
 47.62587	 2.76000	      -0.31813	3.38580
 47.82602	 2.78000	      -0.31840	3.38586
 48.02602	 2.80000	      -0.31891	3.38591
 48.22587	 2.82000	      -0.31925	3.38597
 48.42579	 2.84000	      -0.31952	3.38603
 48.62577	 2.86000	      -0.31983	3.38608
 48.82577	 2.88000	      -0.32025	3.38614
 49.02579	 2.90000	      -0.32059	3.38619
 49.22577	 2.92000	      -0.32072	3.38624
 49.42566	 2.94000	      -0.32077	3.38630
 49.62602	 2.96000	      -0.32125	3.38635
 49.82634	 2.98000	      -0.32167	3.38639
 50.02623	 3.00000	      -0.32194	3.38644
 50.22616	 3.02000	      -0.32219	3.38649
 50.42607	 3.04000	      -0.32252	3.38654
 50.62600	 3.06000	      -0.32268	3.38658
 50.82592	 3.08000	      -0.32317	3.38663
 51.02575	 3.10000	      -0.32357	3.38667
 51.22569	 3.12000	      -0.32384	3.38671
 51.42556	 3.14000	      -0.32373	3.38675
 51.62516	 3.16000	      -0.32427	3.38679
 51.82456	 3.18000	      -0.32442	3.38683
 52.02462	 3.20000	      -0.32474	3.38687
 52.22480	 3.22000	      -0.32492	3.38690
 52.42497	 3.24000	      -0.32520	3.38694
 52.62513	 3.26000	      -0.32558	3.38697
 52.82530	 3.28000	      -0.32591	3.38701
 53.02539	 3.30000	      -0.32638	3.38704
 53.22536	 3.32000	      -0.32642	3.38707
 53.42546	 3.34000	      -0.32638	3.38710
 53.62543	 3.36000	      -0.32657	3.38713
 53.82556	 3.38000	      -0.32668	3.38716
 54.02575	 3.40000	      -0.32716	3.38719
 54.22598	 3.42000	      -0.32728	3.38722
 54.42623	 3.44000	      -0.32737	3.38724
 54.62636	 3.46000	      -0.32728	3.38727
 54.82633	 3.48000	      -0.32751	3.38729
 55.02644	 3.50000	      -0.32780	3.38731
 55.22648	 3.52000	      -0.32802	3.38733
 55.42652	 3.54000	      -0.32819	3.38735
 55.62661	 3.56000	      -0.32833	3.38737
 55.82652	 3.58000	      -0.32841	3.38739
 56.02657	 3.60000	      -0.32839	3.38741
 56.22664	 3.62000	      -0.32842	3.38742
 56.42669	 3.64000	      -0.32854	3.38744
 56.62666	 3.66000	      -0.32854	3.38745
 56.82669	 3.68000	      -0.32872	3.38747
 57.02666	 3.70000	      -0.32871	3.38748
 57.22679	 3.72000	      -0.32892	3.38749
 57.42687	 3.74000	      -0.32918	3.38750
 57.62695	 3.76000	      -0.32905	3.38751
 57.82705	 3.78000	      -0.32914	3.38752
 58.02698	 3.80000	      -0.32909	3.38752
 58.22695	 3.82000	      -0.32900	3.38753
 58.42690	 3.84000	      -0.32911	3.38754
 58.62685	 3.86000	      -0.32905	3.38754
 58.82689	 3.88000	      -0.32916	3.38754
 59.02690	 3.90000	      -0.32919	3.38754
 59.22697	 3.92000	      -0.32921	3.38755
 59.42697	 3.94000	      -0.32938	3.38755
 59.62710	 3.96000	      -0.32938	3.38754
 59.82729	 3.98000	      -0.32949	3.38754
 60.02743	 4.00000	      -0.32953	3.38754
 60.22749	 4.02000	      -0.32961	3.38754
 60.42754	 4.04000	      -0.32960	3.38753
 60.62770	 4.06000	      -0.32959	3.38752
 60.82782	 4.08000	      -0.32952	3.38752
 61.02787	 4.10000	      -0.32948	3.38751
 61.22789	 4.12000	      -0.32944	3.38750
 61.42789	 4.14000	      -0.32949	3.38749
 61.62789	 4.16000	      -0.32954	3.38748
 61.82790	 4.18000	      -0.32941	3.38747
 62.02789	 4.20000	      -0.32923	3.38745
 62.22797	 4.22000	      -0.32896	3.38744
 62.42803	 4.24000	      -0.32875	3.38742
 62.62813	 4.26000	      -0.32867	3.38741
 62.82831	 4.28000	      -0.32849	3.38739
 63.02862	 4.30000	      -0.32857	3.38737
 63.22902	 4.32000	      -0.32854	3.38735
 63.42925	 4.34000	      -0.32846	3.38733
 63.62949	 4.36000	      -0.32843	3.38731
 63.82959	 4.38000	      -0.32837	3.38729
 64.02977	 4.40000	      -0.32823	3.38726
 64.22984	 4.42000	      -0.32801	3.38724
 64.42969	 4.44000	      -0.32810	3.38722
 64.62948	 4.46000	      -0.32768	3.38719
 64.82934	 4.48000	      -0.32754	3.38716
 65.02897	 4.50000	      -0.32727	3.38713
 65.22861	 4.52000	      -0.32722	3.38710
 65.42839	 4.54000	      -0.32709	3.38707
 65.62815	 4.56000	      -0.32685	3.38704
 65.82797	 4.58000	      -0.32663	3.38701
 66.02772	 4.60000	      -0.32638	3.38698
 66.22759	 4.62000	      -0.32607	3.38694
 66.42752	 4.64000	      -0.32573	3.38691
 66.62741	 4.66000	      -0.32554	3.38687
 66.82720	 4.68000	      -0.32531	3.38684
 67.02707	 4.70000	      -0.32512	3.38680
 67.22702	 4.72000	      -0.32526	3.38676
 67.42703	 4.74000	      -0.32508	3.38672
 67.62698	 4.76000	      -0.32495	3.38668
 67.82693	 4.78000	      -0.32477	3.38663
 68.02685	 4.80000	      -0.32474	3.38659
 68.22680	 4.82000	      -0.32467	3.38655
 68.42687	 4.84000	      -0.32463	3.38650
 68.62716	 4.86000	      -0.32459	3.38646
 68.82746	 4.88000	      -0.32466	3.38641
 69.02779	 4.90000	      -0.32461	3.38636
 69.22813	 4.92000	      -0.32458	3.38631
 69.42820	 4.94000	      -0.32452	3.38626
 69.62856	 4.96000	      -0.32449	3.38621
 69.82890	 4.98000	      -0.32441	3.38616
 70.02928	 5.00000	      -0.32441	3.38611
 70.22938	 5.02000	      -0.32416	3.38605
 70.42930	 5.04000	      -0.32406	3.38600
 70.62921	 5.06000	      -0.32401	3.38594
 70.82925	 5.08000	      -0.32397	3.38588
 71.02920	 5.10000	      -0.32387	3.38583
 71.22918	 5.12000	      -0.32374	3.38577
 71.42915	 5.14000	      -0.32359	3.38571
 71.62895	 5.16000	      -0.32332	3.38565
 71.82869	 5.18000	      -0.32314	3.38558
 72.02843	 5.20000	      -0.32302	3.38552
 72.22833	 5.22000	      -0.32301	3.38546
 72.42831	 5.24000	      -0.32278	3.38539
 72.62826	 5.26000	      -0.32269	3.38533
 72.82816	 5.28000	      -0.32228	3.38526
 73.02816	 5.30000	      -0.32205	3.38519
 73.22813	 5.32000	      -0.32157	3.38512
 73.42815	 5.34000	      -0.32115	3.38505
 73.62810	 5.36000	      -0.32050	3.38498
 73.82813	 5.38000	      -0.31996	3.38491
 74.02831	 5.40000	      -0.31938	3.38484
 74.22857	 5.42000	      -0.31867	3.38477
 74.42890	 5.44000	      -0.31802	3.38469
 74.62907	 5.46000	      -0.31717	3.38462
 74.82923	 5.48000	      -0.31618	3.38454
 75.02921	 5.50000	      -0.31529	3.38446
 75.22923	 5.52000	      -0.31415	3.38438
 75.42928	 5.54000	      -0.31312	3.38431
 75.62931	 5.56000	      -0.31187	3.38423
 75.82928	 5.58000	      -0.31041	3.38414
 76.02915	 5.60000	      -0.30872	3.38406
 76.22900	 5.62000	      -0.30714	3.38398
 76.42875	 5.64000	      -0.30545	3.38389
 76.62874	 5.66000	      -0.30359	3.38381
 76.82864	 5.68000	      -0.30182	3.38372
 77.02866	 5.70000	      -0.29979	3.38364
 77.22861	 5.72000	      -0.29787	3.38355
 77.42851	 5.74000	      -0.29597	3.38346
 77.62849	 5.76000	      -0.29333	3.38337
 77.82849	 5.78000	      -0.29109	3.38328
 78.02848	 5.80000	      -0.28894	3.38319
 78.22857	 5.82000	      -0.28668	3.38309
 78.42866	 5.84000	      -0.28387	3.38300
 78.62877	 5.86000	      -0.28141	3.38291
 78.82887	 5.88000	      -0.27860	3.38281
 79.02900	 5.90000	      -0.27570	3.38271
 79.22908	 5.92000	      -0.27266	3.38262
 79.42915	 5.94000	      -0.26933	3.38252
 79.62928	 5.96000	      -0.26603	3.38242
 79.82939	 5.98000	      -0.26270	3.38232
 80.02944	 6.00000	      -0.25913	3.38222
 80.22936	 6.02000	      -0.25547	3.38211
 80.42931	 6.04000	      -0.25144	3.38201
 80.62929	 6.06000	      -0.24733	3.38191
 80.82928	 6.08000	      -0.24321	3.38180
 81.02929	 6.10000	      -0.23895	3.38170
 81.22938	 6.12000	      -0.23441	3.38159
 81.42946	 6.14000	      -0.22949	3.38148
 81.62946	 6.16000	      -0.22463	3.38137
 81.82951	 6.18000	      -0.21965	3.38126
 82.02969	 6.20000	      -0.21438	3.38115
 82.22989	 6.22000	      -0.20877	3.38104
 82.42997	 6.24000	      -0.20278	3.38093
 82.63002	 6.26000	      -0.19699	3.38081
 82.82985	 6.28000	      -0.19072	3.38070
 83.02977	 6.30000	      -0.18417	3.38058
 83.22967	 6.32000	      -0.17740	3.38047
 83.42972	 6.34000	      -0.17011	3.38035
 83.62980	 6.36000	      -0.16248	3.38023
 83.82974	 6.38000	      -0.15452	3.38011
 84.02979	 6.40000	      -0.14649	3.37999
 84.22969	 6.42000	      -0.13826	3.37987
 84.42956	 6.44000	      -0.12956	3.37975
 84.62951	 6.46000	      -0.12020	3.37963
 84.82961	 6.48000	      -0.11073	3.37950
 85.02969	 6.50000	      -0.10052	3.37938
 85.22974	 6.52000	-8.990322e-002	3.37925
 85.42970	 6.54000	-7.890842e-002	3.37913
 85.62962	 6.56000	-6.736238e-002	3.37900
 85.82969	 6.58000	-5.500557e-002	3.37887
 86.02966	 6.60000	-4.210113e-002	3.37874
 86.22982	 6.62000	-2.865487e-002	3.37861
 86.42998	 6.64000	-1.425262e-002	3.37848
 86.63011	 6.66000	 1.191329e-003	3.37835
 86.83011	 6.68000	 1.663648e-002	3.37821
 87.03021	 6.70000	 3.361112e-002	3.37808
 87.23039	 6.72000	 5.145626e-002	3.37794
 87.43046	 6.74000	 7.025686e-002	3.37781
 87.63056	 6.76000	 9.012947e-002	3.37767
 87.83066	 6.78000	       0.11177	3.37753
 88.03085	 6.80000	       0.13402	3.37739
 88.23075	 6.82000	       0.15817	3.37725
 88.43074	 6.84000	       0.18367	3.37711
 88.63079	 6.86000	       0.21028	3.37697
 88.83089	 6.88000	       0.23877	3.37683
 89.03084	 6.90000	       0.26925	3.37669
 89.23085	 6.92000	       0.30145	3.37654
 89.43092	 6.94000	       0.33479	3.37640
 89.63102	 6.96000	       0.37132	3.37625
 89.83100	 6.98000	       0.40981	3.37610
 90.03100	 7.00000	       0.45048	3.37596
 90.23118	 7.02000	       0.49296	3.37581
 90.43133	 7.04000	       0.53788	3.37566
 90.63141	 7.06000	       0.58663	3.37551
 90.83141	 7.08000	       0.63656	3.37536
 91.03159	 7.10000	       0.68984	3.37520
 91.23164	 7.12000	       0.74753	3.37505
 91.43179	 7.14000	       0.80658	3.37489
 91.63195	 7.16000	       0.86859	3.37474
 91.83225	 7.18000	       0.93324	3.37458
 92.03246	 7.20000	       1.00213	3.37443
 92.23266	 7.22000	       1.07295	3.37427
 92.43279	 7.24000	       1.14593	3.37411
 92.63297	 7.26000	       1.22174	3.37395
 92.83333	 7.28000	       1.30006	3.37379
 93.03352	 7.30000	       1.38130	3.37363
 93.23356	 7.32000	       1.46320	3.37346
 93.43367	 7.34000	       1.54648	3.37330
 93.63366	 7.36000	       1.63045	3.37314
 93.83348	 7.38000	       1.71467	3.37297
 94.03323	 7.40000	       1.79872	3.37281
 94.23302	 7.42000	       1.88166	3.37264
 94.43282	 7.44000	       1.96261	3.37247
 94.63274	 7.46000	       2.04119	3.37230
 94.83251	 7.48000	       2.11583	3.37213
 95.03236	 7.50000	       2.18637	3.37196
 95.23220	 7.52000	       2.25212	3.37179
 95.43202	 7.54000	       2.31162	3.37162
 95.63175	 7.56000	       2.36435	3.37145
 95.83151	 7.58000	       2.40998	3.37127
 96.03123	 7.60000	       2.44751	3.37110
 96.23098	 7.62000	       2.47675	3.37092
 96.43074	 7.64000	       2.49760	3.37075
 96.63030	 7.66000	       2.50953	3.37057
 96.82979	 7.68000	       2.51218	3.37039
 97.02925	 7.70000	       2.50561	3.37021
 97.22867	 7.72000	       2.49055	3.37003
 97.42818	 7.74000	       2.46690	3.36985
 97.62772	 7.76000	       2.43482	3.36967
 97.82731	 7.78000	       2.39534	3.36949
 98.02700	 7.80000	       2.34878	3.36930
 98.22662	 7.82000	       2.29567	3.36912
 98.42633	 7.84000	       2.23720	3.36893
 98.62605	 7.86000	       2.17388	3.36875
 98.82579	 7.88000	       2.10643	3.36856
 99.02562	 7.90000	       2.03605	3.36837
 99.22559	 7.92000	       1.96316	3.36818
 99.42557	 7.94000	       1.88889	3.36799
 99.62566	 7.96000	       1.81331	3.36780
 99.82569	 7.98000	       1.73772	3.36761
100.02574	 8.00000	       1.66225	3.36742
100.22579	 8.02000	       1.58764	3.36723
100.42584	 8.04000	       1.51402	3.36703
100.62600	 8.06000	       1.44256	3.36684
100.82625	 8.08000	       1.37275	3.36664
101.02639	 8.10000	       1.30460	3.36644
101.22666	 8.12000	       1.23888	3.36624
101.42695	 8.14000	       1.17544	3.36604
101.62713	 8.16000	       1.11505	3.36585
101.82739	 8.18000	       1.05595	3.36564
102.02767	 8.20000	       1.00040	3.36544
102.22803	 8.22000	       0.94790	3.36524
102.42836	 8.24000	       0.89668	3.36504
102.62849	 8.26000	       0.84899	3.36483
102.82857	 8.28000	       0.80355	3.36463
103.02877	 8.30000	       0.75968	3.36442
103.22889	 8.32000	       0.71801	3.36422
103.42893	 8.34000	       0.68040	3.36401
103.62902	 8.36000	       0.64327	3.36380
103.82908	 8.38000	       0.60786	3.36359
104.02920	 8.40000	       0.57583	3.36338
104.22925	 8.42000	       0.54392	3.36317
104.42934	 8.44000	       0.51395	3.36296
104.62956	 8.46000	       0.48662	3.36274
104.82979	 8.48000	       0.46112	3.36253
105.02997	 8.50000	       0.43565	3.36232
105.23003	 8.52000	       0.41219	3.36210
105.43020	 8.54000	       0.38960	3.36189
105.63034	 8.56000	       0.36843	3.36167
105.83039	 8.58000	       0.34804	3.36145
106.03054	 8.60000	       0.32933	3.36123
106.23080	 8.62000	       0.31125	3.36101
106.43108	 8.64000	       0.29416	3.36079
106.63125	 8.66000	       0.27779	3.36057
106.83141	 8.68000	       0.26241	3.36035
107.03148	 8.70000	       0.24778	3.36013
107.23167	 8.72000	       0.23393	3.35990
107.43184	 8.74000	       0.22092	3.35968
107.63187	 8.76000	       0.20829	3.35945
107.83184	 8.78000	       0.19624	3.35923
108.03169	 8.80000	       0.18506	3.35900
108.23144	 8.82000	       0.17417	3.35877
108.43110	 8.84000	       0.16393	3.35854
108.63071	 8.86000	       0.15403	3.35831
108.83034	 8.88000	       0.14454	3.35808
109.03018	 8.90000	       0.13546	3.35785
109.22995	 8.92000	       0.12719	3.35762
109.42964	 8.94000	       0.11885	3.35739
109.62952	 8.96000	       0.11099	3.35716
109.82944	 8.98000	       0.10353	3.35692
110.02933	 9.00000	 9.627516e-002	3.35669
110.22918	 9.02000	 8.921658e-002	3.35645
110.42895	 9.04000	 8.250706e-002	3.35621
110.62892	 9.06000	 7.579625e-002	3.35597
110.82895	 9.08000	 6.972457e-002	3.35574
111.02897	 9.10000	 6.396751e-002	3.35550
111.22902	 9.12000	 5.820533e-002	3.35526
111.42905	 9.14000	 5.255843e-002	3.35501
111.62900	 9.16000	 4.729080e-002	3.35477
111.82907	 9.18000	 4.210902e-002	3.35453
112.02931	 9.20000	 3.710113e-002	3.35429
112.22949	 9.22000	 3.232246e-002	3.35404
112.42985	 9.24000	 2.786347e-002	3.35379
112.63018	 9.26000	 2.322944e-002	3.35355
112.83039	 9.28000	 1.894395e-002	3.35330
113.03057	 9.30000	 1.460356e-002	3.35305
113.23079	 9.32000	 1.074757e-002	3.35280
113.43095	 9.34000	 6.950808e-003	3.35255
113.63107	 9.36000	 3.239763e-003	3.35230
113.83120	 9.38000	-2.674604e-004	3.35205
114.03120	 9.40000	-3.596847e-003	3.35180
114.23123	 9.42000	-6.936976e-003	3.35155
114.43143	 9.44000	-1.013185e-002	3.35129
114.63154	 9.46000	-1.326891e-002	3.35104
114.83169	 9.48000	-1.602708e-002	3.35078
115.03179	 9.50000	-1.891024e-002	3.35053
115.23182	 9.52000	-2.197689e-002	3.35027
115.43192	 9.54000	-2.478158e-002	3.35001
115.63195	 9.56000	-2.752876e-002	3.34975
115.83195	 9.58000	-3.039341e-002	3.34950
116.03184	 9.60000	-3.281982e-002	3.34924
116.23179	 9.62000	-3.518174e-002	3.34897
116.43149	 9.64000	-3.768911e-002	3.34871
116.63125	 9.66000	-3.970246e-002	3.34845
116.83098	 9.68000	-4.218256e-002	3.34819
117.03074	 9.70000	-4.449131e-002	3.34792
117.23046	 9.72000	-4.646974e-002	3.34766
117.43036	 9.74000	-4.859637e-002	3.34739
117.63023	 9.76000	-5.066383e-002	3.34713
117.83012	 9.78000	-5.270205e-002	3.34686
118.03005	 9.80000	-5.455712e-002	3.34659
118.22995	 9.82000	-5.656441e-002	3.34632
118.42997	 9.84000	-5.833848e-002	3.34605
118.63007	 9.86000	-6.005482e-002	3.34578
118.83015	 9.88000	-6.180143e-002	3.34551
119.03025	 9.90000	-6.343166e-002	3.34524
119.23046	 9.92000	-6.515781e-002	3.34497
119.43034	 9.94000	-6.688310e-002	3.34469
119.63038	 9.96000	-6.834620e-002	3.34442
119.83039	 9.98000	-6.995637e-002	3.34414
120.03048	10.00000	-7.121668e-002	3.34387
120.23057	10.02000	-7.298121e-002	3.34359
120.43074	10.04000	-7.395752e-002	3.34331
120.63072	10.06000	-7.569224e-002	3.34303
120.83070	10.08000	-7.690200e-002	3.34275
121.03069	10.10000	-7.843725e-002	3.34247
121.23062	10.12000	-7.978609e-002	3.34219
121.43085	10.14000	-8.110598e-002	3.34191
121.63097	10.16000	-8.239801e-002	3.34163
121.83097	10.18000	-8.395263e-002	3.34134
122.03098	10.20000	-8.518860e-002	3.34106
122.23102	10.22000	-8.614956e-002	3.34078
122.43093	10.24000	-8.731500e-002	3.34049
122.63098	10.26000	-8.842296e-002	3.34020
122.83102	10.28000	-8.944339e-002	3.33992
123.03113	10.30000	-9.060100e-002	3.33963
123.23108	10.32000	-9.162241e-002	3.33934
123.43107	10.34000	-9.267366e-002	3.33905
123.63100	10.36000	-9.366660e-002	3.33876
123.83093	10.38000	-9.442564e-002	3.33847
124.03098	10.40000	-9.548077e-002	3.33818
124.23102	10.42000	-9.640783e-002	3.33788
124.43095	10.44000	-9.739167e-002	3.33759
124.63077	10.46000	-9.802867e-002	3.33730
124.83067	10.48000	-9.898476e-002	3.33700
125.03049	10.50000	-9.974055e-002	3.33671
125.23046	10.52000	      -0.10075	3.33641
125.43038	10.54000	      -0.10167	3.33611
125.63015	10.56000	      -0.10247	3.33582
125.83008	10.58000	      -0.10316	3.33552
126.02982	10.60000	      -0.10383	3.33522
126.22972	10.62000	      -0.10453	3.33492
126.42969	10.64000	      -0.10511	3.33462
126.62984	10.66000	      -0.10587	3.33432
126.82993	10.68000	      -0.10668	3.33401
127.03011	10.70000	      -0.10780	3.33371
127.23018	10.72000	      -0.10894	3.33340
127.43026	10.74000	      -0.10961	3.33310
127.63039	10.76000	      -0.11023	3.33279
127.83057	10.78000	      -0.11131	3.33249
128.03075	10.80000	      -0.11213	3.33218
128.23079	10.82000	      -0.11297	3.33187
128.43080	10.84000	      -0.11386	3.33156
128.63079	10.86000	      -0.11470	3.33125
128.83077	10.88000	      -0.11545	3.33094
129.03077	10.90000	      -0.11664	3.33063
129.23079	10.92000	      -0.11755	3.33032
129.43067	10.94000	      -0.11860	3.33001
129.63062	10.96000	      -0.11960	3.32970
129.83064	10.98000	      -0.12069	3.32938
130.03072	11.00000	      -0.12184	3.32907
130.23074	11.02000	      -0.12311	3.32875
130.43074	11.04000	      -0.12459	3.32843
130.63056	11.06000	      -0.12568	3.32812
130.83043	11.08000	      -0.12722	3.32780
131.03039	11.10000	      -0.12872	3.32748
131.23048	11.12000	      -0.12976	3.32716
131.43064	11.14000	      -0.13150	3.32684
131.63066	11.16000	      -0.13275	3.32652
131.83061	11.18000	      -0.13420	3.32620
132.03054	11.20000	      -0.13595	3.32588
132.23048	11.22000	      -0.13760	3.32556
132.43048	11.24000	      -0.13919	3.32523
132.63054	11.26000	      -0.14111	3.32491
132.83062	11.28000	      -0.14270	3.32458
133.03069	11.30000	      -0.14441	3.32426
133.23048	11.32000	      -0.14623	3.32393
133.43046	11.34000	      -0.14803	3.32360
133.63043	11.36000	      -0.14985	3.32327
133.83047	11.38000	      -0.15153	3.32295
134.03051	11.40000	      -0.15362	3.32262
134.23061	11.42000	      -0.15561	3.32229
134.43062	11.44000	      -0.15792	3.32195
134.63072	11.46000	      -0.15970	3.32162
134.83085	11.48000	      -0.16190	3.32129
135.03093	11.50000	      -0.16417	3.32096
135.23105	11.52000	      -0.16621	3.32062
135.43113	11.54000	      -0.16855	3.32029
135.63123	11.56000	      -0.17081	3.31995
135.83131	11.58000	      -0.17288	3.31962
136.03139	11.60000	      -0.17539	3.31928
136.23152	11.62000	      -0.17781	3.31894
136.43166	11.64000	      -0.18003	3.31860
136.63159	11.66000	      -0.18245	3.31826
136.83161	11.68000	      -0.18490	3.31792
137.03152	11.70000	      -0.18741	3.31758
137.23143	11.72000	      -0.18979	3.31724
137.43121	11.74000	      -0.19192	3.31690
137.63098	11.76000	      -0.19463	3.31656
137.83084	11.78000	      -0.19705	3.31622
138.03066	11.80000	      -0.19953	3.31587
138.23048	11.82000	      -0.20218	3.31553
138.43034	11.84000	      -0.20470	3.31518
138.63049	11.86000	      -0.20699	3.31484
138.83057	11.88000	      -0.20925	3.31449
139.03062	11.90000	      -0.21156	3.31414
139.23067	11.92000	      -0.21397	3.31379
139.43092	11.94000	      -0.21630	3.31344
139.63115	11.96000	      -0.21812	3.31309
139.83130	11.98000	      -0.22053	3.31274
140.03136	12.00000	      -0.22277	3.31239
140.23139	12.02000	      -0.22513	3.31204
140.43154	12.04000	      -0.22673	3.31169
140.63146	12.06000	      -0.22856	3.31134
140.83135	12.08000	      -0.23030	3.31098
141.03130	12.10000	      -0.23172	3.31063
141.23123	12.12000	      -0.23350	3.31027
141.43100	12.14000	      -0.23445	3.30992
141.63082	12.16000	      -0.23600	3.30956
141.83064	12.18000	      -0.23725	3.30920
142.03051	12.20000	      -0.23799	3.30885
142.23064	12.22000	      -0.23902	3.30849
142.43074	12.24000	      -0.23971	3.30813
142.63079	12.26000	      -0.24047	3.30777
142.83102	12.28000	      -0.24131	3.30741
143.03112	12.30000	      -0.24195	3.30704
143.23123	12.32000	      -0.24247	3.30668
143.43139	12.34000	      -0.24287	3.30632
143.63157	12.36000	      -0.24283	3.30595
143.83169	12.38000	      -0.24297	3.30559
144.03192	12.40000	      -0.24317	3.30522
144.23200	12.42000	      -0.24335	3.30486
144.43192	12.44000	      -0.24308	3.30449
144.63190	12.46000	      -0.24284	3.30412
144.83179	12.48000	      -0.24246	3.30376
145.03169	12.50000	      -0.24237	3.30339
145.23156	12.52000	      -0.24230	3.30302
145.43159	12.54000	      -0.24182	3.30265
145.63153	12.56000	      -0.24154	3.30228
145.83144	12.58000	      -0.24112	3.30191
146.03136	12.60000	      -0.24088	3.30154
146.23107	12.62000	      -0.24037	3.30117
146.43095	12.64000	      -0.23981	3.30079
146.63085	12.66000	      -0.23940	3.30042
146.83067	12.68000	      -0.23892	3.30005
147.03061	12.70000	      -0.23818	3.29967
147.23054	12.72000	      -0.23784	3.29929
147.43054	12.74000	      -0.23755	3.29892
147.63051	12.76000	      -0.23685	3.29854
147.83049	12.78000	      -0.23639	3.29816
148.03046	12.80000	      -0.23574	3.29778
148.23062	12.82000	      -0.23550	3.29740
148.43075	12.84000	      -0.23544	3.29702
148.63087	12.86000	      -0.23494	3.29664
148.83108	12.88000	      -0.23446	3.29626
149.03117	12.90000	      -0.23390	3.29588
149.23121	12.92000	      -0.23319	3.29550
149.43146	12.94000	      -0.23255	3.29511
149.63174	12.96000	      -0.23259	3.29473
149.83182	12.98000	      -0.23198	3.29435
149.93140	12.99000	      -0.23166	3.29415