File: data/ExpDat_SK_Mix_resin_entalp75kpm_20-150.txt
#EXPORTTYPE:                 	DATA SINGLE
#FILE:                       	SK_Mix_resin_entalp75kpm_20-150.ngb-sdg
#FORMAT:                     	NETZSCH5
#FTYPE:                      	ASCII
#IDENTITY:                   	SK_epoxy
#DECIMAL:                    	POINT
#SEPARATOR:                  	TAB
#MTYPE:                      	DSC
#INSTRUMENT:                 	NETZSCH DSC 214
#PROJECT:                    	?ø?†??-Ø
#DATE/TIME:                  	12.09.2019 20:53:40 (UTC+3)
#CORR. FILE:
#TEMPCAL:                    	applied
#SENSITIVITY:                	applied
#LABORATORY:                 	CISIS
#OPERATOR:                   	Nasonov
#REMARK:
#SAMPLE:                     	20190907_1083-G290S -0-
#SAMPLE MASS /mg:            	9.12
#MATERIAL:
#REFERENCE:
#REFERENCE MASS /mg:         	0
#TYPE OF CRUCIBLE:           	Concavus Pan Al, pierced lid
#SAMPLE CRUCIBLE MASS /mg:   	0
#REFERENCE CRUCIBLE MASS /mg:	0
#M.RANGE /ßV:                	5000
#TAU-R:                      	---
#CORR. CODE:                 	009
#EXO:                        	+1
#RANGE:                      	20ËC/7.5(K/min)/150ËC
#SEGMENT:                    	S1/1
#SEG. 1:                     	20ËC/7.5(K/min)/150ËC

##Temp./ËC	Time/min	DSC/(mW/mg)	Sensit./(uV/mW)
 20.07100	 0.00000	 2.965977e-002	3.36739
 20.06833	 0.02000	 3.003087e-002	3.36739
 20.08965	 0.04000	 2.871651e-002	3.36741
 20.15492	 0.06000	 1.544244e-002	3.36748
 20.26224	 0.08000	-1.254509e-002	3.36759
 20.40441	 0.10000	-5.072572e-002	3.36773
 20.57388	 0.12000	-9.455272e-002	3.36791
 20.74973	 0.14000	      -0.14130	3.36809
 20.90502	 0.16000	      -0.18840	3.36825
 21.07696	 0.18000	      -0.23358	3.36842
 21.26362	 0.20000	      -0.27526	3.36861
 21.46145	 0.22000	      -0.31162	3.36881
 21.66716	 0.24000	      -0.34244	3.36902
 21.87782	 0.26000	      -0.36699	3.36923
 22.09029	 0.28000	      -0.38518	3.36944
 22.30191	 0.30000	      -0.39690	3.36964
 22.51093	 0.32000	      -0.40322	3.36985
 22.71518	 0.34000	      -0.40375	3.37005
 22.91329	 0.36000	      -0.39995	3.37024
 23.10422	 0.38000	      -0.39229	3.37042
 23.28756	 0.40000	      -0.38161	3.37060
 23.46309	 0.42000	      -0.36854	3.37076
 23.63084	 0.44000	      -0.35405	3.37092
 23.79102	 0.46000	      -0.33911	3.37107
 23.94431	 0.48000	      -0.32411	3.37122
 24.09144	 0.50000	      -0.30954	3.37135
 24.23322	 0.52000	      -0.29585	3.37149
 24.37042	 0.54000	      -0.28346	3.37161
 24.50411	 0.56000	      -0.27231	3.37174
 24.63505	 0.58000	      -0.26261	3.37186
 24.76402	 0.60000	      -0.25479	3.37197
 24.89185	 0.62000	      -0.24873	3.37209
 25.01942	 0.64000	      -0.24432	3.37221
 25.14733	 0.66000	      -0.24132	3.37232
 25.27589	 0.68000	      -0.24001	3.37244
 25.40567	 0.70000	      -0.24011	3.37255
 25.53705	 0.72000	      -0.24108	3.37267
 25.67011	 0.74000	      -0.24304	3.37279
 25.80502	 0.76000	      -0.24584	3.37291
 25.94178	 0.78000	      -0.24931	3.37303
 26.08056	 0.80000	      -0.25289	3.37315
 26.22113	 0.82000	      -0.25650	3.37327
 26.36333	 0.84000	      -0.26037	3.37340
 26.50729	 0.86000	      -0.26424	3.37352
 26.65280	 0.88000	      -0.26786	3.37365
 26.79953	 0.90000	      -0.27119	3.37378
 26.94720	 0.92000	      -0.27433	3.37390
 27.09575	 0.94000	      -0.27707	3.37403
 27.24504	 0.96000	      -0.27966	3.37415
 27.39493	 0.98000	      -0.28160	3.37428
 27.54509	 1.00000	      -0.28334	3.37441
 27.69547	 1.02000	      -0.28474	3.37453
 27.84593	 1.04000	      -0.28564	3.37466
 27.99633	 1.06000	      -0.28639	3.37478
 28.14662	 1.08000	      -0.28736	3.37491
 28.29680	 1.10000	      -0.28746	3.37503
 28.44696	 1.12000	      -0.28771	3.37515
 28.59680	 1.14000	      -0.28804	3.37527
 28.74638	 1.16000	      -0.28805	3.37539
 28.89596	 1.18000	      -0.28788	3.37551
 29.04525	 1.20000	      -0.28784	3.37563
 29.19442	 1.22000	      -0.28765	3.37575
 29.34347	 1.24000	      -0.28749	3.37587
 29.49238	 1.26000	      -0.28758	3.37599
 29.64120	 1.28000	      -0.28762	3.37610
 29.78996	 1.30000	      -0.28751	3.37622
 29.93871	 1.32000	      -0.28767	3.37633
 30.08751	 1.34000	      -0.28795	3.37645
 30.23636	 1.36000	      -0.28801	3.37656
 30.38524	 1.38000	      -0.28844	3.37667
 30.53407	 1.40000	      -0.28855	3.37679
 30.68309	 1.42000	      -0.28881	3.37690
 30.83213	 1.44000	      -0.28907	3.37701
 30.98122	 1.46000	      -0.28968	3.37712
 31.13047	 1.48000	      -0.28991	3.37723
 31.27962	 1.50000	      -0.29041	3.37734
 31.42893	 1.52000	      -0.29067	3.37745
 31.57829	 1.54000	      -0.29085	3.37756
 31.72776	 1.56000	      -0.29133	3.37767
 31.87731	 1.58000	      -0.29178	3.37778
 32.02698	 1.60000	      -0.29233	3.37789
 32.17667	 1.62000	      -0.29279	3.37799
 32.32644	 1.64000	      -0.29346	3.37810
 32.47631	 1.66000	      -0.29372	3.37820
 32.62624	 1.68000	      -0.29410	3.37831
 32.77613	 1.70000	      -0.29452	3.37841
 32.92605	 1.72000	      -0.29505	3.37852
 33.07607	 1.74000	      -0.29564	3.37862
 33.22609	 1.76000	      -0.29572	3.37872
 33.37615	 1.78000	      -0.29582	3.37883
 33.52611	 1.80000	      -0.29613	3.37893
 33.67611	 1.82000	      -0.29658	3.37903
 33.82620	 1.84000	      -0.29681	3.37913
 33.97618	 1.86000	      -0.29694	3.37923
 34.12613	 1.88000	      -0.29698	3.37933
 34.27609	 1.90000	      -0.29735	3.37943
 34.42602	 1.92000	      -0.29734	3.37952
 34.57591	 1.94000	      -0.29765	3.37962
 34.72587	 1.96000	      -0.29756	3.37972
 34.87585	 1.98000	      -0.29802	3.37981
 35.02587	 2.00000	      -0.29803	3.37991
 35.17587	 2.02000	      -0.29820	3.38001
 35.32589	 2.04000	      -0.29858	3.38010
 35.47587	 2.06000	      -0.29905	3.38019
 35.62604	 2.08000	      -0.29935	3.38029
 35.77620	 2.10000	      -0.29977	3.38038
 35.92625	 2.12000	      -0.30015	3.38047
 36.07640	 2.14000	      -0.30056	3.38056
 36.22655	 2.16000	      -0.30077	3.38065
 36.37673	 2.18000	      -0.30115	3.38074
 36.52689	 2.20000	      -0.30139	3.38083
 36.67682	 2.22000	      -0.30172	3.38092
 36.82676	 2.24000	      -0.30203	3.38101
 36.97676	 2.26000	      -0.30204	3.38110
 37.12675	 2.28000	      -0.30256	3.38118
 37.27671	 2.30000	      -0.30285	3.38127
 37.42667	 2.32000	      -0.30320	3.38136
 37.57678	 2.34000	      -0.30347	3.38144
 37.72676	 2.36000	      -0.30391	3.38153
 37.87665	 2.38000	      -0.30418	3.38161
 38.02653	 2.40000	      -0.30453	3.38169
 38.17651	 2.42000	      -0.30498	3.38178
 38.32660	 2.44000	      -0.30566	3.38186
 38.47658	 2.46000	      -0.30571	3.38194
 38.62658	 2.48000	      -0.30606	3.38202
 38.77665	 2.50000	      -0.30639	3.38210
 38.92682	 2.52000	      -0.30679	3.38218
 39.07685	 2.54000	      -0.30723	3.38226
 39.22695	 2.56000	      -0.30769	3.38234
 39.37711	 2.58000	      -0.30790	3.38242
 39.52718	 2.60000	      -0.30796	3.38250
 39.67724	 2.62000	      -0.30846	3.38257
 39.82724	 2.64000	      -0.30862	3.38265
 39.97745	 2.66000	      -0.30888	3.38273
 40.12767	 2.68000	      -0.30908	3.38280
 40.27780	 2.70000	      -0.30946	3.38287
 40.42795	 2.72000	      -0.30974	3.38295
 40.57818	 2.74000	      -0.30989	3.38302
 40.72844	 2.76000	      -0.30990	3.38309
 40.87869	 2.78000	      -0.31008	3.38317
 41.02885	 2.80000	      -0.31042	3.38324
 41.17909	 2.82000	      -0.31055	3.38331
 41.32931	 2.84000	      -0.31093	3.38338
 41.47945	 2.86000	      -0.31165	3.38345
 41.62964	 2.88000	      -0.31171	3.38352
 41.77982	 2.90000	      -0.31226	3.38359
 41.92989	 2.92000	      -0.31236	3.38366
 42.07996	 2.94000	      -0.31254	3.38372
 42.23002	 2.96000	      -0.31256	3.38379
 42.38007	 2.98000	      -0.31280	3.38386
 42.52996	 3.00000	      -0.31290	3.38392
 42.67985	 3.02000	      -0.31324	3.38399
 42.82964	 3.04000	      -0.31346	3.38405
 42.97945	 3.06000	      -0.31368	3.38411
 43.12940	 3.08000	      -0.31428	3.38418
 43.27935	 3.10000	      -0.31463	3.38424
 43.42920	 3.12000	      -0.31492	3.38430
 43.57909	 3.14000	      -0.31515	3.38436
 43.72896	 3.16000	      -0.31556	3.38442
 43.87895	 3.18000	      -0.31599	3.38448
 44.02900	 3.20000	      -0.31644	3.38454
 44.17905	 3.22000	      -0.31683	3.38460
 44.32904	 3.24000	      -0.31713	3.38466
 44.47915	 3.26000	      -0.31738	3.38472
 44.62940	 3.28000	      -0.31760	3.38478
 44.77962	 3.30000	      -0.31802	3.38483
 44.92982	 3.32000	      -0.31829	3.38489
 45.08002	 3.34000	      -0.31856	3.38494
 45.23013	 3.36000	      -0.31887	3.38500
 45.38027	 3.38000	      -0.31911	3.38505
 45.53045	 3.40000	      -0.31927	3.38511
 45.68053	 3.42000	      -0.31953	3.38516
 45.83058	 3.44000	      -0.31963	3.38521
 45.98067	 3.46000	      -0.31957	3.38527
 46.13075	 3.48000	      -0.32007	3.38532
 46.28078	 3.50000	      -0.32037	3.38537
 46.43075	 3.52000	      -0.32033	3.38542
 46.58064	 3.54000	      -0.32076	3.38547
 46.73055	 3.56000	      -0.32108	3.38552
 46.88058	 3.58000	      -0.32126	3.38556
 47.03056	 3.60000	      -0.32147	3.38561
 47.18056	 3.62000	      -0.32186	3.38566
 47.33056	 3.64000	      -0.32217	3.38571
 47.48055	 3.66000	      -0.32245	3.38575
 47.63060	 3.68000	      -0.32293	3.38580
 47.78069	 3.70000	      -0.32324	3.38584
 47.93069	 3.72000	      -0.32350	3.38589
 48.08078	 3.74000	      -0.32377	3.38593
 48.23084	 3.76000	      -0.32384	3.38597
 48.38105	 3.78000	      -0.32408	3.38602
 48.53116	 3.80000	      -0.32454	3.38606
 48.68122	 3.82000	      -0.32483	3.38610
 48.83151	 3.84000	      -0.32521	3.38614
 48.98182	 3.86000	      -0.32516	3.38618
 49.13207	 3.88000	      -0.32540	3.38622
 49.28227	 3.90000	      -0.32551	3.38626
 49.43242	 3.92000	      -0.32568	3.38630
 49.58249	 3.94000	      -0.32603	3.38633
 49.73256	 3.96000	      -0.32645	3.38637
 49.88264	 3.98000	      -0.32685	3.38641
 50.03267	 4.00000	      -0.32690	3.38644
 50.18267	 4.02000	      -0.32689	3.38648
 50.33262	 4.04000	      -0.32723	3.38651
 50.48260	 4.06000	      -0.32750	3.38655
 50.63269	 4.08000	      -0.32749	3.38658
 50.78262	 4.10000	      -0.32793	3.38662
 50.93247	 4.12000	      -0.32809	3.38665
 51.08220	 4.14000	      -0.32848	3.38668
 51.23220	 4.16000	      -0.32892	3.38671
 51.38220	 4.18000	      -0.32934	3.38674
 51.53216	 4.20000	      -0.32943	3.38677
 51.68218	 4.22000	      -0.32982	3.38680
 51.83220	 4.24000	      -0.33001	3.38683
 51.98220	 4.26000	      -0.33020	3.38686
 52.13216	 4.28000	      -0.33071	3.38689
 52.28216	 4.30000	      -0.33118	3.38691
 52.43231	 4.32000	      -0.33129	3.38694
 52.58222	 4.34000	      -0.33157	3.38697
 52.73218	 4.36000	      -0.33157	3.38699
 52.88211	 4.38000	      -0.33227	3.38702
 53.03196	 4.40000	      -0.33250	3.38704
 53.18195	 4.42000	      -0.33274	3.38707
 53.33171	 4.44000	      -0.33317	3.38709
 53.48162	 4.46000	      -0.33324	3.38711
 53.63156	 4.48000	      -0.33355	3.38713
 53.78144	 4.50000	      -0.33382	3.38716
 53.93142	 4.52000	      -0.33411	3.38718
 54.08140	 4.54000	      -0.33445	3.38720
 54.23140	 4.56000	      -0.33507	3.38722
 54.38138	 4.58000	      -0.33527	3.38724
 54.53129	 4.60000	      -0.33522	3.38725
 54.68142	 4.62000	      -0.33552	3.38727
 54.83144	 4.64000	      -0.33603	3.38729
 54.98160	 4.66000	      -0.33638	3.38731
 55.13184	 4.68000	      -0.33671	3.38732
 55.28196	 4.70000	      -0.33703	3.38734
 55.43218	 4.72000	      -0.33706	3.38735
 55.58242	 4.74000	      -0.33741	3.38737
 55.73271	 4.76000	      -0.33776	3.38738
 55.88304	 4.78000	      -0.33788	3.38740
 56.03331	 4.80000	      -0.33827	3.38741
 56.18347	 4.82000	      -0.33863	3.38742
 56.33364	 4.84000	      -0.33899	3.38743
 56.48375	 4.86000	      -0.33907	3.38744
 56.63380	 4.88000	      -0.33928	3.38745
 56.78391	 4.90000	      -0.33949	3.38746
 56.93395	 4.92000	      -0.33951	3.38747
 57.08393	 4.94000	      -0.33962	3.38748
 57.23395	 4.96000	      -0.33982	3.38749
 57.38411	 4.98000	      -0.33998	3.38750
 57.53415	 5.00000	      -0.34009	3.38751
 57.68433	 5.02000	      -0.34062	3.38751
 57.83438	 5.04000	      -0.34105	3.38752
 57.98415	 5.06000	      -0.34111	3.38752
 58.13391	 5.08000	      -0.34127	3.38753
 58.28375	 5.10000	      -0.34149	3.38753
 58.43378	 5.12000	      -0.34191	3.38754
 58.58369	 5.14000	      -0.34192	3.38754
 58.73365	 5.16000	      -0.34187	3.38754
 58.88373	 5.18000	      -0.34224	3.38754
 59.03385	 5.20000	      -0.34214	3.38754
 59.18405	 5.22000	      -0.34252	3.38755
 59.33413	 5.24000	      -0.34284	3.38755
 59.48404	 5.26000	      -0.34325	3.38755
 59.63391	 5.28000	      -0.34365	3.38754
 59.78365	 5.30000	      -0.34381	3.38754
 59.93353	 5.32000	      -0.34424	3.38754
 60.08360	 5.34000	      -0.34453	3.38754
 60.23376	 5.36000	      -0.34457	3.38753
 60.38387	 5.38000	      -0.34480	3.38753
 60.53396	 5.40000	      -0.34484	3.38753
 60.68415	 5.42000	      -0.34517	3.38752
 60.83427	 5.44000	      -0.34525	3.38752
 60.98411	 5.46000	      -0.34551	3.38751
 61.13387	 5.48000	      -0.34577	3.38750
 61.28360	 5.50000	      -0.34603	3.38750
 61.43333	 5.52000	      -0.34634	3.38749
 61.58316	 5.54000	      -0.34655	3.38748
 61.73313	 5.56000	      -0.34657	3.38747
 61.88293	 5.58000	      -0.34702	3.38746
 62.03295	 5.60000	      -0.34704	3.38745
 62.18287	 5.62000	      -0.34737	3.38744
 62.33291	 5.64000	      -0.34765	3.38743
 62.48302	 5.66000	      -0.34818	3.38742
 62.63300	 5.68000	      -0.34841	3.38741
 62.78296	 5.70000	      -0.34870	3.38739
 62.93295	 5.72000	      -0.34900	3.38738
 63.08313	 5.74000	      -0.34939	3.38737
 63.23335	 5.76000	      -0.34953	3.38735
 63.38356	 5.78000	      -0.34970	3.38734
 63.53376	 5.80000	      -0.34997	3.38732
 63.68389	 5.82000	      -0.35014	3.38730
 63.83404	 5.84000	      -0.35021	3.38729
 63.98422	 5.86000	      -0.35050	3.38727
 64.13436	 5.88000	      -0.35072	3.38725
 64.28442	 5.90000	      -0.35087	3.38723
 64.43442	 5.92000	      -0.35111	3.38721
 64.58438	 5.94000	      -0.35111	3.38720
 64.73451	 5.96000	      -0.35133	3.38717
 64.88458	 5.98000	      -0.35148	3.38715
 65.03478	 6.00000	      -0.35181	3.38713
 65.18487	 6.02000	      -0.35203	3.38711
 65.33500	 6.04000	      -0.35212	3.38709
 65.48515	 6.06000	      -0.35232	3.38707
 65.63527	 6.08000	      -0.35254	3.38704
 65.78529	 6.10000	      -0.35291	3.38702
 65.93544	 6.12000	      -0.35313	3.38699
 66.08549	 6.14000	      -0.35308	3.38697
 66.23556	 6.16000	      -0.35325	3.38694
 66.38560	 6.18000	      -0.35309	3.38692
 66.53555	 6.20000	      -0.35312	3.38689
 66.68545	 6.22000	      -0.35334	3.38686
 66.83535	 6.24000	      -0.35350	3.38683
 66.98529	 6.26000	      -0.35348	3.38680
 67.13516	 6.28000	      -0.35370	3.38678
 67.28505	 6.30000	      -0.35369	3.38675
 67.43489	 6.32000	      -0.35374	3.38672
 67.58460	 6.34000	      -0.35382	3.38669
 67.73433	 6.36000	      -0.35396	3.38665
 67.88415	 6.38000	      -0.35438	3.38662
 68.03382	 6.40000	      -0.35442	3.38659
 68.18356	 6.42000	      -0.35471	3.38656
 68.33349	 6.44000	      -0.35485	3.38652
 68.48344	 6.46000	      -0.35475	3.38649
 68.63340	 6.48000	      -0.35509	3.38645
 68.78344	 6.50000	      -0.35525	3.38642
 68.93351	 6.52000	      -0.35542	3.38638
 69.08344	 6.54000	      -0.35565	3.38635
 69.23345	 6.56000	      -0.35587	3.38631
 69.38367	 6.58000	      -0.35612	3.38627
 69.53382	 6.60000	      -0.35615	3.38623
 69.68407	 6.62000	      -0.35622	3.38620
 69.83429	 6.64000	      -0.35635	3.38616
 69.98451	 6.66000	      -0.35620	3.38612
 70.13475	 6.68000	      -0.35618	3.38608
 70.28493	 6.70000	      -0.35607	3.38604
 70.43500	 6.72000	      -0.35610	3.38599
 70.58509	 6.74000	      -0.35606	3.38595
 70.73513	 6.76000	      -0.35584	3.38591
 70.88505	 6.78000	      -0.35580	3.38587
 71.03493	 6.80000	      -0.35582	3.38582
 71.18495	 6.82000	      -0.35590	3.38578
 71.33484	 6.84000	      -0.35603	3.38574
 71.48473	 6.86000	      -0.35611	3.38569
 71.63476	 6.88000	      -0.35607	3.38564
 71.78478	 6.90000	      -0.35623	3.38560
 71.93482	 6.92000	      -0.35624	3.38555
 72.08489	 6.94000	      -0.35634	3.38550
 72.23498	 6.96000	      -0.35645	3.38546
 72.38504	 6.98000	      -0.35661	3.38541
 72.53509	 7.00000	      -0.35677	3.38536
 72.68518	 7.02000	      -0.35678	3.38531
 72.83524	 7.04000	      -0.35687	3.38526
 72.98527	 7.06000	      -0.35681	3.38521
 73.13529	 7.08000	      -0.35681	3.38516
 73.28525	 7.10000	      -0.35681	3.38510
 73.43522	 7.12000	      -0.35689	3.38505
 73.58513	 7.14000	      -0.35672	3.38500
 73.73513	 7.16000	      -0.35658	3.38495
 73.88504	 7.18000	      -0.35656	3.38489
 74.03498	 7.20000	      -0.35652	3.38484
 74.18495	 7.22000	      -0.35654	3.38478
 74.33487	 7.24000	      -0.35643	3.38473
 74.48484	 7.26000	      -0.35635	3.38467
 74.63484	 7.28000	      -0.35622	3.38461
 74.78489	 7.30000	      -0.35609	3.38456
 74.93500	 7.32000	      -0.35586	3.38450
 75.08507	 7.34000	      -0.35551	3.38444
 75.23520	 7.36000	      -0.35516	3.38438
 75.38529	 7.38000	      -0.35470	3.38432
 75.53527	 7.40000	      -0.35429	3.38426
 75.68527	 7.42000	      -0.35402	3.38420
 75.83529	 7.44000	      -0.35355	3.38414
 75.98531	 7.46000	      -0.35292	3.38408
 76.13535	 7.48000	      -0.35252	3.38402
 76.28545	 7.50000	      -0.35182	3.38396
 76.43545	 7.52000	      -0.35107	3.38389
 76.58542	 7.54000	      -0.35000	3.38383
 76.73536	 7.56000	      -0.34925	3.38376
 76.88524	 7.58000	      -0.34867	3.38370
 77.03518	 7.60000	      -0.34761	3.38363
 77.18522	 7.62000	      -0.34689	3.38357
 77.33533	 7.64000	      -0.34561	3.38350
 77.48549	 7.66000	      -0.34465	3.38343
 77.63551	 7.68000	      -0.34357	3.38337
 77.78555	 7.70000	      -0.34258	3.38330
 77.93555	 7.72000	      -0.34169	3.38323
 78.08549	 7.74000	      -0.34035	3.38316
 78.23551	 7.76000	      -0.33924	3.38309
 78.38542	 7.78000	      -0.33789	3.38302
 78.53545	 7.80000	      -0.33643	3.38295
 78.68551	 7.82000	      -0.33490	3.38288
 78.83549	 7.84000	      -0.33355	3.38281
 78.98547	 7.86000	      -0.33207	3.38274
 79.13538	 7.88000	      -0.33059	3.38266
 79.28525	 7.90000	      -0.32883	3.38259
 79.43511	 7.92000	      -0.32702	3.38252
 79.58496	 7.94000	      -0.32504	3.38244
 79.73496	 7.96000	      -0.32303	3.38237
 79.88498	 7.98000	      -0.32098	3.38229
 80.03509	 8.00000	      -0.31891	3.38221
 80.18513	 8.02000	      -0.31688	3.38214
 80.33509	 8.04000	      -0.31480	3.38206
 80.48511	 8.06000	      -0.31275	3.38198
 80.63515	 8.08000	      -0.31062	3.38190
 80.78525	 8.10000	      -0.30827	3.38183
 80.93536	 8.12000	      -0.30577	3.38175
 81.08547	 8.14000	      -0.30313	3.38167
 81.23564	 8.16000	      -0.30053	3.38159
 81.38571	 8.18000	      -0.29811	3.38151
 81.53575	 8.20000	      -0.29517	3.38142
 81.68591	 8.22000	      -0.29253	3.38134
 81.83598	 8.24000	      -0.28942	3.38126
 81.98600	 8.26000	      -0.28635	3.38118
 82.13609	 8.28000	      -0.28310	3.38109
 82.28620	 8.30000	      -0.27999	3.38101
 82.43638	 8.32000	      -0.27656	3.38092
 82.58642	 8.34000	      -0.27291	3.38084
 82.73640	 8.36000	      -0.26931	3.38075
 82.88636	 8.38000	      -0.26570	3.38067
 83.03636	 8.40000	      -0.26197	3.38058
 83.18636	 8.42000	      -0.25788	3.38049
 83.33635	 8.44000	      -0.25384	3.38041
 83.48647	 8.46000	      -0.24972	3.38032
 83.63649	 8.48000	      -0.24516	3.38023
 83.78649	 8.50000	      -0.24067	3.38014
 83.93645	 8.52000	      -0.23631	3.38005
 84.08638	 8.54000	      -0.23176	3.37996
 84.23627	 8.56000	      -0.22683	3.37987
 84.38609	 8.58000	      -0.22182	3.37978
 84.53596	 8.60000	      -0.21655	3.37968
 84.68585	 8.62000	      -0.21132	3.37959
 84.83578	 8.64000	      -0.20594	3.37950
 84.98580	 8.66000	      -0.20019	3.37941
 85.13585	 8.68000	      -0.19429	3.37931
 85.28613	 8.70000	      -0.18819	3.37922
 85.43624	 8.72000	      -0.18192	3.37912
 85.58642	 8.74000	      -0.17528	3.37903
 85.73664	 8.76000	      -0.16868	3.37893
 85.88680	 8.78000	      -0.16149	3.37883
 86.03696	 8.80000	      -0.15435	3.37874
 86.18716	 8.82000	      -0.14687	3.37864
 86.33735	 8.84000	      -0.13884	3.37854
 86.48749	 8.86000	      -0.13062	3.37844
 86.63760	 8.88000	      -0.12222	3.37834
 86.78767	 8.90000	      -0.11313	3.37824
 86.93778	 8.92000	      -0.10386	3.37814
 87.08780	 8.94000	-9.428209e-002	3.37804
 87.23778	 8.96000	-8.421741e-002	3.37794
 87.38749	 8.98000	-7.373141e-002	3.37784
 87.53725	 9.00000	-6.260021e-002	3.37773
 87.68696	 9.02000	-5.124607e-002	3.37763
 87.83675	 9.04000	-3.929650e-002	3.37753
 87.98656	 9.06000	-2.672698e-002	3.37742
 88.13642	 9.08000	-1.366116e-002	3.37732
 88.28629	 9.10000	-2.267528e-005	3.37722
 88.43627	 9.12000	 1.453321e-002	3.37711
 88.58627	 9.14000	 2.983350e-002	3.37700
 88.73635	 9.16000	 4.555590e-002	3.37690
 88.88645	 9.18000	 6.214705e-002	3.37679
 89.03644	 9.20000	 7.952383e-002	3.37668
 89.18645	 9.22000	 9.794325e-002	3.37657
 89.33653	 9.24000	       0.11693	3.37647
 89.48669	 9.26000	       0.13707	3.37636
 89.63678	 9.28000	       0.15839	3.37625
 89.78682	 9.30000	       0.18090	3.37614
 89.93667	 9.32000	       0.20421	3.37603
 90.08653	 9.34000	       0.22915	3.37592
 90.23647	 9.36000	       0.25528	3.37580
 90.38631	 9.38000	       0.28268	3.37569
 90.53607	 9.40000	       0.31104	3.37558
 90.68598	 9.42000	       0.34186	3.37547
 90.83580	 9.44000	       0.37315	3.37535
 90.98575	 9.46000	       0.40638	3.37524
 91.13578	 9.48000	       0.44115	3.37512
 91.28585	 9.50000	       0.47696	3.37501
 91.43600	 9.52000	       0.51575	3.37489
 91.58620	 9.54000	       0.55558	3.37478
 91.73640	 9.56000	       0.59701	3.37466
 91.88682	 9.58000	       0.64049	3.37454
 92.03725	 9.60000	       0.68636	3.37442
 92.18773	 9.62000	       0.73344	3.37430
 92.33815	 9.64000	       0.78250	3.37418
 92.48853	 9.66000	       0.83330	3.37407
 92.63895	 9.68000	       0.88613	3.37394
 92.78920	 9.70000	       0.94103	3.37382
 92.93944	 9.72000	       0.99668	3.37370
 93.08962	 9.74000	       1.05372	3.37358
 93.23975	 9.76000	       1.11391	3.37346
 93.38978	 9.78000	       1.17329	3.37334
 93.53964	 9.80000	       1.23329	3.37321
 93.68958	 9.82000	       1.29468	3.37309
 93.83949	 9.84000	       1.35558	3.37297
 93.98933	 9.86000	       1.41646	3.37284
 94.13916	 9.88000	       1.47693	3.37272
 94.28902	 9.90000	       1.53581	3.37259
 94.43884	 9.92000	       1.59351	3.37247
 94.58873	 9.94000	       1.64930	3.37234
 94.73858	 9.96000	       1.70244	3.37221
 94.88853	 9.98000	       1.75276	3.37209
 95.03844	10.00000	       1.79993	3.37196
 95.18827	10.02000	       1.84288	3.37183
 95.33807	10.04000	       1.88158	3.37170
 95.48802	10.06000	       1.91595	3.37157
 95.63796	10.08000	       1.94503	3.37144
 95.78785	10.10000	       1.96864	3.37131
 95.93764	10.12000	       1.98676	3.37118
 96.08740	10.14000	       1.99914	3.37105
 96.23722	10.16000	       2.00518	3.37092
 96.38682	10.18000	       2.00514	3.37079
 96.53635	10.20000	       1.99951	3.37065
 96.68595	10.22000	       1.98793	3.37052
 96.83555	10.24000	       1.97036	3.37039
 96.98509	10.26000	       1.94759	3.37025
 97.13465	10.28000	       1.91939	3.37012
 97.28429	10.30000	       1.88586	3.36998
 97.43395	10.32000	       1.84805	3.36985
 97.58360	10.34000	       1.80595	3.36971
 97.73320	10.36000	       1.76012	3.36957
 97.88295	10.38000	       1.71083	3.36944
 98.03285	10.40000	       1.65943	3.36930
 98.18275	10.42000	       1.60536	3.36916
 98.33260	10.44000	       1.54967	3.36902
 98.48262	10.46000	       1.49310	3.36888
 98.63273	10.48000	       1.43562	3.36874
 98.78291	10.50000	       1.37798	3.36860
 98.93304	10.52000	       1.32046	3.36846
 99.08316	10.54000	       1.26311	3.36832
 99.23331	10.56000	       1.20694	3.36818
 99.38342	10.58000	       1.15152	3.36803
 99.53358	10.60000	       1.09727	3.36789
 99.68369	10.62000	       1.04466	3.36775
 99.83384	10.64000	       0.99343	3.36760
 99.98396	10.66000	       0.94352	3.36746
100.13404	10.68000	       0.89557	3.36731
100.28411	10.70000	       0.85010	3.36717
100.43427	10.72000	       0.80523	3.36702
100.58442	10.74000	       0.76308	3.36688
100.73453	10.76000	       0.72297	3.36673
100.88458	10.78000	       0.68405	3.36658
101.03471	10.80000	       0.64648	3.36643
101.18496	10.82000	       0.61205	3.36628
101.33516	10.84000	       0.57792	3.36614
101.48535	10.86000	       0.54602	3.36599
101.63549	10.88000	       0.51576	3.36584
101.78564	10.90000	       0.48676	3.36569
101.93580	10.92000	       0.45935	3.36554
102.08585	10.94000	       0.43344	3.36538
102.23604	10.96000	       0.40867	3.36523
102.38602	10.98000	       0.38513	3.36508
102.53605	11.00000	       0.36276	3.36493
102.68607	11.02000	       0.34176	3.36477
102.83613	11.04000	       0.32158	3.36462
102.98622	11.06000	       0.30236	3.36447
103.13625	11.08000	       0.28446	3.36431
103.28627	11.10000	       0.26717	3.36416
103.43638	11.12000	       0.25083	3.36400
103.58640	11.14000	       0.23508	3.36384
103.73644	11.16000	       0.22031	3.36369
103.88644	11.18000	       0.20603	3.36353
104.03647	11.20000	       0.19254	3.36337
104.18642	11.22000	       0.17975	3.36321
104.33629	11.24000	       0.16754	3.36306
104.48635	11.26000	       0.15572	3.36290
104.63642	11.28000	       0.14432	3.36274
104.78656	11.30000	       0.13437	3.36258
104.93660	11.32000	       0.12391	3.36242
105.08673	11.34000	       0.11416	3.36226
105.23673	11.36000	       0.10496	3.36209
105.38676	11.38000	 9.590751e-002	3.36193
105.53671	11.40000	 8.737718e-002	3.36177
105.68667	11.42000	 7.924389e-002	3.36161
105.83664	11.44000	 7.160788e-002	3.36144
105.98671	11.46000	 6.421970e-002	3.36128
106.13682	11.48000	 5.697997e-002	3.36112
106.28691	11.50000	 4.988682e-002	3.36095
106.43711	11.52000	 4.324035e-002	3.36079
106.58716	11.54000	 3.679403e-002	3.36062
106.73711	11.56000	 3.086857e-002	3.36045
106.88704	11.58000	 2.506766e-002	3.36029
107.03700	11.60000	 1.944424e-002	3.36012
107.18691	11.62000	 1.397992e-002	3.35995
107.33684	11.64000	 8.889858e-003	3.35978
107.48678	11.66000	 3.798953e-003	3.35962
107.63676	11.68000	-9.192672e-004	3.35945
107.78676	11.70000	-5.562927e-003	3.35928
107.93669	11.72000	-1.043087e-002	3.35911
108.08653	11.74000	-1.484801e-002	3.35894
108.23649	11.76000	-1.893940e-002	3.35877
108.38640	11.78000	-2.313149e-002	3.35859
108.53635	11.80000	-2.712311e-002	3.35842
108.68638	11.82000	-3.116627e-002	3.35825
108.83638	11.84000	-3.488633e-002	3.35808
108.98635	11.86000	-3.833141e-002	3.35790
109.13629	11.88000	-4.178482e-002	3.35773
109.28636	11.90000	-4.541051e-002	3.35756
109.43633	11.92000	-4.851299e-002	3.35738
109.58624	11.94000	-5.166566e-002	3.35721
109.73620	11.96000	-5.471931e-002	3.35703
109.88627	11.98000	-5.774868e-002	3.35685
110.03635	12.00000	-6.060436e-002	3.35668
110.18640	12.02000	-6.346211e-002	3.35650
110.33644	12.04000	-6.622177e-002	3.35632
110.48645	12.06000	-6.898142e-002	3.35614
110.63635	12.08000	-7.124217e-002	3.35597
110.78633	12.10000	-7.387774e-002	3.35579
110.93644	12.12000	-7.651263e-002	3.35561
111.08645	12.14000	-7.893855e-002	3.35543
111.23655	12.16000	-8.124981e-002	3.35525
111.38658	12.18000	-8.346193e-002	3.35507
111.53678	12.20000	-8.535047e-002	3.35488
111.68693	12.22000	-8.773765e-002	3.35470
111.83718	12.24000	-8.990033e-002	3.35452
111.98735	12.26000	-9.203896e-002	3.35434
112.13749	12.28000	-9.397920e-002	3.35415
112.28764	12.30000	-9.582104e-002	3.35397
112.43767	12.32000	-9.776253e-002	3.35379
112.58776	12.34000	-9.967898e-002	3.35360
112.73776	12.36000	      -0.10140	3.35342
112.88762	12.38000	      -0.10344	3.35323
113.03753	12.40000	      -0.10473	3.35304
113.18747	12.42000	      -0.10631	3.35286
113.33738	12.44000	      -0.10759	3.35267
113.48731	12.46000	      -0.10939	3.35248
113.63718	12.48000	      -0.11094	3.35230
113.78702	12.50000	      -0.11252	3.35211
113.93687	12.52000	      -0.11440	3.35192
114.08665	12.54000	      -0.11600	3.35173
114.23660	12.56000	      -0.11736	3.35154
114.38653	12.58000	      -0.11883	3.35135
114.53649	12.60000	      -0.12037	3.35116
114.68653	12.62000	      -0.12183	3.35097
114.83667	12.64000	      -0.12297	3.35078
114.98689	12.66000	      -0.12432	3.35059
115.13695	12.68000	      -0.12598	3.35039
115.28698	12.70000	      -0.12708	3.35020
115.43705	12.72000	      -0.12838	3.35001
115.58718	12.74000	      -0.12970	3.34981
115.73722	12.76000	      -0.13112	3.34962
115.88724	12.78000	      -0.13229	3.34942
116.03727	12.80000	      -0.13351	3.34923
116.18727	12.82000	      -0.13505	3.34903
116.33727	12.84000	      -0.13624	3.34884
116.48731	12.86000	      -0.13759	3.34864
116.63727	12.88000	      -0.13913	3.34844
116.78720	12.90000	      -0.14042	3.34825
116.93698	12.92000	      -0.14169	3.34805
117.08676	12.94000	      -0.14319	3.34785
117.23667	12.96000	      -0.14477	3.34765
117.38656	12.98000	      -0.14616	3.34745
117.53635	13.00000	      -0.14749	3.34725
117.68620	13.02000	      -0.14903	3.34705
117.83611	13.04000	      -0.15064	3.34685
117.98596	13.06000	      -0.15250	3.34665
118.13580	13.08000	      -0.15415	3.34645
118.28565	13.10000	      -0.15607	3.34625
118.43560	13.12000	      -0.15799	3.34605
118.58560	13.14000	      -0.15998	3.34584
118.73556	13.16000	      -0.16198	3.34564
118.88564	13.18000	      -0.16420	3.34544
119.03589	13.20000	      -0.16653	3.34523
119.18605	13.22000	      -0.16900	3.34503
119.33613	13.24000	      -0.17146	3.34482
119.48627	13.26000	      -0.17416	3.34462
119.63638	13.28000	      -0.17709	3.34441
119.78645	13.30000	      -0.18010	3.34420
119.93656	13.32000	      -0.18318	3.34400
120.08667	13.34000	      -0.18654	3.34379
120.23675	13.36000	      -0.19012	3.34358
120.38680	13.38000	      -0.19386	3.34337
120.53685	13.40000	      -0.19792	3.34316
120.68691	13.42000	      -0.20221	3.34295
120.83698	13.44000	      -0.20683	3.34274
120.98696	13.46000	      -0.21144	3.34253
121.13696	13.48000	      -0.21685	3.34232
121.28707	13.50000	      -0.22235	3.34211
121.43713	13.52000	      -0.22788	3.34190
121.58718	13.54000	      -0.23417	3.34169
121.73718	13.56000	      -0.24088	3.34148
121.88720	13.58000	      -0.24762	3.34126
122.03729	13.60000	      -0.25483	3.34105
122.18740	13.62000	      -0.26258	3.34084
122.33749	13.64000	      -0.27061	3.34062
122.48756	13.66000	      -0.27857	3.34041
122.63758	13.68000	      -0.28700	3.34019
122.78756	13.70000	      -0.29554	3.33998
122.93753	13.72000	      -0.30407	3.33976
123.08747	13.74000	      -0.31216	3.33955
123.23736	13.76000	      -0.31983	3.33933
123.38729	13.78000	      -0.32718	3.33911
123.53716	13.80000	      -0.33400	3.33890
123.68705	13.82000	      -0.34043	3.33868
123.83693	13.84000	      -0.34643	3.33846
123.98678	13.86000	      -0.35157	3.33824
124.13653	13.88000	      -0.35653	3.33802
124.28636	13.90000	      -0.36044	3.33780
124.43629	13.92000	      -0.36353	3.33758
124.58625	13.94000	      -0.36576	3.33736
124.73618	13.96000	      -0.36684	3.33714
124.88613	13.98000	      -0.36661	3.33692
125.03600	14.00000	      -0.36511	3.33670
125.18596	14.02000	      -0.36196	3.33648
125.33607	14.04000	      -0.35624	3.33625
125.48605	14.06000	      -0.34873	3.33603
125.63618	14.08000	      -0.33893	3.33581
125.78636	14.10000	      -0.32791	3.33558
125.93640	14.12000	      -0.31448	3.33536
126.08658	14.14000	      -0.30027	3.33513
126.23685	14.16000	      -0.28573	3.33491
126.38702	14.18000	      -0.27134	3.33468
126.53716	14.20000	      -0.25770	3.33446
126.68724	14.22000	      -0.24536	3.33423
126.83735	14.24000	      -0.23465	3.33400
126.98751	14.26000	      -0.22535	3.33377
127.13776	14.28000	      -0.21794	3.33355
127.28789	14.30000	      -0.21226	3.33332
127.43795	14.32000	      -0.20764	3.33309
127.58807	14.34000	      -0.20412	3.33286
127.73811	14.36000	      -0.20128	3.33263
127.88822	14.38000	      -0.19914	3.33240
128.03845	14.40000	      -0.19795	3.33217
128.18842	14.42000	      -0.19711	3.33194
128.33833	14.44000	      -0.19659	3.33171
128.48820	14.46000	      -0.19625	3.33147
128.63816	14.48000	      -0.19634	3.33124
128.78809	14.50000	      -0.19650	3.33101
128.93796	14.52000	      -0.19706	3.33078
129.08778	14.54000	      -0.19773	3.33054
129.23747	14.56000	      -0.19828	3.33031
129.38715	14.58000	      -0.19910	3.33008
129.53678	14.60000	      -0.20028	3.32984
129.68647	14.62000	      -0.20080	3.32961
129.83625	14.64000	      -0.20195	3.32937
129.98607	14.66000	      -0.20277	3.32914
130.13585	14.68000	      -0.20377	3.32890
130.28578	14.70000	      -0.20515	3.32866
130.43574	14.72000	      -0.20592	3.32843
130.58576	14.74000	      -0.20747	3.32819
130.73569	14.76000	      -0.20867	3.32795
130.88584	14.78000	      -0.20995	3.32771
131.03607	14.80000	      -0.21137	3.32747
131.18625	14.82000	      -0.21243	3.32723
131.33655	14.84000	      -0.21378	3.32699
131.48684	14.86000	      -0.21512	3.32675
131.63713	14.88000	      -0.21616	3.32651
131.78735	14.90000	      -0.21752	3.32627
131.93749	14.92000	      -0.21851	3.32603
132.08747	14.94000	      -0.21964	3.32579
132.23755	14.96000	      -0.22052	3.32554
132.38762	14.98000	      -0.22155	3.32530
132.53767	15.00000	      -0.22275	3.32506
132.68769	15.02000	      -0.22399	3.32481
132.83764	15.04000	      -0.22527	3.32457
132.98753	15.06000	      -0.22655	3.32433
133.13735	15.08000	      -0.22779	3.32408
133.28727	15.10000	      -0.22900	3.32384
133.43718	15.12000	      -0.23044	3.32359
133.58711	15.14000	      -0.23175	3.32335
133.73705	15.16000	      -0.23306	3.32310
133.88696	15.18000	      -0.23412	3.32285
134.03698	15.20000	      -0.23526	3.32261
134.18702	15.22000	      -0.23643	3.32236
134.33704	15.24000	      -0.23759	3.32211
134.48711	15.26000	      -0.23874	3.32186
134.63704	15.28000	      -0.23967	3.32161
134.78713	15.30000	      -0.24072	3.32136
134.93715	15.32000	      -0.24172	3.32111
135.08714	15.34000	      -0.24306	3.32086
135.23711	15.36000	      -0.24397	3.32061
135.38709	15.38000	      -0.24505	3.32036
135.53709	15.40000	      -0.24603	3.32011
135.68713	15.42000	      -0.24666	3.31986
135.83709	15.44000	      -0.24779	3.31961
135.98707	15.46000	      -0.24837	3.31935
136.13707	15.48000	      -0.24904	3.31910
136.28713	15.50000	      -0.24988	3.31885
136.43707	15.52000	      -0.25044	3.31859
136.58705	15.54000	      -0.25097	3.31834
136.73704	15.56000	      -0.25153	3.31809
136.88691	15.58000	      -0.25204	3.31783
137.03684	15.60000	      -0.25232	3.31758
137.18682	15.62000	      -0.25318	3.31732
137.33678	15.64000	      -0.25344	3.31706
137.48676	15.66000	      -0.25402	3.31681
137.63671	15.68000	      -0.25415	3.31655
137.78669	15.70000	      -0.25440	3.31629
137.93667	15.72000	      -0.25461	3.31603
138.08671	15.74000	      -0.25500	3.31578
138.23680	15.76000	      -0.25514	3.31552
138.38687	15.78000	      -0.25542	3.31526
138.53700	15.80000	      -0.25558	3.31500
138.68705	15.82000	      -0.25578	3.31474
138.83715	15.84000	      -0.25584	3.31448
138.98735	15.86000	      -0.25582	3.31422
139.13753	15.88000	      -0.25596	3.31396
139.28762	15.90000	      -0.25600	3.31369
139.43776	15.92000	      -0.25594	3.31343
139.58778	15.94000	      -0.25588	3.31317
139.73784	15.96000	      -0.25587	3.31291
139.88795	15.98000	      -0.25576	3.31264
140.03795	16.00000	      -0.25557	3.31238
140.18782	16.02000	      -0.25554	3.31212
140.33765	16.04000	      -0.25531	3.31185
140.48755	16.06000	      -0.25513	3.31159
140.63740	16.08000	      -0.25489	3.31132
140.78738	16.10000	      -0.25466	3.31106
140.93736	16.12000	      -0.25445	3.31079
141.08736	16.14000	      -0.25430	3.31053
141.23736	16.16000	      -0.25399	3.31026
141.38735	16.18000	      -0.25399	3.30999
141.53738	16.20000	      -0.25393	3.30973
141.68753	16.22000	      -0.25368	3.30946
141.83762	16.24000	      -0.25350	3.30919
141.98760	16.26000	      -0.25297	3.30892
142.13765	16.28000	      -0.25269	3.30865
142.28780	16.30000	      -0.25264	3.30838
142.43789	16.32000	      -0.25229	3.30811
142.58791	16.34000	      -0.25222	3.30784
142.73793	16.36000	      -0.25199	3.30757
142.88789	16.38000	      -0.25169	3.30730
143.03776	16.40000	      -0.25101	3.30703
143.18758	16.42000	      -0.25081	3.30676
143.33740	16.44000	      -0.25062	3.30649
143.48740	16.46000	      -0.25038	3.30622
143.63729	16.48000	      -0.25013	3.30594
143.78704	16.50000	      -0.24997	3.30567
143.93689	16.52000	      -0.24977	3.30540
144.08678	16.54000	      -0.24961	3.30512
144.23669	16.56000	      -0.24950	3.30485
144.38660	16.58000	      -0.24931	3.30457
144.53647	16.60000	      -0.24910	3.30430
144.68649	16.62000	      -0.24889	3.30402
144.83645	16.64000	      -0.24860	3.30375
144.98640	16.66000	      -0.24854	3.30347
145.13635	16.68000	      -0.24840	3.30320
145.28636	16.70000	      -0.24826	3.30292
145.43644	16.72000	      -0.24812	3.30264
145.58644	16.74000	      -0.24775	3.30236
145.73649	16.76000	      -0.24748	3.30209
145.88653	16.78000	      -0.24749	3.30181
146.03655	16.80000	      -0.24722	3.30153
146.18664	16.82000	      -0.24719	3.30125
146.33673	16.84000	      -0.24698	3.30097
146.48682	16.86000	      -0.24674	3.30069
146.63691	16.88000	      -0.24647	3.30041
146.78702	16.90000	      -0.24621	3.30013
146.93705	16.92000	      -0.24559	3.29985
147.08716	16.94000	      -0.24536	3.29956
147.23716	16.96000	      -0.24523	3.29928
147.38709	16.98000	      -0.24505	3.29900
147.53696	17.00000	      -0.24477	3.29872
147.68687	17.02000	      -0.24441	3.29843
147.83680	17.04000	      -0.24413	3.29815
147.98687	17.06000	      -0.24385	3.29787
148.13691	17.08000	      -0.24353	3.29758
148.28700	17.10000	      -0.24324	3.29730
148.43700	17.12000	      -0.24300	3.29701
148.58693	17.14000	      -0.24279	3.29673
148.73693	17.16000	      -0.24268	3.29644
148.88695	17.18000	      -0.24234	3.29616
149.03696	17.20000	      -0.24210	3.29587
149.18712	17.22000	      -0.24190	3.29558
149.33729	17.24000	      -0.24136	3.29529
149.48752	17.26000	      -0.24105	3.29501
149.63747	17.28000	      -0.24057	3.29472
149.78754	17.30000	      -0.24034	3.29443
149.93866	17.32000	      -0.24011	3.29414