File: data/ExpDat_SK_Mix_resin_entalp300kpm_30-300.txt
#EXPORTTYPE:                 	DATA SINGLE
#FILE:                       	SK_Mix_resin_entalp300kpm_30-300.ngb-sdg
#FORMAT:                     	NETZSCH5
#FTYPE:                      	ASCII
#IDENTITY:                   	SK_epoxy
#DECIMAL:                    	POINT
#SEPARATOR:                  	TAB
#MTYPE:                      	DSC
#INSTRUMENT:                 	NETZSCH DSC 214
#PROJECT:                    	?ø?†??-Ø
#DATE/TIME:                  	12.09.2019 21:16:59 (UTC+3)
#CORR. FILE:
#TEMPCAL:                    	applied
#SENSITIVITY:                	applied
#LABORATORY:                 	CISIS
#OPERATOR:                   	Nasonov
#REMARK:
#SAMPLE:                     	20190907_1083-G290S -0-
#SAMPLE MASS /mg:            	8.42
#MATERIAL:
#REFERENCE:
#REFERENCE MASS /mg:         	0
#TYPE OF CRUCIBLE:           	Concavus Pan Al, pierced lid
#SAMPLE CRUCIBLE MASS /mg:   	0
#REFERENCE CRUCIBLE MASS /mg:	0
#M.RANGE /ßV:                	5000
#TAU-R:                      	---
#CORR. CODE:                 	009
#EXO:                        	+1
#RANGE:                      	30ËC/300.0(K/min)/300ËC
#SEGMENT:                    	S1/1
#SEG. 1:                     	30ËC/300.0(K/min)/300ËC

##Temp./ËC	Time/min	DSC/(mW/mg)	Sensit./(uV/mW)
 30.11600	0.00000	 1.880396e-002	3.37647
 30.11620	0.01000	 1.864298e-002	3.37647
 30.11620	0.02000	 1.861580e-002	3.37647
 30.15600	0.03000	 8.358723e-003	3.37650
 30.37400	0.04000	-4.948209e-002	3.37667
 30.89320	0.05000	      -0.20126	3.37706
 31.74840	0.06000	      -0.46780	3.37768
 32.93460	0.07000	      -0.84658	3.37852
 34.43280	0.08000	      -1.32279	3.37953
 36.22860	0.09000	      -1.88025	3.38065
 38.30460	0.10000	      -2.50206	3.38185
 40.63960	0.11000	      -3.17167	3.38305
 43.22480	0.12000	      -3.87882	3.38422
 46.04460	0.13000	      -4.61350	3.38529
 49.08780	0.14000	      -5.36721	3.38621
 52.33600	0.15000	      -6.13253	3.38692
 55.77040	0.16000	      -6.90140	3.38739
 59.37660	0.17000	      -7.66728	3.38755
 63.13140	0.18000	      -8.42271	3.38736
 67.01800	0.19000	      -9.16212	3.38680
 71.01920	0.20000	      -9.88036	3.38583
 75.11580	0.21000	     -10.57417	3.38443
 79.29180	0.22000	     -11.23798	3.38259
 83.53040	0.23000	     -11.87036	3.38029
 87.81540	0.24000	     -12.46753	3.37754
 92.12840	0.25000	     -13.02712	3.37435
 96.45600	0.26000	     -13.54512	3.37072
100.79020	0.27000	     -14.01661	3.36667
105.12040	0.28000	     -14.45153	3.36222
109.43800	0.29000	     -14.84847	3.35738
113.73140	0.30000	     -15.20362	3.35218
117.98920	0.31000	     -15.51512	3.34665
122.20220	0.32000	     -15.80541	3.34082
126.36240	0.33000	     -16.06987	3.33472
130.46400	0.34000	     -16.29368	3.32838
134.50421	0.35000	     -16.45518	3.32183
138.47760	0.36000	     -16.49822	3.31510
142.37940	0.37000	     -16.33781	3.30822
146.20920	0.38000	     -15.93878	3.30121
149.96680	0.39000	     -15.30584	3.29409
153.64980	0.40000	     -14.43450	3.28688
157.25920	0.41000	     -13.28024	3.27961
160.79640	0.42000	     -11.80588	3.27229
164.26600	0.43000	      -9.89780	3.26492
167.66680	0.44000	      -7.57334	3.25752
171.00060	0.45000	      -4.99023	3.25011
174.27140	0.46000	      -2.16739	3.24269
177.48240	0.47000	       1.40620	3.23527
180.63960	0.48000	       6.20327	3.22784
183.74400	0.49000	      11.05362	3.22040
186.78720	0.50000	      13.85734	3.21300
189.76860	0.51000	      14.28967	3.20564
192.69680	0.52000	      13.36595	3.19831
195.57920	0.53000	      11.81877	3.19100
198.41820	0.54000	      10.06548	3.18371
201.21760	0.55000	       8.28341	3.17644
203.98800	0.56000	       6.55911	3.16917
206.73340	0.57000	       4.93413	3.16188
209.46040	0.58000	       3.43031	3.15457
212.17420	0.59000	       2.05645	3.14723
214.88060	0.60000	       0.80770	3.13984
217.58260	0.61000	      -0.32436	3.13241
220.28120	0.62000	      -1.34834	3.12491
222.98100	0.63000	      -2.27283	3.11736
225.68360	0.64000	      -3.10819	3.10975
228.39440	0.65000	      -3.86951	3.10205
231.11360	0.66000	      -4.56930	3.09428
233.84460	0.67000	      -5.21474	3.08643
236.58400	0.68000	      -5.81030	3.07850
239.33360	0.69000	      -6.36059	3.07050
242.09620	0.70000	      -6.87395	3.06242
244.87820	0.71000	      -7.35817	3.05423
247.68060	0.72000	      -7.82132	3.04595
250.51220	0.73000	      -8.27834	3.03754
253.37180	0.74000	      -8.73598	3.02900
256.24279	0.75000	      -9.14934	3.02040
259.13940	0.76000	      -9.55062	3.01169
262.05140	0.77000	      -9.92934	3.00290
264.97680	0.78000	     -10.27847	2.99404
267.91619	0.79000	     -10.59450	2.98511
270.86620	0.80000	     -10.88516	2.97613
273.83019	0.81000	     -11.15532	2.96708
276.80260	0.82000	     -11.39670	2.95798
279.78660	0.83000	     -11.61956	2.94883
282.77721	0.84000	     -11.82707	2.93965
285.77740	0.85000	     -12.02215	2.93042
288.78519	0.86000	     -12.20133	2.92116
291.80100	0.87000	     -12.36951	2.91187
294.82219	0.88000	     -12.53311	2.90255
297.85020	0.89000	     -12.68780	2.89322