File: data/ExpDat_SK_Mix_resin_entalp200kpm_30-300.txt
#EXPORTTYPE:                 	DATA SINGLE
#FILE:                       	SK_Mix_resin_entalp200kpm_30-300.ngb-sdg
#FORMAT:                     	NETZSCH5
#FTYPE:                      	ASCII
#IDENTITY:                   	SK_epoxy
#DECIMAL:                    	POINT
#SEPARATOR:                  	TAB
#MTYPE:                      	DSC
#INSTRUMENT:                 	NETZSCH DSC 214
#PROJECT:                    	?ø?†??-Ø
#DATE/TIME:                  	12.09.2019 21:23:54 (UTC+3)
#CORR. FILE:
#TEMPCAL:                    	applied
#SENSITIVITY:                	applied
#LABORATORY:                 	CISIS
#OPERATOR:                   	Nasonov
#REMARK:
#SAMPLE:                     	20190907_1083-G290S -0-
#SAMPLE MASS /mg:            	9.12
#MATERIAL:
#REFERENCE:
#REFERENCE MASS /mg:         	0
#TYPE OF CRUCIBLE:           	Concavus Pan Al, pierced lid
#SAMPLE CRUCIBLE MASS /mg:   	0
#REFERENCE CRUCIBLE MASS /mg:	0
#M.RANGE /ßV:                	5000
#TAU-R:                      	---
#CORR. CODE:                 	009
#EXO:                        	+1
#RANGE:                      	30ËC/200.0(K/min)/300ËC
#SEGMENT:                    	S1/1
#SEG. 1:                     	30ËC/200.0(K/min)/300ËC

##Temp./ËC	Time/min	DSC/(mW/mg)	Sensit./(uV/mW)
 29.96600	0.00000	 1.569224e-002	3.37635
 29.96600	0.01000	 1.559313e-002	3.37635
 29.96729	0.02000	 1.537058e-002	3.37635
 29.99643	0.03000	 7.658363e-003	3.37638
 30.14143	0.04000	-3.785545e-002	3.37649
 30.48157	0.05000	      -0.15862	3.37675
 31.03414	0.06000	      -0.36805	3.37716
 31.79729	0.07000	      -0.65999	3.37772
 32.76486	0.08000	      -1.02201	3.37841
 33.93171	0.09000	      -1.44108	3.37920
 35.28800	0.10000	      -1.90520	3.38008
 36.82900	0.11000	      -2.40584	3.38101
 38.54300	0.12000	      -2.93396	3.38198
 40.42200	0.13000	      -3.48023	3.38295
 42.45271	0.14000	      -4.03783	3.38389
 44.62614	0.15000	      -4.60047	3.38478
 46.92957	0.16000	      -5.15993	3.38558
 49.34843	0.17000	      -5.71199	3.38628
 51.87057	0.18000	      -6.25201	3.38684
 54.48300	0.19000	      -6.77502	3.38725
 57.17043	0.20000	      -7.27530	3.38749
 59.91929	0.21000	      -7.74855	3.38754
 62.72014	0.22000	      -8.19399	3.38740
 65.56143	0.23000	      -8.61173	3.38705
 68.43471	0.24000	      -9.00067	3.38650
 71.32957	0.25000	      -9.35965	3.38574
 74.24100	0.26000	      -9.69010	3.38476
 77.15671	0.27000	      -9.99016	3.38358
 80.06857	0.28000	     -10.25965	3.38220
 82.96771	0.29000	     -10.49826	3.38062
 85.84629	0.30000	     -10.70652	3.37886
 88.69686	0.31000	     -10.88513	3.37693
 91.51286	0.32000	     -11.03403	3.37483
 94.29171	0.33000	     -11.15532	3.37259
 97.02800	0.34000	     -11.24851	3.37021
 99.71914	0.35000	     -11.31354	3.36771
102.36329	0.36000	     -11.35090	3.36510
104.95571	0.37000	     -11.36073	3.36240
107.49743	0.38000	     -11.34573	3.35960
109.98800	0.39000	     -11.31399	3.35673
112.42657	0.40000	     -11.26776	3.35380
114.81343	0.41000	     -11.20639	3.35081
117.15000	0.42000	     -11.12870	3.34777
119.43686	0.43000	     -11.02898	3.34468
121.67571	0.44000	     -10.90434	3.34156
123.86943	0.45000	     -10.73695	3.33841
126.01986	0.46000	     -10.50402	3.33523
128.12900	0.47000	     -10.18169	3.33203
130.20057	0.48000	      -9.75283	3.32880
132.23643	0.49000	      -9.21035	3.32555
134.23843	0.50000	      -8.56010	3.32227
136.21228	0.51000	      -7.80203	3.31897
138.15857	0.52000	      -6.91106	3.31565
140.08314	0.53000	      -5.84109	3.31230
141.98700	0.54000	      -4.53144	3.30892
143.87457	0.55000	      -2.92945	3.30551
145.74857	0.56000	      -0.98473	3.30206
147.61014	0.57000	       1.25812	3.29858
149.46214	0.58000	       3.59566	3.29506
151.30257	0.59000	       5.70357	3.29150
153.13414	0.60000	       7.41637	3.28790
154.95886	0.61000	       8.78401	3.28427
156.77543	0.62000	       9.96962	3.28060
158.58700	0.63000	      11.01515	3.27688
160.39157	0.64000	      11.78750	3.27313
162.19500	0.65000	      12.15268	3.26934
163.99743	0.66000	      12.02653	3.26549
165.80257	0.67000	      11.44574	3.26160
167.61228	0.68000	      10.53713	3.25764
169.42843	0.69000	       9.45075	3.25363
171.25400	0.70000	       8.27173	3.24955
173.09000	0.71000	       7.05611	3.24539
174.93657	0.72000	       5.84709	3.24117
176.79586	0.73000	       4.67870	3.23687
178.66843	0.74000	       3.56819	3.23249
180.55357	0.75000	       2.52224	3.22804
182.45086	0.76000	       1.54449	3.22351
184.36257	0.77000	       0.63627	3.21891
186.28414	0.78000	      -0.20199	3.21423
188.21743	0.79000	      -0.97254	3.20948
190.15943	0.80000	      -1.67747	3.20467
192.11372	0.81000	      -2.32026	3.19978
194.07829	0.82000	      -2.90372	3.19482
196.05128	0.83000	      -3.42985	3.18980
198.03343	0.84000	      -3.90298	3.18471
200.02585	0.85000	      -4.33483	3.17955
202.03028	0.86000	      -4.73251	3.17431
204.04772	0.87000	      -5.08763	3.16901
206.07700	0.88000	      -5.40084	3.16363
208.11428	0.89000	      -5.67684	3.15819
210.15786	0.90000	      -5.91840	3.15269
212.20743	0.91000	      -6.12947	3.14714
214.25871	0.92000	      -6.31203	3.14155
216.31157	0.93000	      -6.47067	3.13591
218.36586	0.94000	      -6.61041	3.13024
220.42057	0.95000	      -6.73595	3.12453
222.47400	0.96000	      -6.85240	3.11879
224.52671	0.97000	      -6.96459	3.11301
226.57757	0.98000	      -7.07783	3.10722
228.62614	0.99000	      -7.19645	3.10139
230.67157	1.00000	      -7.32217	3.09555
232.71443	1.01000	      -7.45621	3.08969
234.75529	1.02000	      -7.59940	3.08380
236.79271	1.03000	      -7.74965	3.07790
238.82657	1.04000	      -7.90195	3.07198
240.85586	1.05000	      -8.05143	3.06605
242.88186	1.06000	      -8.19598	3.06011
244.90428	1.07000	      -8.33122	3.05415
246.92343	1.08000	      -8.45430	3.04819
248.93857	1.09000	      -8.56726	3.04221
250.95129	1.10000	      -8.66758	3.03623
252.96129	1.11000	      -8.75805	3.03023
254.96843	1.12000	      -8.83977	3.02422
256.97401	1.13000	      -8.91009	3.01821
258.97629	1.14000	      -8.97482	3.01218
260.97757	1.15000	      -9.03278	3.00614
262.97486	1.16000	      -9.08380	3.00011
264.97114	1.17000	      -9.12927	2.99406
266.96471	1.18000	      -9.17056	2.98800
268.95786	1.19000	      -9.20740	2.98194
270.94914	1.20000	      -9.24065	2.97587
272.93771	1.21000	      -9.27201	2.96980
274.92500	1.22000	      -9.30073	2.96373
276.91100	1.23000	      -9.32737	2.95765
278.89714	1.24000	      -9.35272	2.95156
280.88343	1.25000	      -9.37372	2.94546
282.86886	1.26000	      -9.39705	2.93937
284.85485	1.27000	      -9.41937	2.93326
286.84072	1.28000	      -9.44281	2.92715
288.82715	1.29000	      -9.46657	2.92103
290.81486	1.30000	      -9.48925	2.91491
292.80300	1.31000	      -9.51104	2.90878
294.79286	1.32000	      -9.53185	2.90265
296.78142	1.33000	      -9.55400	2.89651
298.77014	1.34000	      -9.57382	2.89038