File: data/ExpDat_SK_Mix_resin_entalp5kpm_20-150.txt
#EXPORTTYPE:                 	DATA SINGLE
#FILE:                       	SK_Mix_resin_entalp5kpm_30-150_bad_TG.ngb-sdg
#FORMAT:                     	NETZSCH5
#FTYPE:                      	ASCII
#IDENTITY:                   	SK_epoxy
#DECIMAL:                    	POINT
#SEPARATOR:                  	TAB
#MTYPE:                      	DSC
#INSTRUMENT:                 	NETZSCH DSC 214
#PROJECT:                    	?ø?†??-Ø
#DATE/TIME:                  	12.09.2019 21:40:12 (UTC+3)
#CORR. FILE:
#TEMPCAL:                    	applied
#SENSITIVITY:                	applied
#LABORATORY:                 	CISIS
#OPERATOR:                   	Nasonov
#REMARK:
#SAMPLE:                     	20190907_1083-G290S -0-
#SAMPLE MASS /mg:            	9.38
#MATERIAL:
#REFERENCE:
#REFERENCE MASS /mg:         	0
#TYPE OF CRUCIBLE:           	Concavus Pan Al, pierced lid
#SAMPLE CRUCIBLE MASS /mg:   	0
#REFERENCE CRUCIBLE MASS /mg:	0
#M.RANGE /ßV:                	5000
#TAU-R:                      	---
#CORR. CODE:                 	009
#EXO:                        	+1
#RANGE:                      	-40ËC....150ËC/-10.0....50.0K/min
#SEGMENT:                    	S3/3
#SEG. 1:                     	30ËC/10.0(K/min)/-40ËC
#SEG. 2:                     	-40ËC/50.0(K/min)/30ËC
#SEG. 3:                     	30ËC/5.0(K/min)/150ËC

##Temp./ËC	Time/min	DSC/(mW/mg)	Sensit./(uV/mW)
 31.60408	 8.42700	      -1.86328	3.37758
 32.61848	 8.45700	      -1.81155	3.37830
 33.14110	 8.48700	      -1.64499	3.37867
 33.30390	 8.51700	      -1.39347	3.37878
 33.23934	 8.54700	      -1.09817	3.37873
 33.06265	 8.57700	      -0.79625	3.37861
 32.89068	 8.60700	      -0.51324	3.37849
 32.91666	 8.63700	      -0.26421	3.37851
 32.84032	 8.66700	-5.915389e-002	3.37846
 32.70299	 8.69700	 9.537243e-002	3.37836
 32.53854	 8.72700	       0.19928	3.37825
 32.37516	 8.75700	       0.25522	3.37813
 32.23393	 8.78700	       0.26993	3.37803
 32.12962	 8.81700	       0.25084	3.37796
 32.07156	 8.84700	       0.20747	3.37792
 32.06383	 8.87700	       0.14743	3.37791
 32.10603	 8.90700	 7.944365e-002	3.37794
 32.19443	 8.93700	 9.894040e-003	3.37800
 32.32271	 8.96700	-5.562905e-002	3.37810
 32.48313	 8.99700	      -0.11389	3.37821
 32.66752	 9.02700	      -0.16202	3.37834
 32.86801	 9.05700	      -0.19903	3.37848
 33.07714	 9.08700	      -0.22479	3.37862
 33.28847	 9.11700	      -0.23970	3.37877
 33.49725	 9.14700	      -0.24601	3.37891
 33.69990	 9.17700	      -0.24484	3.37904
 33.89409	 9.20700	      -0.23806	3.37917
 34.07860	 9.23700	      -0.22772	3.37930
 34.25348	 9.26700	      -0.21481	3.37941
 34.41929	 9.29700	      -0.20164	3.37952
 34.57720	 9.32700	      -0.18881	3.37962
 34.72859	 9.35700	      -0.17755	3.37972
 34.87500	 9.38700	      -0.16829	3.37981
 35.01820	 9.41700	      -0.16087	3.37991
 35.15958	 9.44700	      -0.15569	3.37999
 35.30007	 9.47700	      -0.15283	3.38008
 35.44101	 9.50700	      -0.15159	3.38017
 35.58306	 9.53700	      -0.15201	3.38026
 35.72662	 9.56700	      -0.15342	3.38035
 35.87192	 9.59700	      -0.15561	3.38044
 36.01907	 9.62700	      -0.15853	3.38053
 36.16794	 9.65700	      -0.16150	3.38062
 36.31808	 9.68700	      -0.16422	3.38071
 36.46939	 9.71700	      -0.16621	3.38080
 36.62168	 9.74700	      -0.16830	3.38089
 36.77457	 9.77700	      -0.17011	3.38098
 36.92788	 9.80700	      -0.17116	3.38107
 37.08121	 9.83700	      -0.17187	3.38116
 37.23444	 9.86700	      -0.17259	3.38125
 37.38732	 9.89700	      -0.17272	3.38133
 37.53976	 9.92700	      -0.17318	3.38142
 37.69187	 9.95700	      -0.17296	3.38151
 37.84370	 9.98700	      -0.17275	3.38159
 37.99514	10.01700	      -0.17248	3.38168
 38.14629	10.04700	      -0.17234	3.38176
 38.29720	10.07700	      -0.17226	3.38184
 38.44793	10.10700	      -0.17213	3.38193
 38.59846	10.13700	      -0.17216	3.38201
 38.74884	10.16700	      -0.17240	3.38209
 38.89921	10.19700	      -0.17276	3.38217
 39.04948	10.22700	      -0.17272	3.38225
 39.19959	10.25700	      -0.17290	3.38233
 39.34973	10.28700	      -0.17291	3.38240
 39.49991	10.31700	      -0.17320	3.38248
 39.65012	10.34700	      -0.17360	3.38256
 39.80049	10.37700	      -0.17385	3.38264
 39.95087	10.40700	      -0.17415	3.38271
 40.10129	10.43700	      -0.17438	3.38279
 40.25176	10.46700	      -0.17459	3.38286
 40.40233	10.49700	      -0.17497	3.38294
 40.55282	10.52700	      -0.17546	3.38301
 40.70338	10.55700	      -0.17581	3.38308
 40.85392	10.58700	      -0.17629	3.38316
 41.00434	10.61700	      -0.17662	3.38323
 41.15493	10.64700	      -0.17700	3.38330
 41.30556	10.67700	      -0.17723	3.38337
 41.45624	10.70700	      -0.17736	3.38344
 41.60702	10.73700	      -0.17772	3.38351
 41.75763	10.76700	      -0.17799	3.38358
 41.90805	10.79700	      -0.17809	3.38365
 42.05839	10.82700	      -0.17842	3.38371
 42.20863	10.85700	      -0.17858	3.38378
 42.35880	10.88700	      -0.17885	3.38385
 42.50891	10.91700	      -0.17903	3.38391
 42.65923	10.94700	      -0.17935	3.38398
 42.80936	10.97700	      -0.17939	3.38404
 42.95962	11.00700	      -0.17965	3.38411
 43.10986	11.03700	      -0.17977	3.38417
 43.26002	11.06700	      -0.18011	3.38423
 43.41009	11.09700	      -0.18057	3.38429
 43.56024	11.12700	      -0.18105	3.38436
 43.71034	11.15700	      -0.18157	3.38442
 43.86047	11.18700	      -0.18216	3.38448
 44.01083	11.21700	      -0.18245	3.38454
 44.16112	11.24700	      -0.18265	3.38460
 44.31147	11.27700	      -0.18299	3.38465
 44.46178	11.30700	      -0.18318	3.38471
 44.61209	11.33700	      -0.18376	3.38477
 44.76230	11.36700	      -0.18398	3.38483
 44.91260	11.39700	      -0.18431	3.38488
 45.06283	11.42700	      -0.18457	3.38494
 45.21316	11.45700	      -0.18466	3.38499
 45.36347	11.48700	      -0.18493	3.38505
 45.51375	11.51700	      -0.18523	3.38510
 45.66404	11.54700	      -0.18533	3.38516
 45.81432	11.57700	      -0.18552	3.38521
 45.96466	11.60700	      -0.18561	3.38526
 46.11485	11.63700	      -0.18596	3.38531
 46.26511	11.66700	      -0.18640	3.38536
 46.41534	11.69700	      -0.18665	3.38541
 46.56559	11.72700	      -0.18679	3.38546
 46.71585	11.75700	      -0.18705	3.38551
 46.86609	11.78700	      -0.18714	3.38556
 47.01629	11.81700	      -0.18743	3.38561
 47.16636	11.84700	      -0.18767	3.38565
 47.31649	11.87700	      -0.18767	3.38570
 47.46653	11.90700	      -0.18788	3.38575
 47.61658	11.93700	      -0.18822	3.38579
 47.76663	11.96700	      -0.18831	3.38584
 47.91668	11.99700	      -0.18865	3.38588
 48.06674	12.02700	      -0.18888	3.38593
 48.21687	12.05700	      -0.18907	3.38597
 48.36694	12.08700	      -0.18941	3.38601
 48.51711	12.11700	      -0.18966	3.38605
 48.66721	12.14700	      -0.19000	3.38609
 48.81732	12.17700	      -0.19043	3.38614
 48.96748	12.20700	      -0.19074	3.38618
 49.11760	12.23700	      -0.19103	3.38622
 49.26762	12.26700	      -0.19125	3.38625
 49.41770	12.29700	      -0.19140	3.38629
 49.56782	12.32700	      -0.19169	3.38633
 49.71786	12.35700	      -0.19177	3.38637
 49.86797	12.38700	      -0.19200	3.38640
 50.01803	12.41700	      -0.19216	3.38644
 50.16816	12.44700	      -0.19230	3.38648
 50.31824	12.47700	      -0.19249	3.38651
 50.46836	12.50700	      -0.19293	3.38655
 50.61857	12.53700	      -0.19312	3.38658
 50.76879	12.56700	      -0.19335	3.38661
 50.91915	12.59700	      -0.19372	3.38665
 51.06940	12.62700	      -0.19426	3.38668
 51.21985	12.65700	      -0.19433	3.38671
 51.37026	12.68700	      -0.19447	3.38674
 51.52064	12.71700	      -0.19482	3.38677
 51.67085	12.74700	      -0.19487	3.38680
 51.82109	12.77700	      -0.19532	3.38683
 51.97117	12.80700	      -0.19526	3.38686
 52.12122	12.83700	      -0.19520	3.38689
 52.27119	12.86700	      -0.19539	3.38691
 52.42126	12.89700	      -0.19544	3.38694
 52.57138	12.92700	      -0.19559	3.38697
 52.72147	12.95700	      -0.19571	3.38699
 52.87143	12.98700	      -0.19585	3.38702
 53.02145	13.01700	      -0.19624	3.38704
 53.17146	13.04700	      -0.19652	3.38706
 53.32140	13.07700	      -0.19689	3.38709
 53.47138	13.10700	      -0.19713	3.38711
 53.62149	13.13700	      -0.19738	3.38713
 53.77162	13.16700	      -0.19780	3.38715
 53.92185	13.19700	      -0.19801	3.38717
 54.07203	13.22700	      -0.19809	3.38720
 54.22226	13.25700	      -0.19808	3.38722
 54.37239	13.28700	      -0.19812	3.38723
 54.52248	13.31700	      -0.19840	3.38725
 54.67236	13.34700	      -0.19840	3.38727
 54.82239	13.37700	      -0.19848	3.38729
 54.97232	13.40700	      -0.19860	3.38731
 55.12229	13.43700	      -0.19901	3.38732
 55.27227	13.46700	      -0.19897	3.38734
 55.42231	13.49700	      -0.19934	3.38735
 55.57231	13.52700	      -0.19949	3.38737
 55.72240	13.55700	      -0.19956	3.38738
 55.87260	13.58700	      -0.19984	3.38739
 56.02275	13.61700	      -0.19993	3.38741
 56.17294	13.64700	      -0.20049	3.38742
 56.32306	13.67700	      -0.20056	3.38743
 56.47323	13.70700	      -0.20087	3.38744
 56.62336	13.73700	      -0.20092	3.38745
 56.77358	13.76700	      -0.20123	3.38746
 56.92367	13.79700	      -0.20155	3.38747
 57.07385	13.82700	      -0.20141	3.38748
 57.22386	13.85700	      -0.20140	3.38749
 57.37396	13.88700	      -0.20161	3.38750
 57.52398	13.91700	      -0.20166	3.38750
 57.67396	13.94700	      -0.20178	3.38751
 57.82391	13.97700	      -0.20185	3.38752
 57.97395	14.00700	      -0.20209	3.38752
 58.12398	14.03700	      -0.20225	3.38753
 58.27405	14.06700	      -0.20231	3.38753
 58.42406	14.09700	      -0.20260	3.38754
 58.57430	14.12700	      -0.20271	3.38754
 58.72452	14.15700	      -0.20287	3.38754
 58.87463	14.18700	      -0.20303	3.38754
 59.02478	14.21700	      -0.20313	3.38754
 59.17491	14.24700	      -0.20336	3.38755
 59.32506	14.27700	      -0.20352	3.38755
 59.47525	14.30700	      -0.20373	3.38755
 59.62536	14.33700	      -0.20385	3.38754
 59.77562	14.36700	      -0.20396	3.38754
 59.92585	14.39700	      -0.20420	3.38754
 60.07600	14.42700	      -0.20411	3.38754
 60.22609	14.45700	      -0.20421	3.38754
 60.37618	14.48700	      -0.20437	3.38753
 60.52626	14.51700	      -0.20452	3.38753
 60.67610	14.54700	      -0.20463	3.38752
 60.82596	14.57700	      -0.20480	3.38752
 60.97581	14.60700	      -0.20481	3.38751
 61.12563	14.63700	      -0.20504	3.38750
 61.27552	14.66700	      -0.20502	3.38750
 61.42550	14.69700	      -0.20529	3.38749
 61.57561	14.72700	      -0.20546	3.38748
 61.72550	14.75700	      -0.20546	3.38747
 61.87541	14.78700	      -0.20557	3.38746
 62.02531	14.81700	      -0.20579	3.38745
 62.17528	14.84700	      -0.20602	3.38744
 62.32532	14.87700	      -0.20629	3.38743
 62.47530	14.90700	      -0.20650	3.38742
 62.62537	14.93700	      -0.20686	3.38741
 62.77569	14.96700	      -0.20704	3.38739
 62.92588	14.99700	      -0.20705	3.38738
 63.07613	15.02700	      -0.20707	3.38737
 63.22647	15.05700	      -0.20706	3.38735
 63.37664	15.08700	      -0.20705	3.38734
 63.52690	15.11700	      -0.20700	3.38732
 63.67700	15.14700	      -0.20710	3.38730
 63.82714	15.17700	      -0.20699	3.38729
 63.97720	15.20700	      -0.20704	3.38727
 64.12716	15.23700	      -0.20709	3.38725
 64.27707	15.26700	      -0.20709	3.38723
 64.42714	15.29700	      -0.20698	3.38722
 64.57709	15.32700	      -0.20705	3.38720
 64.72706	15.35700	      -0.20698	3.38718
 64.87698	15.38700	      -0.20699	3.38716
 65.02701	15.41700	      -0.20699	3.38713
 65.17691	15.44700	      -0.20709	3.38711
 65.32688	15.47700	      -0.20717	3.38709
 65.47679	15.50700	      -0.20726	3.38707
 65.62678	15.53700	      -0.20735	3.38704
 65.77680	15.56700	      -0.20742	3.38702
 65.92683	15.59700	      -0.20745	3.38699
 66.07693	15.62700	      -0.20765	3.38697
 66.22699	15.65700	      -0.20762	3.38694
 66.37701	15.68700	      -0.20764	3.38692
 66.52711	15.71700	      -0.20762	3.38689
 66.67729	15.74700	      -0.20770	3.38686
 66.82739	15.77700	      -0.20765	3.38683
 66.97756	15.80700	      -0.20759	3.38681
 67.12778	15.83700	      -0.20776	3.38678
 67.27795	15.86700	      -0.20782	3.38675
 67.42813	15.89700	      -0.20777	3.38672
 67.57828	15.92700	      -0.20778	3.38669
 67.72836	15.95700	      -0.20800	3.38665
 67.87838	15.98700	      -0.20788	3.38662
 68.02849	16.01700	      -0.20806	3.38659
 68.17853	16.04700	      -0.20804	3.38656
 68.32857	16.07700	      -0.20785	3.38652
 68.47857	16.10700	      -0.20778	3.38649
 68.62850	16.13700	      -0.20762	3.38646
 68.77854	16.16700	      -0.20765	3.38642
 68.92853	16.19700	      -0.20766	3.38638
 69.07840	16.22700	      -0.20785	3.38635
 69.22827	16.25700	      -0.20764	3.38631
 69.37812	16.28700	      -0.20771	3.38627
 69.52811	16.31700	      -0.20754	3.38624
 69.67806	16.34700	      -0.20758	3.38620
 69.82811	16.37700	      -0.20763	3.38616
 69.97816	16.40700	      -0.20732	3.38612
 70.12812	16.43700	      -0.20713	3.38608
 70.27818	16.46700	      -0.20700	3.38604
 70.42822	16.49700	      -0.20690	3.38600
 70.57826	16.52700	      -0.20677	3.38595
 70.72832	16.55700	      -0.20634	3.38591
 70.87825	16.58700	      -0.20631	3.38587
 71.02827	16.61700	      -0.20612	3.38583
 71.17835	16.64700	      -0.20583	3.38578
 71.32836	16.67700	      -0.20558	3.38574
 71.47839	16.70700	      -0.20520	3.38569
 71.62847	16.73700	      -0.20506	3.38565
 71.77846	16.76700	      -0.20473	3.38560
 71.92844	16.79700	      -0.20439	3.38555
 72.07842	16.82700	      -0.20400	3.38551
 72.22842	16.85700	      -0.20382	3.38546
 72.37846	16.88700	      -0.20333	3.38541
 72.52850	16.91700	      -0.20295	3.38536
 72.67854	16.94700	      -0.20245	3.38531
 72.82849	16.97700	      -0.20219	3.38526
 72.97858	17.00700	      -0.20157	3.38521
 73.12868	17.03700	      -0.20122	3.38516
 73.27872	17.06700	      -0.20040	3.38511
 73.42873	17.09700	      -0.19980	3.38505
 73.57870	17.12700	      -0.19926	3.38500
 73.72875	17.15700	      -0.19855	3.38495
 73.87872	17.18700	      -0.19795	3.38489
 74.02877	17.21700	      -0.19721	3.38484
 74.17893	17.24700	      -0.19640	3.38478
 74.32906	17.27700	      -0.19565	3.38473
 74.47911	17.30700	      -0.19504	3.38467
 74.62911	17.33700	      -0.19422	3.38462
 74.77922	17.36700	      -0.19334	3.38456
 74.92936	17.39700	      -0.19230	3.38450
 75.07941	17.42700	      -0.19140	3.38444
 75.22945	17.45700	      -0.19032	3.38438
 75.37957	17.48700	      -0.18905	3.38433
 75.52960	17.51700	      -0.18777	3.38427
 75.67958	17.54700	      -0.18649	3.38420
 75.82955	17.57700	      -0.18574	3.38414
 75.97953	17.60700	      -0.18398	3.38408
 76.12957	17.63700	      -0.18273	3.38402
 76.27947	17.66700	      -0.18121	3.38396
 76.42932	17.69700	      -0.17980	3.38389
 76.57931	17.72700	      -0.17811	3.38383
 76.72939	17.75700	      -0.17671	3.38377
 76.87935	17.78700	      -0.17519	3.38370
 77.02929	17.81700	      -0.17361	3.38364
 77.17927	17.84700	      -0.17195	3.38357
 77.32924	17.87700	      -0.16997	3.38350
 77.47917	17.90700	      -0.16808	3.38344
 77.62914	17.93700	      -0.16628	3.38337
 77.77917	17.96700	      -0.16428	3.38330
 77.92922	17.99700	      -0.16245	3.38323
 78.07919	18.02700	      -0.16022	3.38316
 78.22929	18.05700	      -0.15813	3.38309
 78.37942	18.08700	      -0.15614	3.38302
 78.52959	18.11700	      -0.15376	3.38295
 78.67973	18.14700	      -0.15129	3.38288
 78.82973	18.17700	      -0.14874	3.38281
 78.97980	18.20700	      -0.14623	3.38274
 79.12990	18.23700	      -0.14361	3.38267
 79.27986	18.26700	      -0.14106	3.38259
 79.42991	18.29700	      -0.13806	3.38252
 79.57997	18.32700	      -0.13522	3.38244
 79.73004	18.35700	      -0.13191	3.38237
 79.88011	18.38700	      -0.12883	3.38229
 80.03024	18.41700	      -0.12568	3.38222
 80.18036	18.44700	      -0.12251	3.38214
 80.33040	18.47700	      -0.11875	3.38206
 80.48036	18.50700	      -0.11520	3.38199
 80.63072	18.53700	      -0.11185	3.38191
 80.78112	18.56700	      -0.10791	3.38183
 80.93147	18.59700	      -0.10410	3.38175
 81.08163	18.62700	      -0.10005	3.38167
 81.23172	18.65700	-9.568382e-002	3.38159
 81.38151	18.68700	-9.134257e-002	3.38151
 81.53114	18.71700	-8.662301e-002	3.38143
 81.68085	18.74700	-8.193532e-002	3.38134
 81.83060	18.77700	-7.664968e-002	3.38126
 81.98035	18.80700	-7.118582e-002	3.38118
 82.13012	18.83700	-6.595000e-002	3.38110
 82.27992	18.86700	-6.039582e-002	3.38101
 82.42983	18.89700	-5.438853e-002	3.38093
 82.57962	18.92700	-4.878418e-002	3.38084
 82.72925	18.95700	-4.308107e-002	3.38076
 82.87895	18.98700	-3.679242e-002	3.38067
 83.02870	19.01700	-3.037093e-002	3.38058
 83.17861	19.04700	-2.367670e-002	3.38050
 83.32867	19.07700	-1.616547e-002	3.38041
 83.47916	19.10700	-8.443519e-003	3.38032
 83.62971	19.13700	-2.940205e-004	3.38023
 83.78002	19.16700	 8.163588e-003	3.38014
 83.93024	19.19700	 1.728540e-002	3.38005
 84.08047	19.22700	 2.704949e-002	3.37996
 84.23063	19.25700	 3.692147e-002	3.37987
 84.38073	19.28700	 4.751399e-002	3.37978
 84.53083	19.31700	 5.845279e-002	3.37969
 84.68079	19.34700	 7.010347e-002	3.37960
 84.83080	19.37700	 8.221633e-002	3.37950
 84.98077	19.40700	 9.503351e-002	3.37941
 85.13081	19.43700	       0.10852	3.37931
 85.28085	19.46700	       0.12262	3.37922
 85.43088	19.49700	       0.13777	3.37912
 85.58072	19.52700	       0.15358	3.37903
 85.73073	19.55700	       0.17026	3.37893
 85.88083	19.58700	       0.18788	3.37884
 86.03090	19.61700	       0.20646	3.37874
 86.18100	19.64700	       0.22604	3.37864
 86.33103	19.67700	       0.24643	3.37854
 86.48115	19.70700	       0.26821	3.37844
 86.63132	19.73700	       0.29101	3.37835
 86.78144	19.76700	       0.31542	3.37825
 86.93150	19.79700	       0.34062	3.37815
 87.08160	19.82700	       0.36731	3.37804
 87.23160	19.85700	       0.39553	3.37794
 87.38165	19.88700	       0.42510	3.37784
 87.53170	19.91700	       0.45620	3.37774
 87.68177	19.94700	       0.48897	3.37764
 87.83178	19.97700	       0.52322	3.37753
 87.98178	20.00700	       0.55895	3.37743
 88.13171	20.03700	       0.59658	3.37732
 88.28163	20.06700	       0.63537	3.37722
 88.43160	20.09700	       0.67607	3.37711
 88.58160	20.12700	       0.71795	3.37701
 88.73162	20.15700	       0.76149	3.37690
 88.88159	20.18700	       0.80654	3.37679
 89.03160	20.21700	       0.85218	3.37669
 89.18163	20.24700	       0.89916	3.37658
 89.33173	20.27700	       0.94678	3.37647
 89.48176	20.30700	       0.99473	3.37636
 89.63168	20.33700	       1.04363	3.37625
 89.78169	20.36700	       1.09212	3.37614
 89.93176	20.39700	       1.14011	3.37603
 90.08189	20.42700	       1.18726	3.37592
 90.23208	20.45700	       1.23346	3.37581
 90.38215	20.48700	       1.27793	3.37569
 90.53209	20.51700	       1.32036	3.37558
 90.68197	20.54700	       1.36015	3.37547
 90.83181	20.57700	       1.39680	3.37536
 90.98168	20.60700	       1.43044	3.37524
 91.13157	20.63700	       1.46019	3.37513
 91.28140	20.66700	       1.48555	3.37501
 91.43119	20.69700	       1.50731	3.37490
 91.58105	20.72700	       1.52409	3.37478
 91.73089	20.75700	       1.53583	3.37466
 91.88066	20.78700	       1.54283	3.37455
 92.03037	20.81700	       1.54465	3.37443
 92.18006	20.84700	       1.54171	3.37431
 92.32980	20.87700	       1.53445	3.37419
 92.47967	20.90700	       1.52196	3.37407
 92.62952	20.93700	       1.50505	3.37395
 92.77936	20.96700	       1.48395	3.37383
 92.92934	20.99700	       1.45910	3.37371
 93.07920	21.02700	       1.43034	3.37359
 93.22911	21.05700	       1.39848	3.37347
 93.37945	21.08700	       1.36349	3.37335
 93.52977	21.11700	       1.32623	3.37322
 93.68002	21.14700	       1.28637	3.37310
 93.83029	21.17700	       1.24485	3.37297
 93.98060	21.20700	       1.20172	3.37285
 94.13078	21.23700	       1.15797	3.37272
 94.28087	21.26700	       1.11310	3.37260
 94.43076	21.29700	       1.06800	3.37247
 94.58029	21.32700	       1.02298	3.37235
 94.72988	21.35700	       0.97846	3.37222
 94.87956	21.38700	       0.93407	3.37209
 95.02942	21.41700	       0.89054	3.37197
 95.17954	21.44700	       0.84805	3.37184
 95.32933	21.47700	       0.80671	3.37171
 95.47888	21.50700	       0.76654	3.37158
 95.62865	21.53700	       0.72739	3.37145
 95.77854	21.56700	       0.68958	3.37132
 95.92837	21.59700	       0.65335	3.37119
 96.07840	21.62700	       0.61890	3.37106
 96.22850	21.65700	       0.58619	3.37092
 96.37860	21.68700	       0.55474	3.37079
 96.52910	21.71700	       0.52525	3.37066
 96.67977	21.74700	       0.49708	3.37052
 96.83026	21.77700	       0.47024	3.37039
 96.98059	21.80700	       0.44485	3.37026
 97.13063	21.83700	       0.42117	3.37012
 97.28070	21.86700	       0.39815	3.36999
 97.43078	21.89700	       0.37670	3.36985
 97.58091	21.92700	       0.35662	3.36971
 97.73081	21.95700	       0.33729	3.36958
 97.88075	21.98700	       0.31906	3.36944
 98.03067	22.01700	       0.30193	3.36930
 98.18048	22.04700	       0.28523	3.36916
 98.33034	22.07700	       0.26976	3.36902
 98.48030	22.10700	       0.25489	3.36888
 98.63026	22.13700	       0.24081	3.36874
 98.78035	22.16700	       0.22760	3.36860
 98.93042	22.19700	       0.21487	3.36846
 99.08051	22.22700	       0.20259	3.36832
 99.23063	22.25700	       0.19147	3.36818
 99.38067	22.28700	       0.18047	3.36804
 99.53075	22.31700	       0.17039	3.36789
 99.68081	22.34700	       0.16055	3.36775
 99.83100	22.37700	       0.15112	3.36761
 99.98108	22.40700	       0.14261	3.36746
100.13123	22.43700	       0.13422	3.36732
100.28128	22.46700	       0.12631	3.36717
100.43124	22.49700	       0.11848	3.36703
100.58115	22.52700	       0.11151	3.36688
100.73109	22.55700	       0.10456	3.36673
100.88112	22.58700	 9.781832e-002	3.36658
101.03119	22.61700	 9.165374e-002	3.36644
101.18120	22.64700	 8.530131e-002	3.36629
101.33122	22.67700	 7.951001e-002	3.36614
101.48129	22.70700	 7.376610e-002	3.36599
101.63134	22.73700	 6.843193e-002	3.36584
101.78132	22.76700	 6.306525e-002	3.36569
101.93121	22.79700	 5.843272e-002	3.36554
102.08116	22.82700	 5.357520e-002	3.36539
102.23114	22.85700	 4.902580e-002	3.36524
102.38120	22.88700	 4.507622e-002	3.36508
102.53132	22.91700	 4.105763e-002	3.36493
102.68141	22.94700	 3.691403e-002	3.36478
102.83135	22.97700	 3.335660e-002	3.36462
102.98125	23.00700	 2.959855e-002	3.36447
103.13112	23.03700	 2.596693e-002	3.36432
103.28107	23.06700	 2.258920e-002	3.36416
103.43098	23.09700	 1.907316e-002	3.36401
103.58105	23.12700	 1.603786e-002	3.36385
103.73111	23.15700	 1.290762e-002	3.36369
103.88110	23.18700	 9.971885e-003	3.36354
104.03103	23.21700	 7.148510e-003	3.36338
104.18106	23.24700	 4.371602e-003	3.36322
104.33111	23.27700	 1.832297e-003	3.36306
104.48110	23.30700	-9.249629e-004	3.36290
104.63107	23.33700	-3.452636e-003	3.36274
104.78096	23.36700	-5.693987e-003	3.36258
104.93089	23.39700	-8.146478e-003	3.36242
105.08097	23.42700	-1.042032e-002	3.36226
105.23093	23.45700	-1.260276e-002	3.36210
105.38096	23.48700	-1.456778e-002	3.36194
105.53086	23.51700	-1.678299e-002	3.36178
105.68072	23.54700	-1.877796e-002	3.36161
105.83067	23.57700	-2.061065e-002	3.36145
105.98064	23.60700	-2.255835e-002	3.36129
106.13062	23.63700	-2.444324e-002	3.36112
106.28059	23.66700	-2.623311e-002	3.36096
106.43058	23.69700	-2.781667e-002	3.36079
106.58055	23.72700	-2.966641e-002	3.36063
106.73069	23.75700	-3.150988e-002	3.36046
106.88087	23.78700	-3.312354e-002	3.36029
107.03101	23.81700	-3.461470e-002	3.36013
107.18107	23.84700	-3.630443e-002	3.35996
107.33118	23.87700	-3.768442e-002	3.35979
107.48131	23.90700	-3.927054e-002	3.35962
107.63139	23.93700	-4.067352e-002	3.35945
107.78135	23.96700	-4.203935e-002	3.35928
107.93126	23.99700	-4.330465e-002	3.35911
108.08117	24.02700	-4.433399e-002	3.35894
108.23112	24.05700	-4.569357e-002	3.35877
108.38108	24.08700	-4.695260e-002	3.35860
108.53108	24.11700	-4.798856e-002	3.35843
108.68114	24.14700	-4.901284e-002	3.35826
108.83113	24.17700	-5.028969e-002	3.35808
108.98125	24.20700	-5.144811e-002	3.35791
109.13129	24.23700	-5.260941e-002	3.35774
109.28133	24.26700	-5.377286e-002	3.35756
109.43124	24.29700	-5.518243e-002	3.35739
109.58118	24.32700	-5.601490e-002	3.35721
109.73114	24.35700	-5.687861e-002	3.35704
109.88135	24.38700	-5.790249e-002	3.35686
110.03167	24.41700	-5.863703e-002	3.35668
110.18199	24.44700	-5.963141e-002	3.35650
110.33216	24.47700	-6.025130e-002	3.35633
110.48218	24.50700	-6.110483e-002	3.35615
110.63216	24.53700	-6.186384e-002	3.35597
110.78200	24.56700	-6.268873e-002	3.35579
110.93185	24.59700	-6.386055e-002	3.35561
111.08172	24.62700	-6.480135e-002	3.35543
111.23163	24.65700	-6.528885e-002	3.35525
111.38159	24.68700	-6.609727e-002	3.35507
111.53162	24.71700	-6.700819e-002	3.35489
111.68165	24.74700	-6.755735e-002	3.35471
111.83163	24.77700	-6.874931e-002	3.35453
111.98144	24.80700	-6.941656e-002	3.35434
112.13134	24.83700	-7.021566e-002	3.35416
112.28129	24.86700	-7.093940e-002	3.35398
112.43134	24.89700	-7.170931e-002	3.35379
112.58133	24.92700	-7.247809e-002	3.35361
112.73142	24.95700	-7.295341e-002	3.35342
112.88158	24.98700	-7.379303e-002	3.35324
113.03165	25.01700	-7.454257e-002	3.35305
113.18160	25.04700	-7.519259e-002	3.35287
113.33152	25.07700	-7.585910e-002	3.35268
113.48148	25.10700	-7.633563e-002	3.35249
113.63137	25.13700	-7.684576e-002	3.35230
113.78140	25.16700	-7.768792e-002	3.35212
113.93141	25.19700	-7.796078e-002	3.35193
114.08138	25.22700	-7.847081e-002	3.35174
114.23142	25.25700	-7.914944e-002	3.35155
114.38134	25.28700	-7.967847e-002	3.35136
114.53134	25.31700	-8.031509e-002	3.35117
114.68144	25.34700	-8.068368e-002	3.35098
114.83150	25.37700	-8.139742e-002	3.35078
114.98146	25.40700	-8.217688e-002	3.35059
115.13136	25.43700	-8.253746e-002	3.35040
115.28135	25.46700	-8.332575e-002	3.35021
115.43136	25.49700	-8.379822e-002	3.35001
115.58147	25.52700	-8.433584e-002	3.34982
115.73145	25.55700	-8.483043e-002	3.34963
115.88150	25.58700	-8.534636e-002	3.34943
116.03147	25.61700	-8.588578e-002	3.34924
116.18147	25.64700	-8.663759e-002	3.34904
116.33147	25.67700	-8.735022e-002	3.34884
116.48143	25.70700	-8.766587e-002	3.34865
116.63130	25.73700	-8.849864e-002	3.34845
116.78120	25.76700	-8.899629e-002	3.34825
116.93114	25.79700	-9.002950e-002	3.34806
117.08121	25.82700	-9.072958e-002	3.34786
117.23132	25.85700	-9.149626e-002	3.34766
117.38133	25.88700	-9.226986e-002	3.34746
117.53136	25.91700	-9.301379e-002	3.34726
117.68136	25.94700	-9.381458e-002	3.34706
117.83131	25.97700	-9.485620e-002	3.34686
117.98126	26.00700	-9.607593e-002	3.34666
118.13114	26.03700	-9.687436e-002	3.34646
118.28102	26.06700	-9.774957e-002	3.34625
118.43085	26.09700	-9.902727e-002	3.34605
118.58092	26.12700	      -0.10012	3.34585
118.73094	26.15700	      -0.10142	3.34565
118.88093	26.18700	      -0.10277	3.34544
119.03089	26.21700	      -0.10441	3.34524
119.18084	26.24700	      -0.10596	3.34503
119.33081	26.27700	      -0.10783	3.34483
119.48079	26.30700	      -0.10969	3.34462
119.63080	26.33700	      -0.11195	3.34442
119.78096	26.36700	      -0.11398	3.34421
119.93109	26.39700	      -0.11652	3.34400
120.08122	26.42700	      -0.11910	3.34380
120.23140	26.45700	      -0.12185	3.34359
120.38143	26.48700	      -0.12472	3.34338
120.53142	26.51700	      -0.12810	3.34317
120.68134	26.54700	      -0.13145	3.34296
120.83121	26.57700	      -0.13511	3.34275
120.98115	26.60700	      -0.13897	3.34254
121.13121	26.63700	      -0.14329	3.34233
121.28121	26.66700	      -0.14785	3.34212
121.43126	26.69700	      -0.15263	3.34191
121.58131	26.72700	      -0.15774	3.34170
121.73132	26.75700	      -0.16338	3.34149
121.88125	26.78700	      -0.16912	3.34127
122.03118	26.81700	      -0.17515	3.34106
122.18108	26.84700	      -0.18139	3.34085
122.33114	26.87700	      -0.18783	3.34063
122.48121	26.90700	      -0.19435	3.34042
122.63132	26.93700	      -0.20076	3.34020
122.78145	26.96700	      -0.20709	3.33999
122.93159	26.99700	      -0.21334	3.33977
123.08158	27.02700	      -0.21899	3.33956
123.23157	27.05700	      -0.22422	3.33934
123.38156	27.08700	      -0.22934	3.33912
123.53154	27.11700	      -0.23391	3.33890
123.68153	27.14700	      -0.23817	3.33869
123.83157	27.17700	      -0.24170	3.33847
123.98159	27.20700	      -0.24429	3.33825
124.13154	27.23700	      -0.24633	3.33803
124.28151	27.26700	      -0.24730	3.33781
124.43145	27.29700	      -0.24788	3.33759
124.58150	27.32700	      -0.24705	3.33737
124.73153	27.35700	      -0.24484	3.33715
124.88150	27.38700	      -0.24131	3.33693
125.03154	27.41700	      -0.23606	3.33671
125.18161	27.44700	      -0.22904	3.33648
125.33170	27.47700	      -0.22048	3.33626
125.48169	27.50700	      -0.21027	3.33604
125.63165	27.53700	      -0.19862	3.33581
125.78168	27.56700	      -0.18682	3.33559
125.93165	27.59700	      -0.17495	3.33537
126.08169	27.62700	      -0.16386	3.33514
126.23170	27.65700	      -0.15432	3.33492
126.38175	27.68700	      -0.14624	3.33469
126.53168	27.71700	      -0.13993	3.33446
126.68164	27.74700	      -0.13524	3.33424
126.83162	27.77700	      -0.13197	3.33401
126.98147	27.80700	      -0.12979	3.33378
127.13132	27.83700	      -0.12849	3.33356
127.28113	27.86700	      -0.12754	3.33333
127.43104	27.89700	      -0.12735	3.33310
127.58100	27.92700	      -0.12729	3.33287
127.73101	27.95700	      -0.12756	3.33264
127.88107	27.98700	      -0.12819	3.33241
128.03103	28.01700	      -0.12879	3.33218
128.18104	28.04700	      -0.12937	3.33195
128.33114	28.07700	      -0.13051	3.33172
128.48122	28.10700	      -0.13139	3.33149
128.63121	28.13700	      -0.13236	3.33125
128.78126	28.16700	      -0.13312	3.33102
128.93133	28.19700	      -0.13403	3.33079
129.08146	28.22700	      -0.13498	3.33055
129.23157	28.25700	      -0.13579	3.33032
129.38177	28.28700	      -0.13671	3.33008
129.53186	28.31700	      -0.13753	3.32985
129.68180	28.34700	      -0.13860	3.32961
129.83173	28.37700	      -0.13959	3.32938
129.98168	28.40700	      -0.14049	3.32914
130.13166	28.43700	      -0.14155	3.32891
130.28155	28.46700	      -0.14234	3.32867
130.43144	28.49700	      -0.14363	3.32843
130.58139	28.52700	      -0.14462	3.32820
130.73142	28.55700	      -0.14551	3.32796
130.88133	28.58700	      -0.14660	3.32772
131.03121	28.61700	      -0.14744	3.32748
131.18107	28.64700	      -0.14842	3.32724
131.33106	28.67700	      -0.14919	3.32700
131.48096	28.70700	      -0.15007	3.32676
131.63101	28.73700	      -0.15120	3.32652
131.78119	28.76700	      -0.15223	3.32628
131.93139	28.79700	      -0.15302	3.32604
132.08149	28.82700	      -0.15379	3.32580
132.23162	28.85700	      -0.15453	3.32555
132.38169	28.88700	      -0.15520	3.32531
132.53180	28.91700	      -0.15598	3.32507
132.68181	28.94700	      -0.15666	3.32482
132.83180	28.97700	      -0.15714	3.32458
132.98194	29.00700	      -0.15765	3.32434
133.13209	29.03700	      -0.15818	3.32409
133.28215	29.06700	      -0.15859	3.32385
133.43212	29.09700	      -0.15906	3.32360
133.58199	29.12700	      -0.15940	3.32335
133.73184	29.15700	      -0.15976	3.32311
133.88158	29.18700	      -0.16027	3.32286
134.03139	29.21700	      -0.16054	3.32261
134.18127	29.24700	      -0.16083	3.32237
134.33116	29.27700	      -0.16111	3.32212
134.48116	29.30700	      -0.16138	3.32187
134.63116	29.33700	      -0.16177	3.32162
134.78118	29.36700	      -0.16196	3.32137
134.93124	29.39700	      -0.16226	3.32112
135.08119	29.42700	      -0.16247	3.32087
135.23114	29.45700	      -0.16247	3.32062
135.38111	29.48700	      -0.16257	3.32037
135.53118	29.51700	      -0.16265	3.32012
135.68126	29.54700	      -0.16262	3.31987
135.83142	29.57700	      -0.16259	3.31962
135.98152	29.60700	      -0.16256	3.31936
136.13157	29.63700	      -0.16262	3.31911
136.28157	29.66700	      -0.16242	3.31886
136.43160	29.69700	      -0.16229	3.31860
136.58164	29.72700	      -0.16214	3.31835
136.73168	29.75700	      -0.16210	3.31809
136.88167	29.78700	      -0.16216	3.31784
137.03168	29.81700	      -0.16192	3.31758
137.18171	29.84700	      -0.16182	3.31733
137.33175	29.87700	      -0.16169	3.31707
137.48193	29.90700	      -0.16149	3.31682
137.63198	29.93700	      -0.16141	3.31656
137.78204	29.96700	      -0.16119	3.31630
137.93203	29.99700	      -0.16109	3.31604
138.08202	30.02700	      -0.16085	3.31578
138.23201	30.05700	      -0.16070	3.31553
138.38183	30.08700	      -0.16054	3.31527
138.53172	30.11700	      -0.16031	3.31501
138.68162	30.14700	      -0.16024	3.31475
138.83150	30.17700	      -0.16003	3.31449
138.98141	30.20700	      -0.15973	3.31423
139.13137	30.23700	      -0.15956	3.31397
139.28141	30.26700	      -0.15943	3.31371
139.43135	30.29700	      -0.15933	3.31344
139.58130	30.32700	      -0.15940	3.31318
139.73127	30.35700	      -0.15932	3.31292
139.88121	30.38700	      -0.15916	3.31266
140.03121	30.41700	      -0.15909	3.31239
140.18124	30.44700	      -0.15900	3.31213
140.33132	30.47700	      -0.15876	3.31187
140.48142	30.50700	      -0.15863	3.31160
140.63150	30.53700	      -0.15859	3.31134
140.78153	30.56700	      -0.15841	3.31107
140.93155	30.59700	      -0.15827	3.31080
141.08154	30.62700	      -0.15819	3.31054
141.23148	30.65700	      -0.15802	3.31027
141.38136	30.68700	      -0.15780	3.31001
141.53131	30.71700	      -0.15759	3.30974
141.68131	30.74700	      -0.15751	3.30947
141.83136	30.77700	      -0.15727	3.30920
141.98143	30.80700	      -0.15710	3.30893
142.13149	30.83700	      -0.15694	3.30866
142.28150	30.86700	      -0.15669	3.30839
142.43154	30.89700	      -0.15659	3.30813
142.58164	30.92700	      -0.15654	3.30785
142.73165	30.95700	      -0.15653	3.30758
142.88169	30.98700	      -0.15646	3.30731
143.03168	31.01700	      -0.15639	3.30704
143.18172	31.04700	      -0.15614	3.30677
143.33193	31.07700	      -0.15615	3.30650
143.48203	31.10700	      -0.15580	3.30623
143.63213	31.13700	      -0.15530	3.30595
143.78227	31.16700	      -0.15529	3.30568
143.93219	31.19700	      -0.15517	3.30541
144.08201	31.22700	      -0.15491	3.30513
144.23175	31.25700	      -0.15479	3.30486
144.38160	31.28700	      -0.15463	3.30458
144.53142	31.31700	      -0.15422	3.30431
144.68138	31.34700	      -0.15401	3.30403
144.83129	31.37700	      -0.15392	3.30376
144.98134	31.40700	      -0.15358	3.30348
145.13137	31.43700	      -0.15339	3.30321
145.28129	31.46700	      -0.15330	3.30293
145.43122	31.49700	      -0.15327	3.30265
145.58134	31.52700	      -0.15329	3.30237
145.73134	31.55700	      -0.15330	3.30210
145.88127	31.58700	      -0.15321	3.30182
146.03132	31.61700	      -0.15296	3.30154
146.18145	31.64700	      -0.15291	3.30126
146.33153	31.67700	      -0.15253	3.30098
146.48152	31.70700	      -0.15243	3.30070
146.63160	31.73700	      -0.15213	3.30042
146.78155	31.76700	      -0.15166	3.30014
146.93139	31.79700	      -0.15145	3.29986
147.08126	31.82700	      -0.15115	3.29957
147.23124	31.85700	      -0.15112	3.29929
147.38122	31.88700	      -0.15091	3.29901
147.53106	31.91700	      -0.15082	3.29873
147.68097	31.94700	      -0.15069	3.29845
147.83096	31.97700	      -0.15048	3.29816
147.98104	32.00700	      -0.15032	3.29788
148.13111	32.03700	      -0.15018	3.29759
148.28127	32.06700	      -0.15016	3.29731
148.43144	32.09700	      -0.15010	3.29702
148.58159	32.12700	      -0.14988	3.29674
148.73172	32.15700	      -0.14989	3.29645
148.88190	32.18700	      -0.14973	3.29617
149.03208	32.21700	      -0.14951	3.29588
149.18216	32.24700	      -0.14920	3.29559
149.33235	32.27700	      -0.14897	3.29530
149.48234	32.30700	      -0.14867	3.29502
149.63214	32.33700	      -0.14833	3.29473
149.78204	32.36700	      -0.14815	3.29444
149.93166	32.39700	      -0.14792	3.29415
149.98182	32.40700	      -0.14787	3.29406